Workbook

Sheet Resumen
B2: BIOLARGO (OTCQX: BLGO) — Resumen Ejecutivo
B3: Modelo profesional con 4 capas: 3 estados enlazados, DCF real, sensibilidad, comparables — con SUMA DE PARTES como método principal (es una incubadora). Datos SEC hasta Q1 2026. Cifras en USD.
B5: CIFRAS CLAVE (de DATOS)
B6: Precio de la acción | C6: =DATOS!K37 -> 0.11 | D6: ~$0.11 (ago 2026). Micro-cap OTC.
B7: Ingresos FY2025 (miles $) | C7: =DATOS!E8 -> 10800 | D7: Cayó 42% por el fin de Pooph (era $17.8M).
B8: Ingreso por servicios FY2025 (miles $) | C8: =DATOS!E10 -> 2000 | D8: Se duplicó a ~$2M. La parte resiliente.
B9: Pérdida operativa FY2025 (miles $) | C9: =DATOS!E14 -> -10000 | D9: La pérdida "real" (sin write-offs).
B10: Caja (Q1 2026, miles $) | C10: =DATOS!K21 -> 3900 | D10: ~$3.9M. DÉBIL: riesgo de liquidez real.
B11: Patrimonio (Q1 2026, miles $) | C11: =DATOS!K31 -> 3000 | D11: Se erosiona con las pérdidas.
B12: Pipeline PFAS ($M) | C12: =DATOS!K39 -> 200 | D12: >$200M de oportunidades (no contratadas).
B14: VEREDICTO
B15: Tipo de inversión | C15: Cartera de opciones | D15: Su valor es la suma de 4 apuestas tecnológicas, cada una muy incierta.
B16: Negocio hoy | C16: En transición dolorosa | D16: Perdió su motor de caja (Pooph); depende de que las apuestas despeguen.
B17: Balance | C17: Debilidad | D17: Solo ~$3.9M de caja: riesgo de liquidez y dilución real.
B18: El gran potencial | C18: Agua PFAS + Clyra | D18: Crisis global de "químicos eternos" (>$200M pipeline) + médico.
B19: Valoración | C19: Suma de partes ($0.18) | D19: Por encima del precio ($0.11), pero depende de estimaciones inciertas.
B20: Riesgo/premio | C20: Máximo/máxima asimetría | D20: Posible pérdida total; gran subida si una apuesta prospera.
B22: COMPARACIÓN DEL PORTAFOLIO (8 empresas)
B23: LEU (Centrus) | C23: Rentable · enriquecimiento | D23: El más maduro; precio justificado por fundamentales.
B24: HSAI (Hesai) | C24: Crecimiento rentable · LiDAR | D24: Recién rentable, crecimiento explosivo. Alto upside, riesgo China.
B25: MP (MP Materials) | C25: Cruzando breakeven · imanes | D25: EBITDA+; prima estratégica. Gemelo maduro de USAR.
B26: PCYO (Pure Cycle) | C26: Rentable · agua | D26: Compounder lento y predecible; opción sobre derechos de agua.
B27: UUUU (Energy Fuels) | C27: Pierde dinero · opción REE | D27: Especulativo; se valora por NAV.
B28: ASPI (ASP Isotopes) | C28: Desarrollo · isótopos/nuclear | D28: Muy temprano, opción pura. Balance fuerte.
B29: USAR (USA Rare Earth) | C29: Construcción · imanes REE | D29: Opción a gran escala. Balance descomunal ($1.5B).
B30: BLGO (BioLargo) | C30: Incubadora · cleantech | D30: La más pequeña y frágil. Balance débil, valor en suma de partes.
B32: GUÍA DE HOJAS: DATOS (fuente+drivers) · Estado Resultados · Balance · Análisis Financiero · Proyecciones (3 estados enlazados) · Valoración (Suma de Partes+WACC+DCF) · Sensibilidad · Comparables.
B33: DESCARGO: material educativo, no asesoría financiera. Micro-cap OTC en transición: riesgo muy alto, dilución probable, posible pérdida total. Verifica en SEC EDGAR.

Sheet DATOS
B2: BIOLARGO (BLGO) — HOJA DE DATOS CRUDOS (SEC 10-K / 10-Q). Cifras en MILES USD.
B3: Fuente única. Azul = de SEC. Demás hojas jalan con fórmulas. Edita SOLO aquí. Plataforma cleantech multi-tecnología (incubadora). Perdió su motor de caja (Pooph) en 2025; el valor está en 4 apuestas emergentes. Balance débil: riesgo de liquidez real. FY = dic.
C5: ANUALES (FY dic) | F5: Q2 (homólogo) | H5: Trimestres recientes | J5: Balance (cortes)
B6: Concepto (miles $) | C6: FY2023 | D6: FY2024 | E6: FY2025 | F6: Q2-24 | G6: Q2-25 | H6: Q3-25 | I6: Q1-26 | J6: Dic-24 | K6: Q1-26bal | L6: Fuente / nota
B7: ESTADO DE RESULTADOS
B8: INGRESOS TOTALES | C8: 12230 | D8: 17780 | E8: 10800 | F8: 5010 | G8: 2780 | H8: 1100 | I8: 1120 | L8: FY25 cae 42%: fin de la licencia Pooph. Q4-25 solo 616.
B9: Ingreso por productos (Pooph/odor, otros) | L9: El grueso venía de Pooph (ya terminado).
B10: Ingreso por servicios (ingeniería BLEST) | E10: 2000 | L10: Se duplicó a ~$2M en 2025. Recurrente, resiliente.
B11: Costo de ventas | C11: 6080 | D11: 9930 | E11: 5780 | L11: Cost of revenue.
B12: UTILIDAD BRUTA | C12: 6150 | D12: 7850 | E12: 5020 | L12: Margen bruto ~46-47%. Se mantiene alto.
B13: Gastos operativos | C13: 10340 | D13: 12180 | L13: SG&A + I+D. Estructura de costos fija alta.
B14: PÉRDIDA OPERATIVA | C14: -4190 | D14: -4330 | E14: -10000 | L14: FY25 se amplía por menos ingresos + restructuring.
B15: Partidas no operativas netas | C15: -68 | D15: 1930 | L15: Incl. write-offs, ajustes. Ruido.
B16: PÉRDIDA NETA | C16: -3500 | D16: -4347 | E16: -15200 | F16: -1190 | H16: -6480 | I16: -1000 | L16: FY25 −15.2M inflada por write-offs Pooph + restructuring.
B17: De ella: Clyra Medical (filial) | D17: -3490 | L17: Buena parte de la pérdida es de la filial médica.
B18: EPS (US$) | D18: -0.006 | E18: -0.038 | F18: -0.001 | G18: 0 | H18: -0.02 | I18: -0.01 | L18: Diluted EPS. Pérdida pequeña por acción (muchas acciones).
B19: Acciones en circulación (M) | J19: 320 | K19: 380 | L19: ~380M acciones. Micro-cap. Dilución histórica.
B20: BALANCE GENERAL (fin de periodo)
B21: Caja y equivalentes | J21: 3548 | K21: 3900 | L21: CLAVE (y débil): solo ~$3.9M. Riesgo de liquidez real.
B22: Cuentas por cobrar | J22: 1200 | K22: 900 | L22: Accounts receivable.
B23: Inventarios | J23: 330 | K23: 400 | L23: Inventories.
B24: Total activo corriente | J24: 8037 | K24: 5500 | L24: Current assets.
B25: PP&E + otros activos | J25: 2476 | K25: 2500 | L25: Equipo + activos no corrientes.
B26: TOTAL ACTIVOS | J26: 10513 | K26: 8000 | L26: Total assets. Pequeña.
B27: Cuentas por pagar y acumulados | J27: 3200 | K27: 3500 | L27: AP + accrued.
B28: Deuda + notas + arrendamientos | J28: 1257 | K28: 2500 | L28: Deuda modesta. La empresa evita "deuda tóxica".
B29: TOTAL PASIVOS | J29: 4457 | K29: 5000 | L29: Total liabilities.
B30: Participación no controladora (Clyra) | J30: 0 | K30: 0 | L30: Minoritarios de Clyra (filial médica).
B31: PATRIMONIO | J31: 6056 | K31: 3000 | L31: Stockholders' equity. Se erosiona con las pérdidas.
B32: Deuda total (para WACC/puente) | J32: 1257 | K32: 2500 | L32: Deuda + notas.
B33: FLUJO DE CAJA (anual)
B34: Flujo de caja operativo (FY) | D34: -3000 | E34: -5000 | L34: Quema operativa. Se amplió en 2025 tras Pooph.
B35: CapEx (FY) | D35: -200 | E35: -300 | L35: Ligero: modelo "capital-light".
B36: MERCADO Y OPERATIVO (editable)
B37: Precio de la acción (US$) | K37: 0.11 | L37: ACTUALIZAR. ~$0.11 (ago 2026). 52-sem $0.095–0.234.
B38: Market cap referencia ($M) | K38: 42 | L38: ~$42M (precio × ~380M acciones).
B39: Pipeline PFAS bidded/spec ($M) | K39: 200 | L39: >$200M de oportunidades identificadas (no contratadas).
B40: SUMA DE PARTES — valor estimado por segmento ($M, editable)
B41: Clyra Medical (productos quirúrgicos) | K41: 25 | L41: Filial médica. Ref: rondas previas. EDITA.
B42: AEC / agua PFAS | K42: 20 | L42: Opción sobre crisis PFAS. EDITA según hitos.
...

Sheet Estado Resultados
B2: ESTADO DE RESULTADOS — la transición Pooph (miles $, jala de DATOS)
B3: Lo clave: cómo el fin de la licencia Pooph (mediados 2025) hundió los ingresos, y cómo los servicios recurrentes resisten. La pérdida neta está distorsionada por write-offs.
C5: ANUALES (la caída) | F5: Trimestres (desplome)
B6: Concepto (miles $) | C6: FY23 | D6: FY24 | E6: FY25 | F6: Q2 24 | G6: Q2 25 | H6: Q3 25 | I6: Q1 26
B7: INGRESOS TOTALES | C7: =DATOS!C8 -> 12230 | D7: =DATOS!D8 -> 17780 | E7: =DATOS!E8 -> 10800 | F7: =DATOS!F8 -> 5010 | G7: =DATOS!G8 -> 2780 | H7: =DATOS!H8 -> 1100 | I7: =DATOS!I8 -> 1120
B8: Ingreso por servicios (ingeniería) | C8: =DATOS!C10 | D8: =DATOS!D10 | E8: =DATOS!E10 -> 2000 | F8: =DATOS!F10 | G8: =DATOS!G10 | H8: =DATOS!H10 | I8: =DATOS!I10
B9: Costo de ventas | C9: =DATOS!C11 -> 6080 | D9: =DATOS!D11 -> 9930 | E9: =DATOS!E11 -> 5780 | F9: =DATOS!F11 | G9: =DATOS!G11 | H9: =DATOS!H11 | I9: =DATOS!I11
B10: UTILIDAD BRUTA | C10: =DATOS!C12 -> 6150 | D10: =DATOS!D12 -> 7850 | E10: =DATOS!E12 -> 5020 | F10: =DATOS!F12 | G10: =DATOS!G12 | H10: =DATOS!H12 | I10: =DATOS!I12
B11: Margen bruto % | C11: =IFERROR(DATOS!C12/DATOS!C8,"—") -> 0.50286182 | D11: =IFERROR(DATOS!D12/DATOS!D8,"—") -> 0.44150731 | E11: =IFERROR(DATOS!E12/DATOS!E8,"—") -> 0.46481481 | F11: =IFERROR(DATOS!F12/DATOS!F8,"—") -> 0 | G11: =IFERROR(DATOS!G12/DATOS!G8,"—") -> 0 | H11: =IFERROR(DATOS!H12/DATOS!H8,"—") -> 0 | I11: =IFERROR(DATOS!I12/DATOS!I8,"—") -> 0
B12: Gastos operativos | C12: =DATOS!C13 -> 10340 | D12: =DATOS!D13 -> 12180 | E12: =DATOS!E13 | F12: =DATOS!F13 | G12: =DATOS!G13 | H12: =DATOS!H13 | I12: =DATOS!I13
B13: PÉRDIDA OPERATIVA | C13: =DATOS!C14 -> -4190 | D13: =DATOS!D14 -> -4330 | E13: =DATOS!E14 -> -10000 | F13: =DATOS!F14 | G13: =DATOS!G14 | H13: =DATOS!H14 | I13: =DATOS!I14
B14: PÉRDIDA NETA | C14: =DATOS!C16 -> -3500 | D14: =DATOS!D16 -> -4347 | E14: =DATOS!E16 -> -15200 | F14: =DATOS!F16 -> -1190 | G14: =DATOS!G16 | H14: =DATOS!H16 -> -6480 | I14: =DATOS!I16 -> -1000
B15: De ella: Clyra Medical | C15: =DATOS!C17 | D15: =DATOS!D17 -> -3490 | E15: =DATOS!E17 | F15: =DATOS!F17 | G15: =DATOS!G17 | H15: =DATOS!H17 | I15: =DATOS!I17
B16: EPS (US$) | C16: =DATOS!C18 | D16: =DATOS!D18 -> -0.006 | E16: =DATOS!E18 -> -0.038 | F16: =DATOS!F18 -> -0.001 | G16: =DATOS!G18 -> 0 | H16: =DATOS!H18 -> -0.02 | I16: =DATOS!I18 -> -0.01
B18: Lectura: este estado cuenta una historia de transición dolorosa. Durante años, BioLargo financió su desarrollo con la caja de "Pooph", un producto de control de olores muy exitoso. En 2025 esa licencia terminó, y el efecto es brutal y visible: los ingresos anuales cayeron de $17.8M a $10.8M, y trimestre a trimestre el desplome es aún más claro (de $5M en Q2-24 a apenas $0.6M en Q4-25). La pérdida neta de −$15.2M asusta, pero conviene descomponerla: buena parte son cargos contables no recurrentes (write-offs por el fin de Pooph y reestructuración), no quema de caja pura; la pérdida operativa "real" ronda −$10M. Hay un punto positivo entre los escombros: el ingreso por servicios de ingeniería se duplicó a ~$2M y el margen bruto se mantiene alto (~46%), lo que muestra que el negocio subyacente tiene valor. Pero el mensaje central es claro: BioLargo perdió su motor de caja y ahora corre contra el tiempo para que sus otras apuestas lo reemplacen.

Sheet Balance
B2: BALANCE GENERAL — dic24 → mar26 (Q1) (miles $)
B3: Dos cortes. A diferencia de las otras empresas de opción, el balance es la DEBILIDAD de BLGO: poca caja. Verde = de DATOS.
B5: Partida (miles $) | C5: Dic-24 | D5: Mar-26 | E5: Comentario
B6: ACTIVOS
B7: Caja y equivalentes | C7: =DATOS!J21 -> 3548 | D7: =DATOS!K21 -> 3900 | E7: DÉBIL: solo ~$3.9M. El talón de Aquiles.
B8: Cuentas por cobrar | C8: =DATOS!J22 -> 1200 | D8: =DATOS!K22 -> 900
B9: Inventarios | C9: =DATOS!J23 -> 330 | D9: =DATOS!K23 -> 400
B10: Total activo corriente | C10: =DATOS!J24 -> 8037 | D10: =DATOS!K24 -> 5500
B11: PP&E + otros activos | C11: =DATOS!J25 -> 2476 | D11: =DATOS!K25 -> 2500 | E11: Equipo + no corrientes.
B12: TOTAL ACTIVOS | C12: =DATOS!J26 -> 10513 | D12: =DATOS!K26 -> 8000
B13: PASIVOS Y PATRIMONIO
B14: Cuentas por pagar y acumulados | C14: =DATOS!J27 -> 3200 | D14: =DATOS!K27 -> 3500
B15: Deuda + notas + arrendamientos | C15: =DATOS!J28 -> 1257 | D15: =DATOS!K28 -> 2500 | E15: Modesta: la empresa evita "deuda tóxica".
B16: TOTAL PASIVOS | C16: =DATOS!J29 -> 4457 | D16: =DATOS!K29 -> 5000
B17: PATRIMONIO | C17: =DATOS!J31 -> 6056 | D17: =DATOS!K31 -> 3000 | E17: Se erosiona con las pérdidas acumuladas.
B19: MÉTRICAS DE UNA EMPRESA FRÁGIL
B20: Razón corriente | C20: =IFERROR(DATOS!J24/DATOS!J27,"n/d") -> 2.5115625 | D20: =IFERROR(DATOS!K24/DATOS!K27,"n/d") -> 1.5714286 | E20: Aceptable pero sin holgura.
B21: Caja / Pasivos totales | C21: =IFERROR(DATOS!J21/DATOS!J29,"n/d") -> 0.79605116 | D21: =IFERROR(DATOS!K21/DATOS!K29,"n/d") -> 0.78 | E21: La caja no cubre ni todos los pasivos.
B22: Deuda / Patrimonio | C22: =IFERROR(DATOS!J32/DATOS!J31,"n/d") -> 0.20756275 | D22: =IFERROR(DATOS!K32/DATOS!K31,"n/d") -> 0.83333333 | E22: Sube al erosionarse el patrimonio.
B23: Patrimonio / Activos | C23: =IFERROR(DATOS!J31/DATOS!J26,"n/d") -> 0.5760487 | D23: =IFERROR(DATOS!K31/DATOS!K26,"n/d") -> 0.375 | E23: Baja: el capital se consume.
B25: Lectura: aquí está la diferencia clave de BioLargo frente a las otras apuestas de opción del portafolio. Mientras ASP Isotopes o USA Rare Earth tienen cientos o miles de millones en caja que les compran años de tiempo, BioLargo tiene apenas ~$3.9M. Para una empresa que pierde varios millones al año, eso es un colchón muy delgado. Su estrategia lo compensa en parte: es deliberadamente "capital-light" (invierte poco en activos fijos), evita deuda tóxica y financia sus proyectos a nivel de cada filial en lugar de la matriz. Pero no hay forma de endulzar el mensaje: el balance es frágil y la empresa depende de seguir levantando pequeñas cantidades de capital —lo que diluye a los accionistas— o de que alguna de sus tecnologías genere caja pronto. El riesgo de liquidez es real y hay que tenerlo presente en toda la valoración.

Sheet Análisis Financiero
B2: ANÁLISIS FINANCIERO — enfoque en supervivencia y valor de las partes
B3: Los ratios de rentabilidad no aplican (pierde). El foco: quema de caja, pista de liquidez (corta), y el valor de las 4 apuestas. Metodología Celsia adaptada a una incubadora frágil.
B5: Indicador | C5: FY2024 | D5: FY2025 | E5: Interpretación
B6: 1 · SUPERVIVENCIA (lo más importante aquí)
B7: Caja disponible (miles $) | C7: =DATOS!K21 -> 3900 | D7: =DATOS!K21 -> 3900 | E7: ~$3.9M. El colchón, muy delgado.
B8: Quema operativa anual (miles $) | C8: =-DATOS!D34 -> 3000 | D8: =-DATOS!E34 -> 5000 | E8: Efectivo que consume la operación al año.
B9: Pista de liquidez (meses) | C9: =IFERROR(DATOS!K21/(-DATOS!D34)*12,"n/d") -> 15.6 | D9: =IFERROR(DATOS!K21/(-DATOS!E34)*12,"n/d") -> 9.36 | E9: Meses que dura la caja. CORTA: presiona a levantar capital.
B10: 2 · MARGEN Y ESTRUCTURA
B11: Margen bruto | C11: =IFERROR(DATOS!D12/DATOS!D8,"n/d") -> 0.44150731 | D11: =IFERROR(DATOS!E12/DATOS!E8,"n/d") -> 0.46481481 | E11: Alto (~46%): el producto tiene valor. Buena señal.
B12: Pérdida operativa (miles $) | C12: =DATOS!D14 -> -4330 | D12: =DATOS!E14 -> -10000 | E12: La pérdida "real" (sin write-offs).
B13: Pérdida operativa / Ingresos | C13: =IFERROR(DATOS!D14/DATOS!D8,"n/d") -> -0.24353206 | D13: =IFERROR(DATOS!E14/DATOS!E8,"n/d") -> -0.92592593 | E13: Cuánto pierde por cada $ vendido. Empeora al caer Pooph.
B14: 3 · CRECIMIENTO / RESILIENCIA
B15: Ingresos totales (miles $) | C15: =DATOS!D8 -> 17780 | D15: =DATOS!E8 -> 10800 | E15: Cayó por Pooph: la métrica más dolorosa.
B16: Ingreso por servicios (miles $) | C16: ="n/d" -> n/d | D16: =DATOS!E10 -> 2000 | E16: Se duplicó a ~$2M: la parte resiliente y recurrente.
B17: 4 · CONTEXTO DE VALORACIÓN
B18: Market cap (miles $) | C18: =DATOS!K38*1000 -> 42000 | D18: =DATOS!K38*1000 -> 42000 | E18: ~$42M. Micro-cap.
B19: Suma de partes estimada (miles $) | C19: =(DATOS!K41+DATOS!K42+DATOS!K43+DATOS!K44)*1000 -> 68000 | D19: =(DATOS!K41+DATOS!K42+DATOS!K43+DATOS!K44)*1000 -> 68000 | E19: Valor de las 4 apuestas juntas. Ver hoja Valoración.
B21: Diagnóstico: a BioLargo hay que analizarla como lo que es — una incubadora frágil que acaba de perder su fuente de caja y necesita que alguna de sus apuestas prospere antes de agotar su colchón. El análisis de supervivencia es lo primero: con ~$3.9M de caja y una quema de varios millones al año, su pista de liquidez es corta, lo que la obliga a levantar capital periódicamente (diluyendo a los accionistas) o a acelerar la comercialización. Hay señales de resiliencia: el margen bruto se mantiene alto y el negocio de servicios crece, lo que prueba que la maquinaria subyacente funciona. Pero el veredicto financiero es que esta empresa no se valora por sus números actuales —que son de una empresa en crisis de transición— sino por la suma del valor de sus cuatro apuestas tecnológicas (Clyra, agua PFAS, baterías y servicios), cada una de las cuales podría valer mucho o nada. Es la definición de una apuesta de altísimo riesgo y altísima incertidumbre.

Sheet Proyecciones
B2: MODELO DE TRES ESTADOS PROYECTADOS Y ENLAZADOS (5 años) — BioLargo (miles $)
B3: Recuperación tras Pooph: los ingresos parten del fondo (~$5M) y se recuperan al escalar las apuestas. El margen cruza a positivo TARDE (año 4). Balance débil: la caja tiene un piso; si lo cruza, necesita financiarse (dilución). DESCUADRE verifica el cuadre (=0).
B6: Concepto (miles $) | C6: Base FY26e | D6: Año 1 | E6: Año 2 | F6: Año 3 | G6: Año 4 | H6: Año 5 | I6: Notas / enlace
B7: 1 · ESTADO DE RESULTADOS
B8: Ingresos | C8: =DATOS!$K$62 -> 5000 | D8: =C8*(1+DATOS!$K$63) -> 7000 | E8: =D8*(1+DATOS!$K$64) -> 10850 | F8: =E8*(1+DATOS!$K$65) -> 17360 | G8: =F8*(1+DATOS!$K$66) -> 25172 | H8: =G8*(1+DATOS!$K$67) -> 33982.2 | I8: Recuperación desde el fondo post-Pooph.
B9: Crecimiento % | D9: =D8/C8-1 -> 0.4 | E9: =E8/D8-1 -> 0.55 | F9: =F8/E8-1 -> 0.6 | G9: =G8/F8-1 -> 0.45 | H9: =H8/G8-1 -> 0.35
B10: Ingreso operativo (EBIT) | D10: =D8*DATOS!$K$68 -> -7000 | E10: =E8*DATOS!$K$69 -> -4882.5 | F10: =F8*DATOS!$K$70 -> -1736 | G10: =G8*DATOS!$K$71 -> 2013.76 | H10: =H8*DATOS!$K$72 -> 5097.33 | I10: Ventas × margen EBIT (negativo hasta año 4).
B11: Margen EBIT % | D11: =DATOS!$K$68 -> -1 | E11: =DATOS!$K$69 -> -0.45 | F11: =DATOS!$K$70 -> -0.1 | G11: =DATOS!$K$71 -> 0.08 | H11: =DATOS!$K$72 -> 0.15 | I11: De −100% a +15%. Cruza a positivo en el año 4.
B12: Utilidad antes de impuestos | D12: =D10 -> -7000 | E12: =E10 -> -4882.5 | F12: =F10 -> -1736 | G12: =G10 -> 2013.76 | H12: =H10 -> 5097.33 | I12: Sin caja significativa: sin ingreso por intereses relevante.
B13: (−) Impuestos | D13: =MAX(0,D12)*DATOS!K49 -> 0 | E13: =MAX(0,E12)*DATOS!K49 -> 0 | F13: =MAX(0,F12)*DATOS!K49 -> 0 | G13: =MAX(0,G12)*DATOS!K49 -> 422.8896 | H13: =MAX(0,H12)*DATOS!K49 -> 1070.4393 | I13: Solo si hay utilidad.
B14: UTILIDAD (PÉRDIDA) NETA | D14: =D12-D13 -> -7000 | E14: =E12-E13 -> -4882.5 | F14: =F12-F13 -> -1736 | G14: =G12-G13 -> 1590.8704 | H14: =H12-H13 -> 4026.8907
B16: 2 · BALANCE GENERAL
B17: Caja | C17: =DATOS!K21 -> 3900 | D17: =D39 -> 1000 | E17: =E39 -> 1000 | F17: =F39 -> 1000 | G17: =G39 -> 1306.2304 | H17: =H39 -> 3772.4571 | I17: ← Caja final del Flujo (con piso).
B18: Cuentas por cobrar | C18: =DATOS!K22 -> 900 | D18: =D8*(DATOS!K22/DATOS!$K$62) -> 1260 | E18: =E8*(DATOS!K22/DATOS!$K$62) -> 1953 | F18: =F8*(DATOS!K22/DATOS!$K$62) -> 3124.8 | G18: =G8*(DATOS!K22/DATOS!$K$62) -> 4530.96 | H18: =H8*(DATOS!K22/DATOS!$K$62) -> 6116.796 | I18: Ratio CxC/ventas.
B19: Inventarios | C19: =DATOS!K23 -> 400 | D19: =D8*(DATOS!K23/DATOS!$K$62) -> 560 | E19: =E8*(DATOS!K23/DATOS!$K$62) -> 868 | F19: =F8*(DATOS!K23/DATOS!$K$62) -> 1388.8 | G19: =G8*(DATOS!K23/DATOS!$K$62) -> 2013.76 | H19: =H8*(DATOS!K23/DATOS!$K$62) -> 2718.576 | I19: Ratio inventario/ventas.
B20: PP&E + otros | C20: =DATOS!K25 -> 2500 | D20: =C20+D8*DATOS!$K$75-D8*DATOS!$K$74 -> 2640 | E20: =D20+E8*DATOS!$K$75-E8*DATOS!$K$74 -> 2857 | F20: =E20+F8*DATOS!$K$75-F8*DATOS!$K$74 -> 3204.2 | G20: =F20+G8*DATOS!$K$75-G8*DATOS!$K$74 -> 3707.64 | H20: =G20+H8*DATOS!$K$75-H8*DATOS!$K$74 -> 4387.284 | I20: + CapEx − depreciación (capital-light).
B21: Otros activos (resto) | C21: =DATOS!K26-DATOS!K21-DATOS!K22-DATOS!K23-DATOS!K25 -> 300 | D21: =C21 -> 300 | E21: =D21 -> 300 | F21: =E21 -> 300 | G21: =F21 -> 300 | H21: =G21 -> 300 | I21: Resto constante.
B22: TOTAL ACTIVOS | C22: =C17+C18+C19+C20+C21 -> 8000 | D22: =D17+D18+D19+D20+D21 -> 5760 | E22: =E17+E18+E19+E20+E21 -> 6978 | F22: =F17+F18+F19+F20+F21 -> 9017.8 | G22: =G17+G18+G19+G20+G21 -> 11858.59 | H22: =H17+H18+H19+H20+H21 -> 17295.113
B23: Pasivos operativos | C23: =DATOS!K29-DATOS!K32 -> 2500 | D23: =D8*((DATOS!K29-DATOS!K32)/DATOS!$K$62) -> 3500 | E23: =E8*((DATOS!K29-DATOS!K32)/DATOS!$K$62) -> 5425 | F23: =F8*((DATOS!K29-DATOS!K32)/DATOS!$K$62) -> 8680 | G23: =G8*((DATOS!K29-DATOS!K32)/DATOS!$K$62) -> 12586 | H23: =H8*((DATOS!K29-DATOS!K32)/DATOS!$K$62) -> 16991.1 | I23: Ratio pasivos oper./ventas.
B24: Financiación acumulada (plug) | C24: =DATOS!K32 -> 2500 | D24: =D22-D23-D26 -> 6260 | E24: =E22-E23-E26 -> 10435.5 | F24: =F22-F23-F26 -> 10956.3 | G24: =G22-G23-G26 -> 8300.22 | H24: =H22-H23-H26 -> 5304.752 | I24: PLUG: capital/deuda que necesita levantar para cuadrar.
B25: TOTAL PASIVOS | C25: =C23+C24 -> 5000 | D25: =D23+D24 -> 9760 | E25: =E23+E24 -> 15860.5 | F25: =F23+F24 -> 19636.3 | G25: =G23+G24 -> 20886.22 | H25: =H23+H24 -> 22295.852
B26: PATRIMONIO | C26: =DATOS!K31 -> 3000 | D26: =C26+D14 -> -4000 | E26: =D26+E14 -> -8882.5 | F26: =E26+F14 -> -10618.5 | G26: =F26+G14 -> -9027.6296 | H26: =G26+H14 -> -5000.7389 | I26: Previo + utilidad (o − pérdida).
B27: TOTAL PASIVO + PATRIMONIO | C27: =C25+C26 -> 8000 | D27: =D25+D26 -> 5760 | E27: =E25+E26 -> 6978 | F27: =F25+F26 -> 9017.8 | G27: =G25+G26 -> 11858.59 | H27: =H25+H26 -> 17295.113
B28: DESCUADRE (Activo − Pas − Patr) | C28: =C22-C27 -> 0 | D28: =D22-D27 -> 0 | E28: =E22-E27 -> 0 | F28: =F22-F27 -> 0 | G28: =G22-G27 -> 0 | H28: =H22-H27 -> 0 | I28: DEBE SER 0.
B30: 3 · FLUJO DE CAJA
B31: Utilidad (pérdida) neta | D31: =D14 -> -7000 | E31: =E14 -> -4882.5 | F31: =F14 -> -1736 | G31: =G14 -> 1590.8704 | H31: =H14 -> 4026.8907 | I31: ← Resultados.
B32: (+) Depreciación | D32: =D8*DATOS!$K$74 -> 210 | E32: =E8*DATOS!$K$74 -> 325.5 | F32: =F8*DATOS!$K$74 -> 520.8 | G32: =G8*DATOS!$K$74 -> 755.16 | H32: =H8*DATOS!$K$74 -> 1019.466 | I32: No-caja.
B33: (−) Δ Capital de trabajo | D33: =-(D8-C8)*DATOS!$K$76 -> -200 | E33: =-(E8-D8)*DATOS!$K$76 -> -385 | F33: =-(F8-E8)*DATOS!$K$76 -> -651 | G33: =-(G8-F8)*DATOS!$K$76 -> -781.2 | H33: =-(H8-G8)*DATOS!$K$76 -> -881.02 | I33: Sobre crecimiento de ventas.
B34: Flujo de caja operativo | D34: =D31+D32+D33 -> -6990 | E34: =E31+E32+E33 -> -4942 | F34: =F31+F32+F33 -> -1866.2 | G34: =G31+G32+G33 -> 1564.8304 | H34: =H31+H32+H33 -> 4165.3367
B35: (−) CapEx | D35: =-D8*DATOS!$K$75 -> -350 | E35: =-E8*DATOS!$K$75 -> -542.5 | F35: =-F8*DATOS!$K$75 -> -868 | G35: =-G8*DATOS!$K$75 -> -1258.6 | H35: =-H8*DATOS!$K$75 -> -1699.11 | I35: % de ventas (capital-light).
B36: Flujo de caja libre (FCF) | D36: =D34+D35 -> -7340 | E36: =E34+E35 -> -5484.5 | F36: =F34+F35 -> -2734.2 | G36: =G34+G35 -> 306.2304 | H36: =H34+H35 -> 2466.2267 | I36: OCF − CapEx. Alimenta el DCF. Negativo al inicio.
B37: Caja inicial | D37: =DATOS!K21 -> 3900 | E37: =D39 -> 1000 | F37: =E39 -> 1000 | G37: =F39 -> 1000 | H37: =G39 -> 1306.2304
B38: (+) Capital levantado (si toca el piso) | D38: =MAX(0,DATOS!$K$77-(D37+D36)) -> 4440 | E38: =MAX(0,DATOS!$K$77-(E37+E36)) -> 5484.5 | F38: =MAX(0,DATOS!$K$77-(F37+F36)) -> 2734.2 | G38: =MAX(0,DATOS!$K$77-(G37+G36)) -> 0 | H38: =MAX(0,DATOS!$K$77-(H37+H36)) -> 0 | I38: Emite capital si la caja bajaría del piso. Refleja dilución.
B39: Caja final | D39: =D37+D36+D38 -> 1000 | E39: =E37+E36+E38 -> 1000 | F39: =F37+F36+F38 -> 1000 | G39: =G37+G36+G38 -> 1306.2304 | H39: =H37+H36+H38 -> 3772.4571 | I39: → Caja del Balance. Nunca baja del piso.
B41: Cómo leerlo: esta proyección modela una recuperación, no una historia de crecimiento limpio. BioLargo parte del fondo al que la dejó el fin de Pooph (~$5M de ingresos) y crece a medida que sus apuestas —Clyra médico, agua PFAS, servicios— toman tracción, cruzando a rentabilidad operativa alrededor del año 4. La diferencia clave frente a las otras empresas de opción del portafolio está en la fila de "Capital levantado": como el colchón de caja es delgado, el modelo asume que, cuando la caja amenazaría con caer por debajo de un piso mínimo, la empresa emite acciones para reponerla. Eso mantiene la caja a flote (nunca baja del piso) pero tiene un costo real que no aparece en esta hoja: cada emisión diluye a los accionistas existentes. Todo cuadra (Descuadre=0). El mensaje: la supervivencia está modelada, pero a costa de dilución, y todo depende de que las apuestas efectivamente despeguen.

Sheet Valoración
B2: VALORACIÓN — Suma de Partes (principal) · WACC · DCF
B3: Incubadora multi-tecnología: el método principal es SUMA DE PARTES (valorar cada apuesta). El DCF consolidado es secundario y muy incierto. Amarillo=editable. Cifras internas en miles $.
B5: 1 · SUMA DE PARTES (método principal)
B6: Segmento / apuesta | C6: Valor (miles $) | E6: Qué es y por qué vale eso
B7: Clyra Medical (productos quirúrgicos) | C7: =DATOS!K41*1000 -> 25000 | E7: Filial médica, la más cercana a escalar. Ref: rondas previas.
B8: AEC / agua PFAS | C8: =DATOS!K42*1000 -> 20000 | E8: Opción sobre la crisis de "químicos eternos". >$200M pipeline.
B9: Cellinity (baterías) | C9: =DATOS!K43*1000 -> 15000 | E9: Almacenamiento de energía. Muy temprano, alta opcionalidad.
B10: Servicios de ingeniería (BLEST) | C10: =DATOS!K44*1000 -> 8000 | E10: Negocio recurrente y rentable. El más "cierto".
B11: (+) Caja − deuda (miles $) | C11: =DATOS!K21-DATOS!K32 -> 1400 | E11: Ajuste por balance neto.
B12: VALOR TOTAL (suma de partes, miles $) | C12: =SUM(C7:C10)+C11 -> 69400
B13: Valor por acción — Suma de Partes ($) | C13: =C12/1000/DATOS!K19 -> 0.18263158
B15: 2 · COSTO DE CAPITAL (WACC vía CAPM)
B16: Tasa libre de riesgo (Rf) | C16: =DATOS!K46 -> 0.043 | E16: De DATOS.
B17: Prima de riesgo (ERP) | C17: =DATOS!K47 -> 0.055 | E17: De DATOS.
B18: Beta desapalancado (βu) | C18: =DATOS!K48 -> 1.8 | E18: Micro-cap pre-rentabilidad. Muy alto. De DATOS.
B19: Valor de mercado del equity (miles $) | C19: =DATOS!K37*DATOS!K19*1000 -> 41800 | E19: Precio × ~380M acciones.
B20: Valor de la deuda (miles $) | C20: =MAX(DATOS!K32,1) -> 2500 | E20: Deuda modesta.
B21: Peso deuda D/(D+E) | C21: =C20/(C20+C19) -> 0.056433409
B22: Peso equity E/(D+E) | C22: =C19/(C20+C19) -> 0.94356659
B23: Tasa impositiva (t) | C23: =DATOS!K49 -> 0.21
B24: Beta apalancado (βL, Hamada) | C24: =C18*(1+(1-C23)*C20/C19) -> 1.8850478 | E24: βu×(1+(1−t)×D/E).
B25: Costo del equity (Ke=CAPM) | C25: =C16+C24*C17 -> 0.14667763 | E25: Rf+βL×ERP.
B26: Costo de la deuda (Kd) | C26: =DATOS!K50 -> 0.1
B27: WACC | C27: =C22*C25+C21*C26*(1-C23) -> 0.14285835 | E27: Muy alto: micro-cap de máximo riesgo.
B29: 3 · DCF consolidado (secundario, referencial)
B30: Año | C30: FCF (miles $) | D30: VP (miles $) | E30: FCF de Proyecciones. Negativo al inicio.
B31: 1 | C31: =Proyecciones!D36 -> -7340 | D31: =C31/(1+C27)^1 -> -6422.4932
B32: 2 | C32: =Proyecciones!E36 -> -5484.5 | D32: =C32/(1+C27)^2 -> -4199.0614
B33: 3 | C33: =Proyecciones!F36 -> -2734.2 | D33: =C33/(1+C27)^3 -> -1831.6946
B34: 4 | C34: =Proyecciones!G36 -> 306.2304 | D34: =C34/(1+C27)^4 -> 179.50588
B35: 5 | C35: =Proyecciones!H36 -> 2466.2267 | D35: =C35/(1+C27)^5 -> 1264.943
B36: FCF terminal normalizado (miles $) | C36: =Proyecciones!H8*DATOS!K51*(1-DATOS!K49) -> 4026.8907 | E36: Ventas año5 × margen terminal × (1−t).
B37: Valor terminal (Gordon, g=3%) | C37: =C36*(1.03)/(C27-0.03) -> 36751.355 | D37: =C37/(1+C27)^5 -> 18849.999 | E37: g perpetuo 3%.
B38: Valor patrimonio — DCF (miles $) | C38: =SUM(D31:D35)+D37+DATOS!K21-DATOS!K32 -> 9241.1986
B39: Valor por acción — DCF ($) | C39: =C38/1000/DATOS!K19 -> 0.024318944
B41: 4 · SÍNTESIS
B42: Valor/acción — Suma de Partes ($) | C42: =C13 -> 0.18263158 | E42: Método principal: valor de las 4 apuestas + caja neta.
B43: Valor/acción — DCF ($) | C43: =C39 -> 0.024318944 | E43: Secundario: si la recuperación proyectada se cumple.
B44: Precio de mercado ($) | C44: =DATOS!K37 -> 0.11
B45: Margen de seguridad (vs SoP / vs DCF) | C45: =C13/DATOS!K37-1 -> 0.66028708 | D45: =C39/DATOS!K37-1 -> -0.77891869 | E45: Positivo = infravalorada por ese método.
...

Sheet Sensibilidad
B2: ANÁLISIS DE SENSIBILIDAD — Valor por acción (Suma de Partes)
B3: Valor de la apuesta de agua PFAS (filas) × valor de Clyra Medical (columnas), en $M. Son las dos opciones de mayor peso e incertidumbre.
B5: Agua PFAS \ Clyra ($M) | C5: 10 | D5: 20 | E5: 25 | F5: 40 | G5: 60
B6: 0 | C6: =(($B6*1000+C$5*1000+(DATOS!K43+DATOS!K44)*1000+DATOS!K21-DATOS!K32))/1000/DATOS!K19 -> 0.090526316 | D6: =(($B6*1000+D$5*1000+(DATOS!K43+DATOS!K44)*1000+DATOS!K21-DATOS!K32))/1000/DATOS!K19 -> 0.11684211 | E6: =(($B6*1000+E$5*1000+(DATOS!K43+DATOS!K44)*1000+DATOS!K21-DATOS!K32))/1000/DATOS!K19 -> 0.13 | F6: =(($B6*1000+F$5*1000+(DATOS!K43+DATOS!K44)*1000+DATOS!K21-DATOS!K32))/1000/DATOS!K19 -> 0.16947368 | G6: =(($B6*1000+G$5*1000+(DATOS!K43+DATOS!K44)*1000+DATOS!K21-DATOS!K32))/1000/DATOS!K19 -> 0.22210526
B7: 10 | C7: =(($B7*1000+C$5*1000+(DATOS!K43+DATOS!K44)*1000+DATOS!K21-DATOS!K32))/1000/DATOS!K19 -> 0.11684211 | D7: =(($B7*1000+D$5*1000+(DATOS!K43+DATOS!K44)*1000+DATOS!K21-DATOS!K32))/1000/DATOS!K19 -> 0.14315789 | E7: =(($B7*1000+E$5*1000+(DATOS!K43+DATOS!K44)*1000+DATOS!K21-DATOS!K32))/1000/DATOS!K19 -> 0.15631579 | F7: =(($B7*1000+F$5*1000+(DATOS!K43+DATOS!K44)*1000+DATOS!K21-DATOS!K32))/1000/DATOS!K19 -> 0.19578947 | G7: =(($B7*1000+G$5*1000+(DATOS!K43+DATOS!K44)*1000+DATOS!K21-DATOS!K32))/1000/DATOS!K19 -> 0.24842105
B8: 20 | C8: =(($B8*1000+C$5*1000+(DATOS!K43+DATOS!K44)*1000+DATOS!K21-DATOS!K32))/1000/DATOS!K19 -> 0.14315789 | D8: =(($B8*1000+D$5*1000+(DATOS!K43+DATOS!K44)*1000+DATOS!K21-DATOS!K32))/1000/DATOS!K19 -> 0.16947368 | E8: =(($B8*1000+E$5*1000+(DATOS!K43+DATOS!K44)*1000+DATOS!K21-DATOS!K32))/1000/DATOS!K19 -> 0.18263158 | F8: =(($B8*1000+F$5*1000+(DATOS!K43+DATOS!K44)*1000+DATOS!K21-DATOS!K32))/1000/DATOS!K19 -> 0.22210526 | G8: =(($B8*1000+G$5*1000+(DATOS!K43+DATOS!K44)*1000+DATOS!K21-DATOS!K32))/1000/DATOS!K19 -> 0.27473684
B9: 35 | C9: =(($B9*1000+C$5*1000+(DATOS!K43+DATOS!K44)*1000+DATOS!K21-DATOS!K32))/1000/DATOS!K19 -> 0.18263158 | D9: =(($B9*1000+D$5*1000+(DATOS!K43+DATOS!K44)*1000+DATOS!K21-DATOS!K32))/1000/DATOS!K19 -> 0.20894737 | E9: =(($B9*1000+E$5*1000+(DATOS!K43+DATOS!K44)*1000+DATOS!K21-DATOS!K32))/1000/DATOS!K19 -> 0.22210526 | F9: =(($B9*1000+F$5*1000+(DATOS!K43+DATOS!K44)*1000+DATOS!K21-DATOS!K32))/1000/DATOS!K19 -> 0.26157895 | G9: =(($B9*1000+G$5*1000+(DATOS!K43+DATOS!K44)*1000+DATOS!K21-DATOS!K32))/1000/DATOS!K19 -> 0.31421053
B10: 60 | C10: =(($B10*1000+C$5*1000+(DATOS!K43+DATOS!K44)*1000+DATOS!K21-DATOS!K32))/1000/DATOS!K19 -> 0.24842105 | D10: =(($B10*1000+D$5*1000+(DATOS!K43+DATOS!K44)*1000+DATOS!K21-DATOS!K32))/1000/DATOS!K19 -> 0.27473684 | E10: =(($B10*1000+E$5*1000+(DATOS!K43+DATOS!K44)*1000+DATOS!K21-DATOS!K32))/1000/DATOS!K19 -> 0.28789474 | F10: =(($B10*1000+F$5*1000+(DATOS!K43+DATOS!K44)*1000+DATOS!K21-DATOS!K32))/1000/DATOS!K19 -> 0.32736842 | G10: =(($B10*1000+G$5*1000+(DATOS!K43+DATOS!K44)*1000+DATOS!K21-DATOS!K32))/1000/DATOS!K19 -> 0.38
B12: Precio de mercado: | C12: =DATOS!K37 -> 0.11 | D12: Compara cada celda con el precio de ~$0.11.
B14: Lectura: en una incubadora como BioLargo, el valor por acción depende casi por completo de cuánto valgan sus apuestas individuales — y esas valoraciones son muy inciertas. La tabla lo hace explícito: si el agua PFAS y Clyra resultan valiosas (esquina inferior derecha), el valor por acción supera con holgura el precio actual; si ambas decepcionan (esquina superior izquierda), el valor colapsa. El rango es enorme, lo que refleja honestamente que esto es una cartera de opciones binarias más que un negocio predecible. La apuesta central para el inversor es si el mercado del agua PFAS —una crisis regulatoria global— se materializa en contratos para BioLargo.

Sheet Comparables
B2: ANÁLISIS DE COMPARABLES (Comps) — cleantech / tratamiento de agua / micro-cap
B3: Ancla BLGO contra cleantech de agua/PFAS y micro-caps de tecnología. Casi todas pre-rentabilidad → EV/Ventas y P/VC. Múltiplos aprox/editables (azul).
B5: Empresa | C5: Ticker | D5: EV/Ventas | E5: P/VC | F5: Comentario
B6: Gorilla Technology | C6: GRRR | D6: 3 | E6: 2.5 | F6: Cleantech/IoT. Referencia de small-cap tech.
B7: CECO Environmental | C7: CECO | D7: 1.5 | E7: 2.8 | F7: Soluciones ambientales, rentable. Ancla madura.
B8: Montrose Environmental | C8: MEG | D8: 1.8 | E8: 2 | F8: Servicios ambientales incl. PFAS. Referencia sectorial.
B9: Energy Recovery | C9: ERII | D9: 3.5 | E9: 3 | F9: Tecnología de agua, rentable.
B10: PureCycle Technologies | C10: PCT | D10: n/d | E10: 4 | F10: Cleantech pre-rentabilidad (reciclaje). Comparable de opción.
B11: MEDIANA | D11: =MEDIAN(D6:D10) -> 2.4 | E11: =MEDIAN(E6:E10) -> 2.8
B13: VALORACIÓN IMPLÍCITA DE BLGO ($/acción)
B14: Método | C14: Base (miles $) | D14: × múltiplo | E14: Valor/acción | H14: Nota
B15: Por EV/Ventas (ingreso año3 proj) | C15: =Proyecciones!F8 -> 17360 | D15: =D11 -> 2.4 | E15: =(Proyecciones!F8*D11+DATOS!K21-DATOS!K32)/1000/DATOS!K19 -> 0.11332632 | F15: Ventas recuperadas (año3) × múltiplo + caja neta.
B16: Por P/VC (patrimonio) | C16: =DATOS!K31 -> 3000 | D16: =E11 -> 2.8 | E16: =DATOS!K31*E11/1000/DATOS!K19 -> 0.022105263 | F16: Patrimonio × P/VC mediana.
B17: Precio de mercado ($) | E17: =DATOS!K37 -> 0.11
B19: Nota: BioLargo no tiene comparables perfectos — es una mezcla de cleantech de agua, dispositivos médicos y baterías. Los comparables de tratamiento de agua y servicios ambientales (Montrose, CECO, Energy Recovery) enmarcan su negocio de PFAS y servicios; PureCycle aporta una referencia de cleantech pre-rentabilidad valorada por opción. Como la base de ingresos de BLGO está deprimida tras Pooph, el comparable por ventas se aplica sobre los ingresos ya recuperados del año 3 proyectado, no sobre los actuales. Todos estos métodos son orientativos: para una incubadora tan pequeña, la suma de partes (hoja Valoración) es más informativa que los múltiplos de mercado.
