Workbook

Sheet Resumen
B2: CADIZ (NASDAQ: CDZI) — Resumen Ejecutivo
B3: Modelo profesional con 4 capas: 3 estados enlazados, DCF real, sensibilidad, comparables — con NAV/Suma de Partes como método principal (empresa de recursos de agua). Datos SEC hasta Q2 2025. Cifras en USD.
B5: CIFRAS CLAVE (de DATOS, miles $ salvo precio)
B6: Precio de la acción CDZI | C6: =DATOS!K43 -> 3 | D6: ~$3 (2025-26).
B7: Ingresos TTM (miles $) | C7: =DATOS!E8 -> 16300 | D7: ~$16.3M. Crece fuerte por ATEC (filtros).
B8: Ingresos ATEC H1-25 (miles $) | C8: =DATOS!I10 -> 6084 | D8: De 648 a 6,084 en un año: el motor de crecimiento.
B9: Caja + restringida (jun-25, miles $) | C9: =DATOS!K22+DATOS!K23 -> 15964 | D9: ~$16M. Corta frente a la quema.
B10: Deuda total (jun-25, miles $) | C10: =DATOS!K38 -> 85345 | D10: ~$85M (deuda + lease Heerema). PESADA.
B11: Patrimonio (jun-25, miles $) | C11: =DATOS!K37 -> 35566 | D11: ~$36M. Delgado y apalancado.
B12: Derechos de agua (acre-pies) | C12: =DATOS!K44 -> 2500000 | D12: 2.5M AF + 1M almacenamiento. El activo central.
B13: NOL fiscal federal (miles $) | C13: =DATOS!K46 -> 368000 | D13: $368M: escudo fiscal para ganancias futuras.
B15: VEREDICTO
B16: Tipo de inversión | C16: Activos de agua (NAV) | D16: El valor está en los derechos de agua, no en los flujos actuales.
B17: Negocio hoy | C17: Pre-rentabilidad dual | D17: ATEC (filtros) ya despega; el gran negocio de agua aún es pre-ingreso.
B18: Balance | C18: Apalancado | D18: Deuda pesada (~$85M) + preferentes ($57.5M). El gran riesgo.
B19: El gran potencial | C19: Mojave Water Bank | D19: 2.5M AF de agua + contratos take-or-pay firmados. Necesita ~$800M.
B20: Valoración | C20: NAV ($5.81) > precio ($3) | D20: Posible infravaloración, pero depende del valor del agua.
B21: Riesgo/premio | C21: Alto/asimétrico | D21: Deuda + ejecución (Mojave) + Heerema concentrado (31.4%).
B23: COMPARACIÓN DEL PORTAFOLIO (9 empresas)
B24: LEU (Centrus) | C24: Rentable · enriquecimiento | D24: El más maduro; precio justificado por fundamentales.
B25: HSAI (Hesai) | C25: Crecimiento rentable · LiDAR | D25: Recién rentable, crecimiento explosivo. Riesgo China.
B26: MP (MP Materials) | C26: Cruzando breakeven · imanes | D26: EBITDA+; prima estratégica. Gemelo maduro de USAR.
B27: PCYO (Pure Cycle) | C27: Rentable · agua | D27: Compounder lento; opción sobre derechos de agua. SIN deuda.
B28: UUUU (Energy Fuels) | C28: Pierde dinero · opción REE | D28: Especulativo; se valora por NAV.
B29: ASPI (ASP Isotopes) | C29: Desarrollo · isótopos/nuclear | D29: Muy temprano, opción pura. Balance fuerte.
B30: USAR (USA Rare Earth) | C30: Construcción · imanes REE | D30: Opción a gran escala. Balance descomunal ($1.5B).
B31: BLGO (BioLargo) | C31: Incubadora · cleantech | D31: La más pequeña y frágil. Balance débil.
B32: CDZI (Cadiz) | C32: Agua apalancada · NAV | D32: Primo agresivo de PCYO: agua valiosa, pero con deuda pesada.
B34: GUÍA DE HOJAS: DATOS (fuente+drivers) · Estado Resultados · Balance · Análisis Financiero · Proyecciones (3 estados enlazados) · Valoración (NAV+WACC+DCF) · Sensibilidad · Comparables.
B35: DESCARGO: material educativo, no asesoría financiera. Empresa de recursos apalancada: riesgo alto por deuda y ejecución. Verifica en SEC EDGAR.

Sheet DATOS
B2: CADIZ (CDZI) — HOJA DE DATOS CRUDOS (SEC 10-K / 10-Q). Cifras en MILES USD.
B3: Fuente única. Azul = de SEC. Demás hojas jalan con fórmulas. Edita SOLO aquí. Soluciones de agua en el sur de California. Pre-rentabilidad con activos de agua masivos y deuda pesada. El "primo agresivo" de Pure Cycle. FY = dic.
C5: ANUALES (FY dic) | F5: Q2 (homólogo) | H5: H1 / 6 meses | J5: Balance (cortes)
B6: Concepto (miles $) | C6: FY2023 | D6: FY2024 | E6: FY2025 | F6: Q2-24 | G6: Q2-25 | H6: H1-24 | I6: H1-25 | J6: Dic-24 | K6: Jun-25 | L6: Fuente / nota
B7: ESTADO DE RESULTADOS
B8: INGRESOS TOTALES | D8: 4500 | E8: 16300 | F8: 513 | G8: 4126 | H8: 1634 | I8: 7080 | L8: FY25 ~16.3M TTM. Crece fuerte por ATEC (filtros).
B9: Land & Water Resources (agua+agro) | F9: 350 | G9: 431 | H9: 986 | I9: 996 | L9: Agua/agro. El gran negocio aún es pre-ingreso.
B10: Water Filtration (ATEC) | F10: 163 | G10: 3695 | H10: 648 | I10: 6084 | L10: ATEC: de 163 a 3,695 en un año. El motor de crecimiento.
B11: Costo de ventas | F11: 852 | G11: 2665 | H11: 1856 | I11: 4743 | L11: Cost of sales.
B12: UTILIDAD BRUTA | F12: -339 | G12: 1461 | H12: -222 | I12: 2337 | L12: Bruto positivo ya en 2025 (ATEC margen +44%).
B13: Gastos generales y admin | F13: 6305 | G13: 6935 | H13: 11035 | I13: 15042 | L13: G&A. Alto: desarrollo del Mojave + stock comp.
B14: PÉRDIDA OPERATIVA | F14: -6949 | G14: -5777 | H14: -11857 | I14: -13310 | L14: La pérdida "real" del negocio.
B15: Gasto por intereses, neto | F15: -1921 | G15: -1951 | H15: -3860 | I15: -4008 | L15: Deuda Heerema (7%, parte PIK). Pesado.
B16: PÉRDIDA NETA | D16: -30000 | E16: -39200 | F16: -8872 | G16: -7730 | H16: -15722 | I16: -17323 | L16: FY25 TTM ~−39M. Grande frente a ingresos.
B17: Dividendo preferentes (Serie A 8.875%) | F17: -1288 | G17: -1288 | H17: -2553 | I17: -2553 | L17: Pref CDZIP: $2.22/año por acción depositaria.
B18: Pérdida neta atribuible a comunes | F18: -10160 | G18: -9018 | H18: -18275 | I18: -19876 | L18: Tras dividendo preferente.
B19: EPS (US$) | F19: -0.15 | G19: -0.11 | H19: -0.27 | I19: -0.25 | L19: Loss per common share.
B20: Acciones comunes (M) | F20: 67.8 | G20: 81.9 | H20: 67.4 | I20: 79.6 | J20: 75.4 | K20: 82 | L20: ~82M a ago-2025. Heerema tiene 31.4%.
B21: BALANCE GENERAL (fin de periodo)
B22: Caja y equivalentes | J22: 17292 | K22: 13205 | L22: Caja. Baja: quema + capex Mojave.
B23: Caja restringida (LP) | J23: 134 | K23: 2759 | L23: Colateral (bono Northern Pipeline).
B24: Cuentas por cobrar | J24: 4586 | K24: 4090 | L24: Accounts receivable.
B25: Inventarios | J25: 3020 | K25: 3011 | L25: Inventories (filtros ATEC).
B26: Total activo corriente | J26: 25786 | K26: 21039 | L26: Current assets.
B27: PP&E + programas de agua, neto | J27: 88362 | K27: 92605 | L27: Tierra + tubería + programas de agua. A COSTO histórico.
B28: Goodwill | J28: 5714 | K28: 5714 | L28: De la adquisición de ATEC.
B29: Otros activos (ROU, depósitos) | J29: 14632 | K29: 16667 | L29: Right-of-use + otros.
B30: TOTAL ACTIVOS | J30: 134494 | K30: 136379 | L30: Total assets. A costo, NO refleja valor del agua.
B31: Cuentas por pagar y acumulados | J31: 10258 | K31: 6840 | L31: AP + accrued + dividendo por pagar.
B32: Ingreso diferido | J32: 1851 | K32: 3627 | L32: Anticipos Mojave + ATEC.
B33: Total pasivo corriente | J33: 14406 | K33: 11594 | L33: Current liabilities.
... B38: Deuda total (deuda + lease relacionado) | J38: 81983 | K38: 85345 | L38: Para WACC/puente: deuda LP + lease Heerema.
B39: FLUJO DE CAJA (H1 / semestral)
B40: Flujo de caja operativo (H1) | H40: -9936 | I40: -5000 | L40: Quema operativa H1-25: −5M (mejora vs −9.9M).
B41: CapEx + depósitos (H1) | H41: -467 | I41: -10800 | L41: Sube fuerte: capex Mojave + opciones de compra.
B42: MERCADO Y OPERATIVO (editable)
B43: Precio de la acción CDZI (US$) | K43: 3 | L43: ACTUALIZAR. ~$3 (2025-26).
B44: Derechos de agua (acre-pies) | K44: 2500000 | L44: 2.5M acre-pies de derechos + 1M almacenamiento.
B45: Contratado (AFY, take-or-pay) | K45: 21275 | L45: 85% del Northern Pipeline. ~$850/AF, 40 años.
B46: NOL fiscal federal ($ miles) | K46: 368000 | L46: Pérdidas acumuladas: escudo fiscal futuro valioso.
...

Sheet Estado Resultados
B2: ESTADO DE RESULTADOS — el despegue de ATEC (miles $, jala de DATOS)
B3: Lo clave: el segmento de filtración (ATEC) crece explosivamente y ya da margen positivo, mientras el gran negocio de agua sigue pre-ingreso. La pérdida persiste por G&A del proyecto Mojave y el interés de la deuda.
C5: ANUALES | F5: Q2 (24→25) | I5: H1 (24→25)
B6: Concepto (miles $) | C6: FY23 | D6: FY24 | E6: FY25 | F6: Q2 24 | G6: Q2 25 | H6: Δ% | I6: H1 24 | J6: H1 25 | K6: Δ%
B7: INGRESOS TOTALES | C7: =DATOS!C8 | D7: =DATOS!D8 -> 4500 | E7: =DATOS!E8 -> 16300 | F7: =DATOS!F8 -> 513 | G7: =DATOS!G8 -> 4126 | H7: =IFERROR((DATOS!G8-DATOS!F8)/ABS(DATOS!F8),"—") -> 7.042885 | I7: =DATOS!H8 -> 1634 | J7: =DATOS!I8 -> 7080 | K7: =IFERROR((DATOS!I8-DATOS!H8)/ABS(DATOS!H8),"—") -> 3.3329253
B8: Land & Water (agua + agro) | C8: =DATOS!C9 | D8: =DATOS!D9 | E8: =DATOS!E9 | F8: =DATOS!F9 -> 350 | G8: =DATOS!G9 -> 431 | H8: =IFERROR((DATOS!G9-DATOS!F9)/ABS(DATOS!F9),"—") -> 0.23142857 | I8: =DATOS!H9 -> 986 | J8: =DATOS!I9 -> 996 | K8: =IFERROR((DATOS!I9-DATOS!H9)/ABS(DATOS!H9),"—") -> 0.010141988
B9: Water Filtration (ATEC) | C9: =DATOS!C10 | D9: =DATOS!D10 | E9: =DATOS!E10 | F9: =DATOS!F10 -> 163 | G9: =DATOS!G10 -> 3695 | H9: =IFERROR((DATOS!G10-DATOS!F10)/ABS(DATOS!F10),"—") -> 21.668712 | I9: =DATOS!H10 -> 648 | J9: =DATOS!I10 -> 6084 | K9: =IFERROR((DATOS!I10-DATOS!H10)/ABS(DATOS!H10),"—") -> 8.3888889
B10: Costo de ventas | C10: =DATOS!C11 | D10: =DATOS!D11 | E10: =DATOS!E11 | F10: =DATOS!F11 -> 852 | G10: =DATOS!G11 -> 2665 | H10: =IFERROR((DATOS!G11-DATOS!F11)/ABS(DATOS!F11),"—") -> 2.1279343 | I10: =DATOS!H11 -> 1856 | J10: =DATOS!I11 -> 4743 | K10: =IFERROR((DATOS!I11-DATOS!H11)/ABS(DATOS!H11),"—") -> 1.5554957
B11: UTILIDAD BRUTA | C11: =DATOS!C12 | D11: =DATOS!D12 | E11: =DATOS!E12 | F11: =DATOS!F12 -> -339 | G11: =DATOS!G12 -> 1461 | H11: =IFERROR((DATOS!G12-DATOS!F12)/ABS(DATOS!F12),"—") -> 5.3097345 | I11: =DATOS!H12 -> -222 | J11: =DATOS!I12 -> 2337 | K11: =IFERROR((DATOS!I12-DATOS!H12)/ABS(DATOS!H12),"—") -> 11.527027
B12: Gastos generales y admin | C12: =DATOS!C13 | D12: =DATOS!D13 | E12: =DATOS!E13 | F12: =DATOS!F13 -> 6305 | G12: =DATOS!G13 -> 6935 | H12: =IFERROR((DATOS!G13-DATOS!F13)/ABS(DATOS!F13),"—") -> 0.099920698 | I12: =DATOS!H13 -> 11035 | J12: =DATOS!I13 -> 15042 | K12: =IFERROR((DATOS!I13-DATOS!H13)/ABS(DATOS!H13),"—") -> 0.36311735
B13: PÉRDIDA OPERATIVA | C13: =DATOS!C14 | D13: =DATOS!D14 | E13: =DATOS!E14 | F13: =DATOS!F14 -> -6949 | G13: =DATOS!G14 -> -5777 | H13: =IFERROR((DATOS!G14-DATOS!F14)/ABS(DATOS!F14),"—") -> 0.16865736 | I13: =DATOS!H14 -> -11857 | J13: =DATOS!I14 -> -13310 | K13: =IFERROR((DATOS!I14-DATOS!H14)/ABS(DATOS!H14),"—") -> -0.12254365
B14: Gasto por intereses, neto | C14: =DATOS!C15 | D14: =DATOS!D15 | E14: =DATOS!E15 | F14: =DATOS!F15 -> -1921 | G14: =DATOS!G15 -> -1951 | H14: =IFERROR((DATOS!G15-DATOS!F15)/ABS(DATOS!F15),"—") -> -0.015616866 | I14: =DATOS!H15 -> -3860 | J14: =DATOS!I15 -> -4008 | K14: =IFERROR((DATOS!I15-DATOS!H15)/ABS(DATOS!H15),"—") -> -0.038341969
B15: PÉRDIDA NETA | C15: =DATOS!C16 | D15: =DATOS!D16 -> -30000 | E15: =DATOS!E16 -> -39200 | F15: =DATOS!F16 -> -8872 | G15: =DATOS!G16 -> -7730 | H15: =IFERROR((DATOS!G16-DATOS!F16)/ABS(DATOS!F16),"—") -> 0.12871957 | I15: =DATOS!H16 -> -15722 | J15: =DATOS!I16 -> -17323 | K15: =IFERROR((DATOS!I16-DATOS!H16)/ABS(DATOS!H16),"—") -> -0.10183183
B16: Dividendo preferentes | C16: =DATOS!C17 | D16: =DATOS!D17 | E16: =DATOS!E17 | F16: =DATOS!F17 -> -1288 | G16: =DATOS!G17 -> -1288 | H16: =IFERROR((DATOS!G17-DATOS!F17)/ABS(DATOS!F17),"—") -> 0 | I16: =DATOS!H17 -> -2553 | J16: =DATOS!I17 -> -2553 | K16: =IFERROR((DATOS!I17-DATOS!H17)/ABS(DATOS!H17),"—") -> 0
B17: EPS (US$) | C17: =DATOS!C19 | D17: =DATOS!D19 | E17: =DATOS!E19 | F17: =DATOS!F19 -> -0.15 | G17: =DATOS!G19 -> -0.11 | H17: =IFERROR((DATOS!G19-DATOS!F19)/ABS(DATOS!F19),"—") -> 0.26666667 | I17: =DATOS!H19 -> -0.27 | J17: =DATOS!I19 -> -0.25 | K17: =IFERROR((DATOS!I19-DATOS!H19)/ABS(DATOS!H19),"—") -> 0.074074074
B19: Lectura: aquí hay dos historias en un solo estado. La primera es el despegue de ATEC, el negocio de filtros de agua: sus ingresos pasaron de $163 mil a $3.7 millones en un solo trimestre (de 4 filtros enviados a 115), y ya genera margen bruto positivo del ~44%. Esa es la señal de que la parte "comercial" de Cadiz está encontrando tracción real. La segunda historia es que el gran negocio —los derechos de agua y el proyecto Mojave Groundwater Bank— sigue siendo pre-ingreso: genera casi nada hoy porque el proyecto aún se está financiando y construyendo. Por eso, pese al crecimiento de ATEC, la empresa sigue perdiendo dinero: los gastos de desarrollar el Mojave (honorarios legales, ingeniería) y el interés de su deuda pesan más que los ingresos actuales. En resumen: el motor pequeño (ATEC) ya arrancó; el motor grande (el agua) todavía no.

Sheet Balance
B2: BALANCE GENERAL — dic24 → jun25 (Q2) (miles $)
B3: Dos claves: (1) los activos de agua están A COSTO histórico, muy por debajo de su valor real; (2) la deuda es pesada. Verde = de DATOS.
B5: Partida (miles $) | C5: Dic-24 | D5: Jun-25 | E5: Comentario
B6: ACTIVOS
B7: Caja + restringida | C7: =DATOS!J22 -> 17292 | D7: =DATOS!K22 -> 13205 | E7: ~$16M. Baja por quema + capex Mojave.
B8: Cuentas por cobrar | C8: =DATOS!J24 -> 4586 | D8: =DATOS!K24 -> 4090
B9: Inventarios (filtros ATEC) | C9: =DATOS!J25 -> 3020 | D9: =DATOS!K25 -> 3011
B10: Total activo corriente | C10: =DATOS!J26 -> 25786 | D10: =DATOS!K26 -> 21039
B11: PP&E + programas de agua | C11: =DATOS!J27 -> 88362 | D11: =DATOS!K27 -> 92605 | E11: A COSTO histórico (~$92M): NO refleja el valor real del agua.
B12: Goodwill + otros | C12: =DATOS!J28 -> 5714 | D12: =DATOS!K28 -> 5714 | E12: De ATEC.
B13: TOTAL ACTIVOS | C13: =DATOS!J30 -> 134494 | D13: =DATOS!K30 -> 136379
B14: PASIVOS Y PATRIMONIO
B15: Pasivos operativos + diferidos | C15: =DATOS!J31 -> 10258 | D15: =DATOS!K31 -> 6840
B16: Deuda de largo plazo | C16: =DATOS!J34 -> 56708 | D16: =DATOS!K34 -> 58751 | E16: Heerema 7% (convertible + no conv).
B17: Lease LP con parte relacionada | C17: =DATOS!J35 -> 25275 | D17: =DATOS!K35 -> 26594 | E17: Heerema. Cuasi-deuda.
B18: TOTAL PASIVOS | C18: =DATOS!J36 -> 100533 | D18: =DATOS!K36 -> 100813 | E18: PESADO: ~$101M frente a $136M de activos a costo.
B19: PATRIMONIO (total) | C19: =DATOS!J37 -> 33961 | D19: =DATOS!K37 -> 35566 | E19: Delgado: ~$36M (incluye preferentes).
B21: MÉTRICAS
B22: Deuda total / Patrimonio | C22: =IFERROR(DATOS!J38/DATOS!J37,"n/d") -> 2.4140337 | D22: =IFERROR(DATOS!K38/DATOS!K37,"n/d") -> 2.3996232 | E22: ALTA: >2x. Apalancamiento elevado.
B23: Razón corriente | C23: =IFERROR(DATOS!J26/DATOS!J33,"n/d") -> 1.7899486 | D23: =IFERROR(DATOS!K26/DATOS!K33,"n/d") -> 1.8146455 | E23: Aceptable, sin holgura.
B24: Caja / Deuda total | C24: =IFERROR(DATOS!J22/DATOS!J38,"n/d") -> 0.21092178 | D24: =IFERROR(DATOS!K22/DATOS!K38,"n/d") -> 0.15472494 | E24: Baja: la caja no cubre ni 1/5 de la deuda.
B25: Patrimonio / Activos | C25: =IFERROR(DATOS!J37/DATOS!J30,"n/d") -> 0.25250941 | D25: =IFERROR(DATOS!K37/DATOS!K30,"n/d") -> 0.26078795 | E25: Bajo: muy apalancada.
B27: Lectura: el balance de Cadiz esconde su verdadera historia, y por partida doble. Por el lado de los activos, sus tierras y programas de agua figuran a costo histórico (~$92M), una cifra que no tiene nada que ver con lo que valen realmente 2.5 millones de acre-pies de derechos de agua en el sur de California, una de las regiones con mayor estrés hídrico del país. Ese es el "activo oculto" que justifica valorar la empresa por NAV y no por su balance contable. Pero por el lado de los pasivos hay una advertencia igual de importante: Cadiz está fuertemente endeudada (~$85M entre deuda y lease con Heerema, su acreedor-accionista que controla el 31.4%), y su patrimonio es delgado. Además necesitará ~$800M para construir el Mojave. En una palabra: activos potencialmente muy valiosos, pero un balance apalancado y dependiente de financiación externa. El agua vale mucho; la deuda pesa mucho.

Sheet Análisis Financiero
B2: ANÁLISIS FINANCIERO — activos de agua, apalancamiento y supervivencia
B3: Los ratios de rentabilidad no aplican (pierde). El foco: el valor de los activos de agua, el peso de la deuda, y la pista de liquidez. Metodología Celsia adaptada a una empresa de recursos con deuda.
B5: Indicador | C5: Dic-2024 | D5: Jun-2025 | E5: Interpretación
B6: 1 · EL ACTIVO CENTRAL: EL AGUA
B7: Derechos de agua (acre-pies) | C7: =DATOS!K44 -> 2500000 | D7: =DATOS!K44 -> 2500000 | E7: 2.5M AF: el corazón del valor. Recurso escaso.
B8: Contratado take-or-pay (AFY) | C8: =DATOS!K45 -> 21275 | D8: =DATOS!K45 -> 21275 | E8: 21,275 AFY ya vendidos a ~$850/AF por 40 años.
B9: PP&E en libros (miles $) | C9: =DATOS!J27 -> 88362 | D9: =DATOS!K27 -> 92605 | E9: A costo: subestima enormemente el valor real.
B10: 2 · APALANCAMIENTO (el gran riesgo)
B11: Deuda total (miles $) | C11: =DATOS!J38 -> 81983 | D11: =DATOS!K38 -> 85345 | E11: Deuda + lease Heerema. Pesada.
B12: Deuda / Patrimonio | C12: =IFERROR(DATOS!J38/DATOS!J37,"n/d") -> 2.4140337 | D12: =IFERROR(DATOS!K38/DATOS!K37,"n/d") -> 2.3996232 | E12: >2x: muy apalancada para una empresa que pierde.
B13: Interés anual (miles $) | C13: =-DATOS!I15*2 -> 8016 | D13: =-DATOS!I15*2 -> 8016 | E13: ~$8M/año. Consume caja y parte es PIK (crece).
B14: Dividendo preferente anual (miles $) | C14: =-DATOS!I17*2 -> 5106 | D14: =-DATOS!I17*2 -> 5106 | E14: ~$5M/año a las preferentes (CDZIP). Senior a comunes.
B15: 3 · SUPERVIVENCIA Y LIQUIDEZ
B16: Caja + restringida (miles $) | C16: =DATOS!J22+DATOS!J23 -> 17426 | D16: =DATOS!K22+DATOS!K23 -> 15964 | E16: ~$16M. Reforzada con emisiones de acciones.
B17: Quema operativa anual (miles $) | C17: =-DATOS!I40*2 -> 10000 | D17: =-DATOS!I40*2 -> 10000 | E17: ~$10M/año. Mejora al crecer ATEC.
B18: Pista de liquidez (meses) | C18: =IFERROR((DATOS!K22+DATOS!K23)/(-DATOS!I40*2)*12,"n/d") -> 19.1568 | D18: =IFERROR((DATOS!K22+DATOS!K23)/(-DATOS!I40*2)*12,"n/d") -> 19.1568 | E18: Corta: depende de seguir levantando capital/deuda.
B19: 4 · ACTIVO OCULTO
B20: NOL fiscal federal (miles $) | C20: =DATOS!K46 -> 368000 | D20: =DATOS!K46 -> 368000 | E20: $368M de pérdidas: escudo fiscal para futuras ganancias.
B21: Ingresos ATEC (H1, miles $) | C21: ="n/d" -> n/d | D21: =DATOS!I10 -> 6084 | E21: El segmento que ya funciona y crece rápido.
B23: Diagnóstico: Cadiz es, en esencia, una gran apuesta al valor del agua en el suroeste de Estados Unidos, envuelta en un balance apalancado. Lo que hay que sopesar son tres cosas a la vez. Primero, el activo: 2.5 millones de acre-pies de derechos de agua y capacidad de almacenamiento en una región sedienta, con contratos take-or-pay ya firmados que validan la demanda — un valor que el balance contable esconde por completo. Segundo, el riesgo financiero: la deuda es pesada (~$85M), el interés y los dividendos preferentes consumen ~$13M al año, y el proyecto estrella (Mojave) necesita ~$800M que aún no están asegurados. Tercero, la señal positiva: el negocio de filtros ATEC ya despegó y crece rápido, dando ingresos reales mientras el agua madura, y hay un NOL fiscal de $368M que hará que las futuras ganancias tributen poco. El veredicto financiero: no se valora por sus flujos actuales, sino por la suma de sus activos de agua menos su deuda — con la ejecución del Mojave y el manejo del apalancamiento como las grandes incógnitas.

Sheet Proyecciones
B2: MODELO DE TRES ESTADOS PROYECTADOS Y ENLAZADOS (5 años) — Cadiz (miles $)
B3: Rampa dual: ATEC crece + arranca el agua contratada. El margen cruza a positivo (año 3) cuando el agua de alto margen fluye. A diferencia de otras opciones, aquí la DEUDA es real: el interés se modela explícitamente. DESCUADRE verifica el cuadre (=0).
B6: Concepto (miles $) | C6: Base FY25 | D6: Año 1 | E6: Año 2 | F6: Año 3 | G6: Año 4 | H6: Año 5 | I6: Notas / enlace
B7: 1 · ESTADO DE RESULTADOS
B8: Ingresos | C8: =DATOS!$K$69 -> 16300 | D8: =C8*(1+DATOS!$K$70) -> 23635 | E8: =D8*(1+DATOS!$K$71) -> 37816 | F8: =E8*(1+DATOS!$K$72) -> 68068.8 | G8: =F8*(1+DATOS!$K$73) -> 105506.64 | H8: =G8*(1+DATOS!$K$74) -> 147709.3 | I8: ATEC + agro + agua contratada entrando.
B9: Crecimiento % | D9: =D8/C8-1 -> 0.45 | E9: =E8/D8-1 -> 0.6 | F9: =F8/E8-1 -> 0.8 | G9: =G8/F8-1 -> 0.55 | H9: =H8/G8-1 -> 0.4
B10: Ingreso operativo (EBIT) | D10: =D8*DATOS!$K$75 -> -12999.25 | E10: =E8*DATOS!$K$76 -> -9454 | F10: =F8*DATOS!$K$77 -> 3403.44 | G10: =G8*DATOS!$K$78 -> 23211.461 | H10: =H8*DATOS!$K$79 -> 51698.254 | I10: Ventas × margen EBIT (negativo hasta año 3).
B11: Margen EBIT % | D11: =DATOS!$K$75 -> -0.55 | E11: =DATOS!$K$76 -> -0.25 | F11: =DATOS!$K$77 -> 0.05 | G11: =DATOS!$K$78 -> 0.22 | H11: =DATOS!$K$79 -> 0.35 | I11: De −55% a +35%. Cruza a positivo en el año 3.
B12: (−) Gasto por intereses | D12: =-C25*DATOS!$K$84 -> -6827.6 | E12: =-D25*DATOS!$K$84 -> -8071.608 | F12: =-E25*DATOS!$K$84 -> -9617.3806 | G12: =-F25*DATOS!$K$84 -> -10179.085 | H12: =-G25*DATOS!$K$84 -> -9668.6248 | I12: Sobre la deuda del año anterior. Real y pesado.
B13: Utilidad antes de impuestos | D13: =D10+D12 -> -19826.85 | E13: =E10+E12 -> -17525.608 | F13: =F10+F12 -> -6213.9406 | G13: =G10+G12 -> 13032.376 | H13: =H10+H12 -> 42029.629
B14: (−) Impuestos (mitigado por NOL) | D14: =MAX(0,D13)*DATOS!K56*0.2 -> 0 | E14: =MAX(0,E13)*DATOS!K56*0.2 -> 0 | F14: =MAX(0,F13)*DATOS!K56*0.2 -> 0 | G14: =MAX(0,G13)*DATOS!K56*0.2 -> 547.3598 | H14: =MAX(0,H13)*DATOS!K56*0.2 -> 1765.2444 | I14: Solo 20% de la tasa: el NOL de $368M escuda casi todo.
B15: UTILIDAD (PÉRDIDA) NETA | D15: =D13-D14 -> -19826.85 | E15: =E13-E14 -> -17525.608 | F15: =F13-F14 -> -6213.9406 | G15: =G13-G14 -> 12485.016 | H15: =H13-H14 -> 40264.384
B17: 2 · BALANCE GENERAL
B18: Caja + restringida | C18: =DATOS!K22+DATOS!K23 -> 15964 | D18: =D39 -> 9780 | E18: =E39 -> 9780 | F18: =F39 -> 9780 | G18: =G39 -> 9780 | H18: =H39 -> 10373.888 | I18: ← Caja final del Flujo.
B19: Cuentas por cobrar | C19: =DATOS!K24 -> 4090 | D19: =D8*(DATOS!K24/DATOS!$K$69) -> 5930.5 | E19: =E8*(DATOS!K24/DATOS!$K$69) -> 9488.8 | F19: =F8*(DATOS!K24/DATOS!$K$69) -> 17079.84 | G19: =G8*(DATOS!K24/DATOS!$K$69) -> 26473.752 | H19: =H8*(DATOS!K24/DATOS!$K$69) -> 37063.253 | I19: Ratio CxC/ventas.
B20: Inventarios | C20: =DATOS!K25 -> 3011 | D20: =D8*(DATOS!K25/DATOS!$K$69) -> 4365.95 | E20: =E8*(DATOS!K25/DATOS!$K$69) -> 6985.52 | F20: =F8*(DATOS!K25/DATOS!$K$69) -> 12573.936 | G20: =G8*(DATOS!K25/DATOS!$K$69) -> 19489.601 | H20: =H8*(DATOS!K25/DATOS!$K$69) -> 27285.441 | I20: Ratio inventario/ventas.
B21: PP&E + programas de agua | C21: =DATOS!K27 -> 92605 | D21: =C21+D8*DATOS!$K$82-D8*DATOS!$K$81 -> 98277.4 | E21: =D21+E8*DATOS!$K$82-E8*DATOS!$K$81 -> 107353.24 | F21: =E21+F8*DATOS!$K$82-F8*DATOS!$K$81 -> 123689.75 | G21: =F21+G8*DATOS!$K$82-G8*DATOS!$K$81 -> 149011.35 | H21: =G21+H8*DATOS!$K$82-H8*DATOS!$K$81 -> 184461.58 | I21: + CapEx − depreciación (infraestructura de agua).
B22: Otros activos (goodwill, resto) | C22: =DATOS!K30-DATOS!K22-DATOS!K23-DATOS!K24-DATOS!K25-DATOS!K27 -> 20709 | D22: =C22 -> 20709 | E22: =D22 -> 20709 | F22: =E22 -> 20709 | G22: =F22 -> 20709 | H22: =G22 -> 20709 | I22: Resto constante.
B23: TOTAL ACTIVOS | C23: =C18+C19+C20+C21+C22 -> 136379 | D23: =D18+D19+D20+D21+D22 -> 139062.85 | E23: =E18+E19+E20+E21+E22 -> 154316.56 | F23: =F18+F19+F20+F21+F22 -> 183832.53 | G23: =G18+G19+G20+G21+G22 -> 225463.7 | H23: =H18+H19+H20+H21+H22 -> 279893.16
B24: Pasivos operativos | C24: =DATOS!K36-DATOS!K38 -> 15468 | D24: =D8*((DATOS!K36-DATOS!K38)/DATOS!$K$69) -> 22428.6 | E24: =E8*((DATOS!K36-DATOS!K38)/DATOS!$K$69) -> 35885.76 | F24: =F8*((DATOS!K36-DATOS!K38)/DATOS!$K$69) -> 64594.368 | G24: =G8*((DATOS!K36-DATOS!K38)/DATOS!$K$69) -> 100121.27 | H24: =H8*((DATOS!K36-DATOS!K38)/DATOS!$K$69) -> 140169.78 | I24: Ratio pasivos oper./ventas.
B25: Deuda + financiación (plug) | C25: =DATOS!K38 -> 85345 | D25: =D23-D24-D27 -> 100895.1 | E25: =E23-E24-E27 -> 120217.26 | F25: =F23-F24-F27 -> 127238.56 | G25: =G23-G24-G27 -> 120857.81 | H25: =H23-H24-H27 -> 94974.378 | I25: PLUG: deuda/capital que necesita para cuadrar.
B26: TOTAL PASIVOS | C26: =C24+C25 -> 100813 | D26: =D24+D25 -> 123323.7 | E26: =E24+E25 -> 156103.02 | F26: =F24+F25 -> 191832.93 | G26: =G24+G25 -> 220979.08 | H26: =H24+H25 -> 235144.16
B27: PATRIMONIO | C27: =DATOS!K37 -> 35566 | D27: =C27+D15 -> 15739.15 | E27: =D27+E15 -> -1786.458 | F27: =E27+F15 -> -8000.3986 | G27: =F27+G15 -> 4484.6177 | H27: =G27+H15 -> 44749.002 | I27: Previo + utilidad (o − pérdida).
B28: TOTAL PASIVO + PATRIMONIO | C28: =C26+C27 -> 136379 | D28: =D26+D27 -> 139062.85 | E28: =E26+E27 -> 154316.56 | F28: =F26+F27 -> 183832.53 | G28: =G26+G27 -> 225463.7 | H28: =H26+H27 -> 279893.16
B29: DESCUADRE (Activo − Pas − Patr) | C29: =C23-C28 -> 0 | D29: =D23-D28 -> 0 | E29: =E23-E28 -> 0 | F29: =F23-F28 -> 0 | G29: =G23-G28 -> 0 | H29: =H23-H28 -> 0 | I29: DEBE SER 0.
B31: 3 · FLUJO DE CAJA
B32: Utilidad (pérdida) neta | D32: =D15 -> -19826.85 | E32: =E15 -> -17525.608 | F32: =F15 -> -6213.9406 | G32: =G15 -> 12485.016 | H32: =H15 -> 40264.384 | I32: ← Resultados.
B33: (+) Depreciación | D33: =D8*DATOS!$K$81 -> 1418.1 | E33: =E8*DATOS!$K$81 -> 2268.96 | F33: =F8*DATOS!$K$81 -> 4084.128 | G33: =G8*DATOS!$K$81 -> 6330.3984 | H33: =H8*DATOS!$K$81 -> 8862.5578 | I33: No-caja.
B34: (−) Δ Capital de trabajo | D34: =-(D8-C8)*DATOS!$K$83 -> -733.5 | E34: =-(E8-D8)*DATOS!$K$83 -> -1418.1 | F34: =-(F8-E8)*DATOS!$K$83 -> -3025.28 | G34: =-(G8-F8)*DATOS!$K$83 -> -3743.784 | H34: =-(H8-G8)*DATOS!$K$83 -> -4220.2656 | I34: Sobre crecimiento de ventas.
B35: Flujo de caja operativo | D35: =D32+D33+D34 -> -19142.25 | E35: =E32+E33+E34 -> -16674.748 | F35: =F32+F33+F34 -> -5155.0926 | G35: =G32+G33+G34 -> 15071.631 | H35: =H32+H33+H34 -> 44906.677
B36: (−) CapEx | D36: =-D8*DATOS!$K$82 -> -7090.5 | E36: =-E8*DATOS!$K$82 -> -11344.8 | F36: =-F8*DATOS!$K$82 -> -20420.64 | G36: =-G8*DATOS!$K$82 -> -31651.992 | H36: =-H8*DATOS!$K$82 -> -44312.789 | I36: Infraestructura (el Mojave se financia aparte vía MWI).
B37: Flujo de caja libre (FCF) | D37: =D35+D36 -> -26232.75 | E37: =E35+E36 -> -28019.548 | F37: =F35+F36 -> -25575.733 | G37: =G35+G36 -> -16580.361 | H37: =H35+H36 -> 593.88773 | I37: OCF − CapEx. Alimenta el DCF. Negativo al inicio.
B38: Caja inicial | D38: =DATOS!K22+DATOS!K23 -> 15964 | E38: =D39 -> 9780 | F38: =E39 -> 9780 | G38: =F39 -> 9780 | H38: =G39 -> 9780
B39: Caja final | D39: =MAX(DATOS!$K$69*0.6,D38+D37) -> 9780 | E39: =MAX(DATOS!$K$69*0.6,E38+E37) -> 9780 | F39: =MAX(DATOS!$K$69*0.6,F38+F37) -> 9780 | G39: =MAX(DATOS!$K$69*0.6,G38+G37) -> 9780 | H39: =MAX(DATOS!$K$69*0.6,H38+H37) -> 10373.888 | I39: → Caja del Balance (con piso ~$10M; se financia si baja).
B41: Cómo leerlo: esta proyección captura la tesis de Cadiz — una transición de "empresa que gasta" a "empresa que cobra por el agua". Los ingresos crecen fuerte (ATEC primero, luego el agua contratada del Northern Pipeline entrando en los años 2-3), y el margen operativo da un giro notable: de muy negativo a +35%, porque vender agua bajo contratos take-or-pay es un negocio de altísimo margen una vez que la infraestructura existe. Dos matices propios de Cadiz que el modelo incorpora: el gasto por intereses es real y pesado (tiene deuda de verdad, no como las otras opciones), y los impuestos están casi anulados por el escudo fiscal del NOL de $368M. El CapEx del gigantesco proyecto Mojave se financia por separado (vía la filial MWI con inversores externos), no se carga aquí. Todo cuadra (Descuadre=0). La gran incógnita: que el agua efectivamente empiece a fluir y generar ingresos según lo contratado.

Sheet Valoración
B2: VALORACIÓN — NAV / Suma de Partes (principal) · WACC · DCF
B3: El valor de Cadiz está en sus activos de agua (a costo en libros), no en sus flujos actuales. Método principal: NAV = activos de agua − deuda. Amarillo=editable. Cifras internas en miles $.
B5: 1 · NAV / SUMA DE PARTES (método principal)
B6: Activo / componente | C6: Valor (miles $) | E6: Qué es y por qué vale eso
B7: Derechos de agua (suministro) | C7: =DATOS!K48 -> 300000 | E7: 2.5M acre-pies. Recurso escaso en California. El activo central.
B8: Capacidad de almacenamiento | C8: =DATOS!K49 -> 80000 | E8: 1M acre-pies de banco de agua (Mojave).
B9: Infraestructura (tuberías) | C9: =DATOS!K50 -> 90000 | E9: 220 millas Northern + derecho de Southern Pipeline.
B10: Negocio ATEC (filtración) | C10: =DATOS!K51 -> 60000 | E10: Segmento en crecimiento, margen +44%. Ya funciona.
B11: (+) Escudo fiscal NOL (20% de $368M) | C11: =DATOS!K46*0.2 -> 73600 | E11: Valor del ahorro fiscal futuro (estimación conservadora).
B12: (+) Caja − (−) Deuda total (miles $) | C12: =DATOS!K22+DATOS!K23-DATOS!K38 -> -69381 | E12: Puente a equity. NEGATIVO: la deuda supera la caja (el gran lastre).
B13: (−) Preferentes (valor de liquidación) | C13: =-2300*25 -> -57500 | E13: 2,300 pref × $25k liq = $57.5M. Senior a las comunes.
B14: NAV para comunes (miles $) | C14: =SUM(C7:C10)+C11+C12+C13 -> 476719
B15: NAV por acción común ($) | C15: =C14/1000/DATOS!K20 -> 5.8136463
B17: 2 · COSTO DE CAPITAL (WACC vía CAPM)
B18: Tasa libre de riesgo (Rf) | C18: =DATOS!K53 -> 0.043 | E18: De DATOS.
B19: Prima de riesgo (ERP) | C19: =DATOS!K54 -> 0.055 | E19: De DATOS.
B20: Beta desapalancado (βu) | C20: =DATOS!K55 -> 1.2 | E20: Agua = defensivo. De DATOS.
B21: Valor de mercado del equity (miles $) | C21: =DATOS!K43*DATOS!K20*1000 -> 246000 | E21: Precio × ~82M acciones.
B22: Valor de la deuda (miles $) | C22: =DATOS!K38 -> 85345 | E22: Deuda + lease Heerema. Pesada.
B23: Peso deuda D/(D+E) | C23: =C22/(C22+C21) -> 0.25757141 | E23: Alto: muy apalancada.
B24: Peso equity E/(D+E) | C24: =C21/(C22+C21) -> 0.74242859
B25: Tasa impositiva (t) | C25: =DATOS!K56 -> 0.21
B26: Beta apalancado (βL, Hamada) | C26: =C20*(1+(1-C25)*C22/C21) -> 1.5288905 | E26: βu×(1+(1−t)×D/E). Alto por la deuda.
B27: Costo del equity (Ke=CAPM) | C27: =C18+C26*C19 -> 0.12708898 | E27: Rf+βL×ERP.
B28: Costo de la deuda (Kd) | C28: =DATOS!K57 -> 0.09
B29: WACC | C29: =C24*C27+C23*C28*(1-C25) -> 0.11266782 | E29: We×Ke+Wd×Kd(1−t).
B31: 3 · DCF (secundario, valida la senda operativa)
B32: Año | C32: FCF (miles $) | D32: VP (miles $) | E32: FCF de Proyecciones. Negativo al inicio (invierte en agua).
B33: 1 | C33: =Proyecciones!D37 -> -26232.75 | D33: =C33/(1+C29)^1 -> -23576.444
B34: 2 | C34: =Proyecciones!E37 -> -28019.548 | D34: =C34/(1+C29)^2 -> -22632.372
B35: 3 | C35: =Proyecciones!F37 -> -25575.733 | D35: =C35/(1+C29)^3 -> -18566.562
B36: 4 | C36: =Proyecciones!G37 -> -16580.361 | D36: =C36/(1+C29)^4 -> -10817.624
B37: 5 | C37: =Proyecciones!H37 -> 593.88773 | D37: =C37/(1+C29)^5 -> 348.23845
B38: FCF terminal normalizado (miles $) | C38: =Proyecciones!H8*DATOS!K58*(1-DATOS!K56*0.2) -> 49526.927 | E38: Ventas año5 × margen terminal × (casi sin impuesto por NOL).
B39: Valor terminal (Gordon, g=3%) | C39: =C38*(1.03)/(C29-0.03) -> 617080.95 | D39: =C39/(1+C29)^5 -> 361838.28 | E39: g perpetuo 3% (agua: demanda estructural creciente).
B40: Valor patrimonio — DCF (miles $) | C40: =SUM(D33:D37)+D39+DATOS!K22+DATOS!K23-DATOS!K38-2300*25 -> 159712.51 | E40: Menos deuda y preferentes.
B41: Valor por acción — DCF ($) | C41: =C40/1000/DATOS!K20 -> 1.9477136
B43: 4 · SÍNTESIS
B44: Valor/acción — NAV (principal) ($) | C44: =C15 -> 5.8136463 | E44: Valor de los activos de agua − deuda − preferentes.
B45: Valor/acción — DCF ($) | C45: =C41 -> 1.9477136 | E45: Si la rampa de agua contratada se cumple.
...

Sheet Sensibilidad
B2: ANÁLISIS DE SENSIBILIDAD — Valor por acción (NAV)
B3: Valor de los derechos de agua+almacenamiento (filas) × valor de la infraestructura+ATEC (columnas), en $M. Son los grandes componentes del NAV.
B5: Agua \ Infra+ATEC ($M) | C5: 80 | D5: 120 | E5: 150 | F5: 200 | G5: 280
B6: 250 | C6: =(($B6*1000+C$5*1000+(DATOS!K46*0.2+DATOS!K22+DATOS!K23-DATOS!K38-2300*25)))/1000/DATOS!K20 -> 3.374622 | D6: =(($B6*1000+D$5*1000+(DATOS!K46*0.2+DATOS!K22+DATOS!K23-DATOS!K38-2300*25)))/1000/DATOS!K20 -> 3.8624268 | E6: =(($B6*1000+E$5*1000+(DATOS!K46*0.2+DATOS!K22+DATOS!K23-DATOS!K38-2300*25)))/1000/DATOS!K20 -> 4.2282805 | F6: =(($B6*1000+F$5*1000+(DATOS!K46*0.2+DATOS!K22+DATOS!K23-DATOS!K38-2300*25)))/1000/DATOS!K20 -> 4.8380366 | G6: =(($B6*1000+G$5*1000+(DATOS!K46*0.2+DATOS!K22+DATOS!K23-DATOS!K38-2300*25)))/1000/DATOS!K20 -> 5.8136463
B7: 350 | C7: =(($B7*1000+C$5*1000+(DATOS!K46*0.2+DATOS!K22+DATOS!K23-DATOS!K38-2300*25)))/1000/DATOS!K20 -> 4.5941341 | D7: =(($B7*1000+D$5*1000+(DATOS!K46*0.2+DATOS!K22+DATOS!K23-DATOS!K38-2300*25)))/1000/DATOS!K20 -> 5.081939 | E7: =(($B7*1000+E$5*1000+(DATOS!K46*0.2+DATOS!K22+DATOS!K23-DATOS!K38-2300*25)))/1000/DATOS!K20 -> 5.4477927 | F7: =(($B7*1000+F$5*1000+(DATOS!K46*0.2+DATOS!K22+DATOS!K23-DATOS!K38-2300*25)))/1000/DATOS!K20 -> 6.0575488 | G7: =(($B7*1000+G$5*1000+(DATOS!K46*0.2+DATOS!K22+DATOS!K23-DATOS!K38-2300*25)))/1000/DATOS!K20 -> 7.0331585
B8: 450 | C8: =(($B8*1000+C$5*1000+(DATOS!K46*0.2+DATOS!K22+DATOS!K23-DATOS!K38-2300*25)))/1000/DATOS!K20 -> 5.8136463 | D8: =(($B8*1000+D$5*1000+(DATOS!K46*0.2+DATOS!K22+DATOS!K23-DATOS!K38-2300*25)))/1000/DATOS!K20 -> 6.3014512 | E8: =(($B8*1000+E$5*1000+(DATOS!K46*0.2+DATOS!K22+DATOS!K23-DATOS!K38-2300*25)))/1000/DATOS!K20 -> 6.6673049 | F8: =(($B8*1000+F$5*1000+(DATOS!K46*0.2+DATOS!K22+DATOS!K23-DATOS!K38-2300*25)))/1000/DATOS!K20 -> 7.277061 | G8: =(($B8*1000+G$5*1000+(DATOS!K46*0.2+DATOS!K22+DATOS!K23-DATOS!K38-2300*25)))/1000/DATOS!K20 -> 8.2526707
B9: 600 | C9: =(($B9*1000+C$5*1000+(DATOS!K46*0.2+DATOS!K22+DATOS!K23-DATOS!K38-2300*25)))/1000/DATOS!K20 -> 7.6429146 | D9: =(($B9*1000+D$5*1000+(DATOS!K46*0.2+DATOS!K22+DATOS!K23-DATOS!K38-2300*25)))/1000/DATOS!K20 -> 8.1307195 | E9: =(($B9*1000+E$5*1000+(DATOS!K46*0.2+DATOS!K22+DATOS!K23-DATOS!K38-2300*25)))/1000/DATOS!K20 -> 8.4965732 | F9: =(($B9*1000+F$5*1000+(DATOS!K46*0.2+DATOS!K22+DATOS!K23-DATOS!K38-2300*25)))/1000/DATOS!K20 -> 9.1063293 | G9: =(($B9*1000+G$5*1000+(DATOS!K46*0.2+DATOS!K22+DATOS!K23-DATOS!K38-2300*25)))/1000/DATOS!K20 -> 10.081939
B10: 800 | C10: =(($B10*1000+C$5*1000+(DATOS!K46*0.2+DATOS!K22+DATOS!K23-DATOS!K38-2300*25)))/1000/DATOS!K20 -> 10.081939 | D10: =(($B10*1000+D$5*1000+(DATOS!K46*0.2+DATOS!K22+DATOS!K23-DATOS!K38-2300*25)))/1000/DATOS!K20 -> 10.569744 | E10: =(($B10*1000+E$5*1000+(DATOS!K46*0.2+DATOS!K22+DATOS!K23-DATOS!K38-2300*25)))/1000/DATOS!K20 -> 10.935598 | F10: =(($B10*1000+F$5*1000+(DATOS!K46*0.2+DATOS!K22+DATOS!K23-DATOS!K38-2300*25)))/1000/DATOS!K20 -> 11.545354 | G10: =(($B10*1000+G$5*1000+(DATOS!K46*0.2+DATOS!K22+DATOS!K23-DATOS!K38-2300*25)))/1000/DATOS!K20 -> 12.520963
B12: Precio de mercado: | C12: =DATOS!K43 -> 3 | D12: Compara cada celda con el precio de ~$3.
B14: Lectura: el valor de Cadiz depende enteramente de cuánto valgan sus derechos de agua, y esa es una cifra difícil de precisar. La tabla lo hace explícito: con valuaciones conservadoras del agua (esquina superior izquierda) el NAV por acción puede quedar cerca o por debajo del precio; con valuaciones más generosas —justificables dado el estrés hídrico de California y los contratos ya firmados— el NAV supera holgadamente el precio. La deuda y las preferentes (restadas en todos los escenarios) son el lastre que reduce cuánto de ese valor del agua llega a las acciones comunes. La apuesta central: ¿cuánto vale realmente el agua en el suroeste, y logrará Cadiz monetizarla antes de que la deuda apriete?

Sheet Comparables
B2: ANÁLISIS DE COMPARABLES (Comps) — agua y recursos hídricos
B3: Ancla CDZI contra empresas de agua. Pure Cycle (PCYO) es el comparable directo (mismo tema, más maduro y sin deuda). Múltiplos aprox/editables (azul).
B5: Empresa | C5: Ticker | D5: EV/Ventas | E5: P/VC | F5: Comentario
B6: Pure Cycle | C6: PCYO | D6: 12 | E6: 1.8 | F6: Comparable directo: agua, rentable, SIN deuda. Referencia clave.
B7: American States Water | C7: AWR | D7: 6 | E7: 3.5 | F7: Utility de agua regulada, madura y rentable.
B8: California Water Service | C8: CWT | D8: 4.5 | E8: 2 | F8: Utility de agua de California. Referencia regional.
B9: Global Water Resources | C9: GWRS | D9: 10 | E9: 4 | F9: Agua/aguas residuales en el suroeste (Arizona).
B10: Consolidated Water | C10: CWCO | D10: 4 | E10: 2.5 | F10: Desalinización y agua. Rentable.
B11: MEDIANA | D11: =MEDIAN(D6:D10) -> 6 | E11: =MEDIAN(E6:E10) -> 2.5
B13: VALORACIÓN IMPLÍCITA DE CDZI ($/acción)
B14: Método | C14: Base (miles $) | D14: × múltiplo | E14: Valor/acción | H14: Nota
B15: Por EV/Ventas (ingreso año4 proj) | C15: =Proyecciones!G8 -> 105506.64 | D15: =D11 -> 6 | E15: =(Proyecciones!G8*D11+DATOS!K22-DATOS!K38-2300*25)/1000/DATOS!K20 -> 6.1390224 | F15: Ventas futuras (año4) × múlt − deuda − pref.
B16: Por P/VC (sobre patrimonio contable) | C16: =DATOS!K37 -> 35566 | D16: =E11 -> 2.5 | E16: =DATOS!K37*E11/1000/DATOS!K20 -> 1.0843293 | F16: Ojo: el patrimonio contable subestima el agua. Referencial.
B17: Precio de mercado ($) | E17: =DATOS!K43 -> 3
B19: Nota: el comparable natural de Cadiz es Pure Cycle (PCYO), que ya valoramos: misma tesis de agua en el suroeste, pero PCYO es rentable y no tiene deuda, mientras Cadiz es pre-rentabilidad y apalancada — por eso PCYO cotiza a múltiplos más altos y con menos riesgo. Las utilities de agua reguladas (American States, California Water) son negocios maduros y estables que enmarcan el múltiplo "de destino" si Cadiz logra convertirse en un proveedor de agua en operación. El comparable por ventas se aplica sobre los ingresos futuros (año 4), cuando el agua ya fluye, no sobre los actuales. El P/VC es poco informativo aquí porque el patrimonio contable esconde el valor real del agua — por eso el NAV (hoja Valoración) es el método principal.
