Workbook

Sheet Resumen
B2: CENTRUS ENERGY (NYSE: LEU) — Resumen Ejecutivo
B3: Modelo profesional (metodología Celsia/Murray). Arquitectura DATOS→fórmulas. Datos SEC 10-K/10-Q hasta Q2 2026 (5-ago-2026).
B5: CIFRAS CLAVE (jaladas de DATOS)
B6: Precio de la acción | C6: =DATOS!K66 -> 166.34 | D6: ~$166 (ago 2026). Editable en DATOS.
B7: Capitalización de mercado | C7: =DATOS!K66*DATOS!K67 -> 3318.483 | D7: Precio × 19.95M acciones.
B8: Ingresos FY2025 | C8: =DATOS!E11 -> 448.7 | D8: Año completo.
B9: Ingresos 1S 2026 | C9: =DATOS!K11 -> 252.8 | D9: Semestre (+11% vs 1S25).
B10: Utilidad neta FY2025 | C10: =DATOS!E29 -> 77.8
B11: Utilidad neta 1S 2026 | C11: =DATOS!K29 -> 26.8 | D11: GAAP −52%: por gastos de expansión.
B12: Utilidad ajustada 1S 2026 | C12: =DATOS!K30 -> 62.2 | D12: No-GAAP casi plana: núcleo sano.
B13: Caja (jun-2026) | C13: =DATOS!I37 -> 1868.5 | D13: Colchón: ~$1.9B.
B14: Deuda LP (jun-2026) | C14: =DATOS!I55 -> 1177.5 | D14: Convertibles.
B15: Posición neta de caja | C15: =DATOS!I37-DATOS!I55 -> 691 | D15: Caja − deuda. POSITIVA.
B16: Backlog (jun-2026) | C16: =DATOS!I68 -> 4500 | D16: Cartera a 2040. Creció a $4.5B.
B18: VEREDICTO
B19: Tipo de inversión | C19: Opción estratégica | D19: No es compuesto clásico ni 100-bagger. Apuesta asimétrica sobre el enriquecimiento occidental.
B20: Negocio hoy | C20: Rentable, pequeño | D20: Único enricher cotizado probado; ingresos lumpy; ROIC deprimido por caja ociosa.
B21: Balance | C21: Fortaleza | D21: Posición neta de caja. PP&E saltó 29→142M: la expansión ya es real, no promesa.
B22: Resultado 1S 2026 | C22: Sano en el núcleo | D22: GAAP cae por stock-comp + I+D de crecimiento; utilidad AJUSTADA casi plana.
B23: Motor de valor | C23: La expansión | D23: Convertir ~$1.9B caja + backlog $4.5B en capacidad HALEU/LEU rentable (2029+).
B24: Valoración | C24: Exigente | D24: Ver hoja Valoración: DCF del negocio actual queda por debajo del precio. El mercado paga la opción.
B25: Riesgo/premio | C25: Binario, asimétrico | D25: Piso por la caja; techo alto si ejecuta. Dimensiona según convicción.
B27: GUÍA DE HOJAS: DATOS (fuente+drivers) · Estado Resultados · Balance · Análisis Financiero · Proyecciones (3 estados enlazados) · Valoración (DCF real) · Sensibilidad (WACC×g) · Comparables.
B28: DATOS | C28: Fuente única. Números crudos SEC. Edita aquí para actualizar todo.
B29: Estado Resultados | C29: Comparación homogénea: Q1 vs Q1, Q2 vs Q2, 1S, anuales.
B30: Balance | C30: Cortes dic23→dic25→mar26→jun26 + métricas.
B31: Análisis Financiero | C31: Liquidez, Actividad (ciclo de caja), Endeudamiento, Rentabilidad, DuPont.
B32: Valoración | C32: WACC-CAPM, KTNO, NOPLAT, ROIC, g endógeno, DCF, valor intrínseco.
B34: DESCARGO: material educativo, no asesoría financiera. Verifica cada cifra en SEC EDGAR. Alto riesgo; puedes perder capital.

Sheet DATOS
B2: CENTRUS ENERGY (LEU) — HOJA DE DATOS CRUDOS (SEC 10-K / 10-Q)
B3: Fuente única del modelo. Números azules = directo de SEC. Las demás hojas jalan de aquí con fórmulas (sin datos escritos a mano). Para actualizar: edita SOLO esta hoja. Estructura de comparación homogénea: trimestres vs mismo trimestre del año anterior, semestre acumulado, y anuales completos por separado.
C5: ANUALES COMPLETOS | F5: Q1 (homólogo) | H5: Q2 (homólogo) | J5: 1S acumulado
B6: Concepto ($M) | C6: FY2023 | D6: FY2024 | E6: FY2025 | F6: Q1-25 | G6: Q1-26 | H6: Q2-25 | I6: Q2-26 | J6: 1S-25 | K6: 1S-26 | L6: Fuente / nota
B7: ESTADO DE RESULTADOS
B8: Ingresos SWU | F8: 51.3 | G8: 41.6 | H8: 125.7 | I8: 100 | J8: 177 | K8: 141.6 | L8: Q2: SWU 100.0(26) vs 125.7(25). Ajuste abajo.
B9: Ingresos Uranio | F9: 0 | G9: 3 | H9: 0 | I9: 53.4 | J9: 0 | K9: 56.4 | L9: Uranio: cero en 1S25, fuerte en Q2 26.
B10: Ingresos Technical Solutions | C10: 51.2 | D10: 92.1 | E10: 102.5 | F10: 21.8 | G10: 32.1 | H10: 28.8 | I10: 22.7 | J10: 50.6 | K10: 54.8 | L10: HALEU + servicios.
B11: INGRESOS TOTALES | C11: 320.2 | D11: 442 | E11: 448.7 | F11: 73.1 | G11: 76.7 | H11: 154.5 | I11: 176.1 | J11: 227.6 | K11: 252.8 | L11: Total revenue (10-Q/10-K).
B12: Costo SWU+Uranio | F12: 40.2 | G12: 45.2 | H12: 75 | I12: 101.8 | J12: 95.1 | K12: 118.5 | L12: Cost of sales LEU.
B13: Costo Technical Solutions | F13: 20.1 | G13: 29.3 | H13: 25.6 | I13: 24.4 | J13: 45.7 | K13: 52.9 | L13: Cost of sales TS.
B14: Costo de ventas total | C14: 208.1 | D14: 330.5 | E14: 331.2 | F14: 40.2 | G14: 45.2 | H14: 100.6 | I14: 126.2 | J14: 140.8 | K14: 171.4 | L14: Total cost of sales.
B15: UTILIDAD BRUTA | C15: 112.1 | D15: 111.5 | E15: 117.5 | F15: 32.9 | G15: 31.5 | H15: 53.9 | I15: 49.9 | J15: 86.8 | K15: 81.4 | L15: Gross profit.
B16: UB segmento LEU | C16: 105.1 | D16: 93.9 | E16: 111.5 | F16: 31.2 | G16: 30.1 | H16: 50.7 | I16: 51.6 | L16: Gross profit LEU.
B17: UB segmento TS | C17: 7 | D17: 17.6 | E17: 6 | F17: 1.7 | G17: 1.4 | H17: 3.2 | I17: -1.7 | L17: Gross profit TS. Q2 26 en pérdida.
B18: Costos tecnología avanzada (I+D) | F18: 3 | G18: 18.9 | H18: 3.3 | I18: 10.8 | J18: 6.3 | K18: 29.7 | L18: Advanced technology costs. Sube fuerte.
B19: Gastos SG&A | F19: 8.3 | G19: 10 | H19: 13.4 | I19: 26.2 | J19: 21.7 | K19: 36.2 | L19: SG&A. Q2 26 incluye +17.2 stock-comp RSU.
B20: Amortización intangibles | F20: 1.1 | G20: 1.8 | H20: 3.7 | I20: 2.5 | J20: 4.8 | K20: 4.3 | L20: Amortization.
B21: INGRESO OPERATIVO | E21: 50.2 | F21: 20.5 | G21: 0.8 | H21: 33.5 | I21: 10.4 | J21: 54 | K21: 11.2 | L21: Operating income.
B22: Componente no-op beneficio | F22: 0.9 | G22: 1 | H22: 1 | I22: 1 | J22: 1.9 | K22: 2 | L22: Nonoperating benefit loss.
B23: Gasto por intereses | F23: 3.4 | G23: 4 | H23: 3.1 | I23: 4.2 | J23: 6.5 | K23: 8.2 | L23: Interest expense.
B24: Ingreso por inversiones | F24: 7.3 | G24: 17 | H24: 8 | I24: 16.3 | J24: 15.3 | K24: 33.3 | L24: Investment income (positivo).
B25: Extinción de deuda (one-time) | F25: 11.8 | G25: 0 | H25: 0 | I25: 0 | J25: 11.8 | K25: 0 | L25: One-time Q1 25.
B26: Otros (ingreso) gasto | F26: 0 | G26: 0.2 | H26: 0 | I26: -0.1 | J26: 0.1 | K26: 0.2 | L26: Other.
B27: Utilidad antes de impuestos | F27: 35.2 | G27: 12.5 | H27: 37.4 | I27: 21.6 | J27: 72.6 | K27: 34.1 | L27: Pretax income.
B28: Impuesto sobre la renta | F28: 8 | G28: 2.5 | H28: 8.5 | I28: 4.8 | J28: 16.5 | K28: 7.3 | L28: Income tax.
B29: UTILIDAD NETA | C29: 84.4 | D29: 73.2 | E29: 77.8 | F29: 27.2 | G29: 10 | H29: 28.9 | I29: 16.8 | J29: 56.1 | K29: 26.8 | L29: Net income.
B30: Utilidad neta ajustada (no-GAAP) | H30: 34.5 | I30: 38.7 | J30: 63.1 | K30: 62.2 | L30: Ajustada por growth costs + stock-comp.
B31: EPS básico ($) | C31: 5.55 | F31: 1.6 | G31: 0.51 | H31: 1.63 | I31: 0.85 | J31: 3.23 | K31: 1.35 | L31: Basic EPS.
B32: EPS diluido ($) | C32: 5.44 | E32: 3.9 | F32: 1.6 | G32: 0.45 | H32: 1.59 | I32: 0.77 | J32: 3.22 | K32: 1.21 | L32: Diluted EPS.
B33: Acciones básicas (miles) | F33: 16982 | G33: 19773 | H33: 17703 | I33: 19879 | J33: 17344 | K33: 19826 | L33: Weighted avg basic.
B34: Acciones diluidas (miles) | F34: 17048 | G34: 22446 | H34: 18121 | I34: 21891 | J34: 17406 | K34: 22114 | L34: Weighted avg diluted.
B35: Depreciación y amortización | J35: 5.4 | K35: 5.1 | L35: D&A del flujo de caja (1S).
B36: BALANCE GENERAL (fin de periodo)
B37: Caja y equivalentes | C37: 201.2 | D37: 671.4 | E37: 1957.2 | G37: 1868.2 | I37: 1868.5 | L37: Cash. mar26 y jun26.
B38: Cuentas por cobrar | E38: 30.7 | G38: 41.8 | I38: 25.6 | L38: Accounts receivable.
B39: Inventarios | E39: 322.9 | G39: 336 | I39: 377.1 | L39: Inventories. Sube fuerte.
B40: Costos diferidos | E40: 40.9 | G40: 37 | I40: 33.2 | L40: Deferred costs.
B41: Otros activos corrientes | E41: 11.9 | G41: 12.4 | I41: 12.7 | L41: Other current assets.
B42: Total activo corriente | E42: 2363.6 | G42: 2295.4 | I42: 2317.1 | L42: Total current assets.
...

Sheet Estado Resultados
B2: ESTADO DE RESULTADOS — comparación homogénea (jala de DATOS)
B3: Se compara cada trimestre con su HOMÓLOGO del año anterior (Q1 vs Q1, Q2 vs Q2), el semestre acumulado (1S), y los anuales. Cada bloque trae su variación %. Verde = de DATOS.
C5: ANUALES | F5: Q1 (25→26) | I5: Q2 (25→26)
B6: Concepto ($M) | C6: FY23 | D6: FY24 | E6: FY25 | F6: Q1 25 | G6: Q1 26 | H6: Δ% | I6: Q2 25 | J6: Q2 26 | K6: Δ%
B7: Ingresos SWU | C7: =DATOS!C8 | D7: =DATOS!D8 | E7: =DATOS!E8 | F7: =DATOS!F8 -> 51.3 | G7: =DATOS!G8 -> 41.6 | H7: =IFERROR((DATOS!G8-DATOS!F8)/ABS(DATOS!F8),"—") -> -0.18908382 | I7: =DATOS!H8 -> 125.7 | J7: =DATOS!I8 -> 100 | K7: =IFERROR((DATOS!I8-DATOS!H8)/ABS(DATOS!H8),"—") -> -0.20445505
B8: Ingresos Uranio | C8: =DATOS!C9 | D8: =DATOS!D9 | E8: =DATOS!E9 | F8: =DATOS!F9 -> 0 | G8: =DATOS!G9 -> 3 | H8: =IFERROR((DATOS!G9-DATOS!F9)/ABS(DATOS!F9),"—") -> — | I8: =DATOS!H9 -> 0 | J8: =DATOS!I9 -> 53.4 | K8: =IFERROR((DATOS!I9-DATOS!H9)/ABS(DATOS!H9),"—") -> —
B9: Ingresos Technical Solutions | C9: =DATOS!C10 -> 51.2 | D9: =DATOS!D10 -> 92.1 | E9: =DATOS!E10 -> 102.5 | F9: =DATOS!F10 -> 21.8 | G9: =DATOS!G10 -> 32.1 | H9: =IFERROR((DATOS!G10-DATOS!F10)/ABS(DATOS!F10),"—") -> 0.47247706 | I9: =DATOS!H10 -> 28.8 | J9: =DATOS!I10 -> 22.7 | K9: =IFERROR((DATOS!I10-DATOS!H10)/ABS(DATOS!H10),"—") -> -0.21180556
B10: INGRESOS TOTALES | C10: =DATOS!C11 -> 320.2 | D10: =DATOS!D11 -> 442 | E10: =DATOS!E11 -> 448.7 | F10: =DATOS!F11 -> 73.1 | G10: =DATOS!G11 -> 76.7 | H10: =IFERROR((DATOS!G11-DATOS!F11)/ABS(DATOS!F11),"—") -> 0.049247606 | I10: =DATOS!H11 -> 154.5 | J10: =DATOS!I11 -> 176.1 | K10: =IFERROR((DATOS!I11-DATOS!H11)/ABS(DATOS!H11),"—") -> 0.13980583
B11: Costo de ventas | C11: =DATOS!C14 -> 208.1 | D11: =DATOS!D14 -> 330.5 | E11: =DATOS!E14 -> 331.2 | F11: =DATOS!F14 -> 40.2 | G11: =DATOS!G14 -> 45.2 | H11: =IFERROR((DATOS!G14-DATOS!F14)/ABS(DATOS!F14),"—") -> 0.12437811 | I11: =DATOS!H14 -> 100.6 | J11: =DATOS!I14 -> 126.2 | K11: =IFERROR((DATOS!I14-DATOS!H14)/ABS(DATOS!H14),"—") -> 0.25447316
B12: UTILIDAD BRUTA | C12: =DATOS!C15 -> 112.1 | D12: =DATOS!D15 -> 111.5 | E12: =DATOS!E15 -> 117.5 | F12: =DATOS!F15 -> 32.9 | G12: =DATOS!G15 -> 31.5 | H12: =IFERROR((DATOS!G15-DATOS!F15)/ABS(DATOS!F15),"—") -> -0.042553191 | I12: =DATOS!H15 -> 53.9 | J12: =DATOS!I15 -> 49.9 | K12: =IFERROR((DATOS!I15-DATOS!H15)/ABS(DATOS!H15),"—") -> -0.074211503
B13: Margen bruto % | C13: =DATOS!C15/DATOS!C11 -> 0.35009369 | D13: =DATOS!D15/DATOS!D11 -> 0.25226244 | E13: =DATOS!E15/DATOS!E11 -> 0.26186762 | F13: =DATOS!F15/DATOS!F11 -> 0.4500684 | G13: =DATOS!G15/DATOS!G11 -> 0.410691 | I13: =DATOS!H15/DATOS!H11 -> 0.34886731 | J13: =DATOS!I15/DATOS!I11 -> 0.28336173
B14: I+D (tecnología avanzada) | C14: =DATOS!C18 | D14: =DATOS!D18 | E14: =DATOS!E18 | F14: =DATOS!F18 -> 3 | G14: =DATOS!G18 -> 18.9 | H14: =IFERROR((DATOS!G18-DATOS!F18)/ABS(DATOS!F18),"—") -> 5.3 | I14: =DATOS!H18 -> 3.3 | J14: =DATOS!I18 -> 10.8 | K14: =IFERROR((DATOS!I18-DATOS!H18)/ABS(DATOS!H18),"—") -> 2.2727273
B15: SG&A | C15: =DATOS!C19 | D15: =DATOS!D19 | E15: =DATOS!E19 | F15: =DATOS!F19 -> 8.3 | G15: =DATOS!G19 -> 10 | H15: =IFERROR((DATOS!G19-DATOS!F19)/ABS(DATOS!F19),"—") -> 0.20481928 | I15: =DATOS!H19 -> 13.4 | J15: =DATOS!I19 -> 26.2 | K15: =IFERROR((DATOS!I19-DATOS!H19)/ABS(DATOS!H19),"—") -> 0.95522388
B16: Amortización | C16: =DATOS!C20 | D16: =DATOS!D20 | E16: =DATOS!E20 | F16: =DATOS!F20 -> 1.1 | G16: =DATOS!G20 -> 1.8 | H16: =IFERROR((DATOS!G20-DATOS!F20)/ABS(DATOS!F20),"—") -> 0.63636364 | I16: =DATOS!H20 -> 3.7 | J16: =DATOS!I20 -> 2.5 | K16: =IFERROR((DATOS!I20-DATOS!H20)/ABS(DATOS!H20),"—") -> -0.32432432
B17: INGRESO OPERATIVO | C17: =DATOS!C21 | D17: =DATOS!D21 | E17: =DATOS!E21 -> 50.2 | F17: =DATOS!F21 -> 20.5 | G17: =DATOS!G21 -> 0.8 | H17: =IFERROR((DATOS!G21-DATOS!F21)/ABS(DATOS!F21),"—") -> -0.96097561 | I17: =DATOS!H21 -> 33.5 | J17: =DATOS!I21 -> 10.4 | K17: =IFERROR((DATOS!I21-DATOS!H21)/ABS(DATOS!H21),"—") -> -0.68955224
B18: Ingreso por inversiones | C18: =DATOS!C24 | D18: =DATOS!D24 | E18: =DATOS!E24 | F18: =DATOS!F24 -> 7.3 | G18: =DATOS!G24 -> 17 | H18: =IFERROR((DATOS!G24-DATOS!F24)/ABS(DATOS!F24),"—") -> 1.3287671 | I18: =DATOS!H24 -> 8 | J18: =DATOS!I24 -> 16.3 | K18: =IFERROR((DATOS!I24-DATOS!H24)/ABS(DATOS!H24),"—") -> 1.0375
B19: Gasto por intereses | C19: =DATOS!C23 | D19: =DATOS!D23 | E19: =DATOS!E23 | F19: =DATOS!F23 -> 3.4 | G19: =DATOS!G23 -> 4 | H19: =IFERROR((DATOS!G23-DATOS!F23)/ABS(DATOS!F23),"—") -> 0.17647059 | I19: =DATOS!H23 -> 3.1 | J19: =DATOS!I23 -> 4.2 | K19: =IFERROR((DATOS!I23-DATOS!H23)/ABS(DATOS!H23),"—") -> 0.35483871
B20: Utilidad antes de impuestos | C20: =DATOS!C27 | D20: =DATOS!D27 | E20: =DATOS!E27 | F20: =DATOS!F27 -> 35.2 | G20: =DATOS!G27 -> 12.5 | H20: =IFERROR((DATOS!G27-DATOS!F27)/ABS(DATOS!F27),"—") -> -0.64488636 | I20: =DATOS!H27 -> 37.4 | J20: =DATOS!I27 -> 21.6 | K20: =IFERROR((DATOS!I27-DATOS!H27)/ABS(DATOS!H27),"—") -> -0.42245989
B21: UTILIDAD NETA | C21: =DATOS!C29 -> 84.4 | D21: =DATOS!D29 -> 73.2 | E21: =DATOS!E29 -> 77.8 | F21: =DATOS!F29 -> 27.2 | G21: =DATOS!G29 -> 10 | H21: =IFERROR((DATOS!G29-DATOS!F29)/ABS(DATOS!F29),"—") -> -0.63235294 | I21: =DATOS!H29 -> 28.9 | J21: =DATOS!I29 -> 16.8 | K21: =IFERROR((DATOS!I29-DATOS!H29)/ABS(DATOS!H29),"—") -> -0.41868512
B22: Utilidad neta AJUSTADA (no-GAAP) | C22: =DATOS!C30 | D22: =DATOS!D30 | E22: =DATOS!E30 | F22: =DATOS!F30 | G22: =DATOS!G30 | H22: =IFERROR((DATOS!G30-DATOS!F30)/ABS(DATOS!F30),"—") -> — | I22: =DATOS!H30 -> 34.5 | J22: =DATOS!I30 -> 38.7 | K22: =IFERROR((DATOS!I30-DATOS!H30)/ABS(DATOS!H30),"—") -> 0.12173913
B23: EPS diluido ($) | C23: =DATOS!C32 -> 5.44 | D23: =DATOS!D32 | E23: =DATOS!E32 -> 3.9 | F23: =DATOS!F32 -> 1.6 | G23: =DATOS!G32 -> 0.45 | H23: =IFERROR((DATOS!G32-DATOS!F32)/ABS(DATOS!F32),"—") -> -0.71875 | I23: =DATOS!H32 -> 1.59 | J23: =DATOS!I32 -> 0.77 | K23: =IFERROR((DATOS!I32-DATOS!H32)/ABS(DATOS!H32),"—") -> -0.51572327
B25: ACUMULADO SEMESTRE (1S)
B26: Concepto ($M) | C26: 1S 2025 | D26: 1S 2026 | E26: Δ% | F26: Lectura
B27: Ingresos totales | C27: =DATOS!J11 -> 227.6 | D27: =DATOS!K11 -> 252.8 | E27: =IFERROR((DATOS!K11-DATOS!J11)/ABS(DATOS!J11),"—") -> 0.11072056 | F27: Sube +11%: uranio compensa caída de SWU.
B28: Utilidad bruta | C28: =DATOS!J15 -> 86.8 | D28: =DATOS!K15 -> 81.4 | E28: =IFERROR((DATOS!K15-DATOS!J15)/ABS(DATOS!J15),"—") -> -0.062211982 | F28: Baja: mezcla de contratos y costos.
B29: Ingreso operativo | C29: =DATOS!J21 -> 54 | D29: =DATOS!K21 -> 11.2 | E29: =IFERROR((DATOS!K21-DATOS!J21)/ABS(DATOS!J21),"—") -> -0.79259259 | F29: Cae fuerte: I+D y SG&A (stock-comp) disparados.
B30: Utilidad neta | C30: =DATOS!J29 -> 56.1 | D30: =DATOS!K29 -> 26.8 | E30: =IFERROR((DATOS!K29-DATOS!J29)/ABS(DATOS!J29),"—") -> -0.52228164 | F30: Baja ~52%: gastos de expansión + one-time 25.
B31: Utilidad neta ajustada | C31: =DATOS!J30 -> 63.1 | D31: =DATOS!K30 -> 62.2 | E31: =IFERROR((DATOS!K30-DATOS!J30)/ABS(DATOS!J30),"—") -> -0.014263074 | F31: Casi plana (62.2 vs 63.1): el núcleo aguanta.
B33: Clave analítica: la caída de utilidad neta GAAP (−42% Q2, −52% 1S) NO es deterioro operativo — es inversión. Los $17.2M de stock-comp por RSU y el salto de I+D (growth costs) son gastos de la expansión. La utilidad AJUSTADA (que los excluye) queda casi plana, confirmando que el negocio base sigue sano mientras construyen capacidad futura.

Sheet Balance
B2: BALANCE GENERAL — cortes dic23 → dic25 → mar26 → jun26 ($M)
B3: Cuatro cortes fiables en el tiempo. Verde = de DATOS. Se omite dic24 salvo patrimonio (no divulgado completo).
B5: Partida ($M) | C5: Dic-23 | D5: Dic-25 | E5: Mar-26 | F5: Jun-26 | G5: Comentario
B6: ACTIVOS
B7: Caja y equivalentes | C7: =DATOS!C37 -> 201.2 | D7: =DATOS!E37 -> 1957.2 | E7: =DATOS!G37 -> 1868.2 | F7: =DATOS!I37 -> 1868.5 | G7: ~$1.9B. Financia toda la expansión.
B8: Cuentas por cobrar | C8: =DATOS!C38 | D8: =DATOS!E38 -> 30.7 | E8: =DATOS!G38 -> 41.8 | F8: =DATOS!I38 -> 25.6
B9: Inventarios | C9: =DATOS!C39 | D9: =DATOS!E39 -> 322.9 | E9: =DATOS!G39 -> 336 | F9: =DATOS!I39 -> 377.1 | G9: Sube 322.9→377.1: acumulación pre-entregas.
B10: Otros activos corrientes | C10: =DATOS!C41 | D10: =DATOS!E41 -> 11.9 | E10: =DATOS!G41 -> 12.4 | F10: =DATOS!I41 -> 12.7
B11: Total activo corriente | C11: =DATOS!C42 | D11: =DATOS!E42 -> 2363.6 | E11: =DATOS!G42 -> 2295.4 | F11: =DATOS!I42 -> 2317.1
B12: PP&E neto | C12: =DATOS!C43 | D12: =DATOS!E43 -> 29.5 | E12: =DATOS!G43 -> 59.5 | F12: =DATOS!I43 -> 142.5 | G12: 29.5→142.5: la expansión ya se ve en el balance.
B13: Intangibles | C13: =DATOS!C45 | D13: =DATOS!E45 -> 21.2 | E13: =DATOS!G45 -> 19.4 | F13: =DATOS!I45 -> 16.9
B14: TOTAL ACTIVOS | C14: =DATOS!C48 | D14: =DATOS!E48 -> 2445.9 | E14: =DATOS!G48 -> 2433.2 | F14: =DATOS!I48 -> 2531
B15: PASIVOS
B16: Cuentas por pagar | C16: =DATOS!C49 | D16: =DATOS!E49 -> 41.6 | E16: =DATOS!G49 -> 49.5 | F16: =DATOS!I49 -> 74
B17: Inventarios adeudados | C17: =DATOS!C51 | D17: =DATOS!E51 -> 192.7 | E17: =DATOS!G51 -> 170.8 | F17: =DATOS!I51 -> 235.7 | G17: Debe SWU/uranio a clientes.
B18: Ingreso diferido | C18: =DATOS!C52 | D18: =DATOS!E52 -> 131.1 | E18: =DATOS!G52 -> 112.8 | F18: =DATOS!I52 -> 85 | G18: Clientes ya pagaron por adelantado.
B19: Total pasivo corriente | C19: =DATOS!C54 | D19: =DATOS!E54 -> 422.8 | E19: =DATOS!G54 -> 401.3 | F19: =DATOS!I54 -> 429.5
B20: Deuda de largo plazo | C20: =DATOS!C55 | D20: =DATOS!E55 -> 1174.8 | E20: =DATOS!G55 -> 1176.1 | F20: =DATOS!I55 -> 1177.5 | G20: Convertibles 0% y 2.25%.
B21: TOTAL PASIVOS | C21: =DATOS!C59 | D21: =DATOS!E59 -> 1680.8 | E21: =DATOS!G59 -> 1658 | F21: =DATOS!I59 -> 1685.6
B22: PATRIMONIO TOTAL | C22: =DATOS!C60 | D22: =DATOS!E60 -> 765.1 | E22: =DATOS!G60 -> 775.2 | F22: =DATOS!I60 -> 845.4 | G22: 765→845: retiene + emite acciones (ATM).
B24: MÉTRICAS DEL BALANCE
B25: Deuda neta (deuda − caja) | C25: =IFERROR(DATOS!C55-DATOS!C37,"—") -> -201.2 | D25: =IFERROR(DATOS!E55-DATOS!E37,"—") -> -782.4 | E25: =IFERROR(DATOS!G55-DATOS!G37,"—") -> -692.1 | F25: =IFERROR(DATOS!I55-DATOS!I37,"—") -> -691 | G25: NEGATIVA = posición neta de caja.
B26: Capital de trabajo (AC−PC) | C26: =IFERROR(DATOS!C42-DATOS!C54,"—") -> 0 | D26: =IFERROR(DATOS!E42-DATOS!E54,"—") -> 1940.8 | E26: =IFERROR(DATOS!G42-DATOS!G54,"—") -> 1894.1 | F26: =IFERROR(DATOS!I42-DATOS!I54,"—") -> 1887.6 | G26: Working capital.
B27: Razón corriente | C27: =IFERROR(DATOS!C42/DATOS!C54,"—") -> — | D27: =IFERROR(DATOS!E42/DATOS!E54,"—") -> 5.59035 | E27: =IFERROR(DATOS!G42/DATOS!G54,"—") -> 5.7199103 | F27: =IFERROR(DATOS!I42/DATOS!I54,"—") -> 5.3948778 | G27: >5x: muy líquida.
B28: Deuda/Patrimonio | C28: =IFERROR(DATOS!C55/DATOS!C60,"—") -> — | D28: =IFERROR(DATOS!E55/DATOS!E60,"—") -> 1.5354856 | E28: =IFERROR(DATOS!G55/DATOS!G60,"—") -> 1.5171569 | F28: =IFERROR(DATOS!I55/DATOS!I60,"—") -> 1.3928318 | G28: Apalancamiento.
B30: Lectura: balance sólido con posición neta de caja (más caja que deuda). El cambio más visible de 2026 es PP&E: de $29.5M a $142.5M en 6 meses — la expansión de enriquecimiento dejó de ser promesa y ya aparece en el activo. Contrapartida: inventarios suben y caja baja algo, consumida por capital de trabajo y CapEx.

Sheet Análisis Financiero
B2: ANÁLISIS FINANCIERO — Liquidez · Actividad · Endeudamiento · Rentabilidad · DuPont
B3: Metodología de tus modelos (Celsia/Murray). Calculado sobre años completos FY2023-2025 (comparables). Todo jala de DATOS.
B5: Indicador | C5: FY2023 | D5: FY2024 | E5: FY2025 | F5: Interpretación
B6: 1 · LIQUIDEZ
B7: Razón corriente | C7: =IFERROR(DATOS!C42/DATOS!C54,"n/d") -> n/d | D7: =IFERROR(DATOS!D42/DATOS!D54,"n/d") -> n/d | E7: =IFERROR(DATOS!E42/DATOS!E54,"n/d") -> 5.59035 | F7: AC/PC. FY25 ~5.6x. Muy líquida.
B8: Prueba ácida | C8: =IFERROR((DATOS!C42-DATOS!C39)/DATOS!C54,"n/d") -> n/d | D8: =IFERROR((DATOS!D42-DATOS!D39)/DATOS!D54,"n/d") -> n/d | E8: =IFERROR((DATOS!E42-DATOS!E39)/DATOS!E54,"n/d") -> 4.826632 | F8: (AC−Inv)/PC. Excluye inventarios.
B9: Prueba hiper-ácida | C9: =IFERROR(DATOS!C37/DATOS!C54,"n/d") -> n/d | D9: =IFERROR(DATOS!D37/DATOS!D54,"n/d") -> n/d | E9: =IFERROR(DATOS!E37/DATOS!E54,"n/d") -> 4.6291391 | F9: Caja/PC. FY25 ~4.6x: colchón enorme.
B10: Capital de trabajo ($M) | C10: =IFERROR(DATOS!C42-DATOS!C54,"n/d") -> 0 | D10: =IFERROR(DATOS!D42-DATOS!D54,"n/d") -> 0 | E10: =IFERROR(DATOS!E42-DATOS!E54,"n/d") -> 1940.8 | F10: AC−PC. Muy positivo.
B11: 2 · ACTIVIDAD (eficiencia operativa)
B12: Rotación CxC | C12: =IFERROR(DATOS!C11/DATOS!C38,"n/d") -> n/d | D12: =IFERROR(DATOS!D11/DATOS!D38,"n/d") -> n/d | E12: =IFERROR(DATOS!E11/DATOS!E38,"n/d") -> 14.615635 | F12: Ventas/CxC. Alta: cobra rápido.
B13: Días de CxC | C13: =IFERROR(365*DATOS!C38/DATOS!C11,"n/d") -> 0 | D13: =IFERROR(365*DATOS!D38/DATOS!D11,"n/d") -> 0 | E13: =IFERROR(365*DATOS!E38/DATOS!E11,"n/d") -> 24.973256 | F13: Periodo medio de cobro.
B14: Rotación inventarios | C14: =IFERROR(DATOS!C14/DATOS!C39,"n/d") -> n/d | D14: =IFERROR(DATOS!D14/DATOS!D39,"n/d") -> n/d | E14: =IFERROR(DATOS!E14/DATOS!E39,"n/d") -> 1.0257046 | F14: CV/Inv. Baja: inventario estratégico.
B15: Días de inventario | C15: =IFERROR(365*DATOS!C39/DATOS!C14,"n/d") -> 0 | D15: =IFERROR(365*DATOS!D39/DATOS!D14,"n/d") -> 0 | E15: =IFERROR(365*DATOS!E39/DATOS!E14,"n/d") -> 355.85296 | F15: PME. Alto: guarda SWU/uranio.
B16: Rotación CxP | C16: =IFERROR(DATOS!C14/DATOS!C49,"n/d") -> n/d | D16: =IFERROR(DATOS!D14/DATOS!D49,"n/d") -> n/d | E16: =IFERROR(DATOS!E14/DATOS!E49,"n/d") -> 7.9615385 | F16: CV/CxP.
B17: Días de CxP | C17: =IFERROR(365*DATOS!C49/DATOS!C14,"n/d") -> 0 | D17: =IFERROR(365*DATOS!D49/DATOS!D14,"n/d") -> 0 | E17: =IFERROR(365*DATOS!E49/DATOS!E14,"n/d") -> 45.845411 | F17: PMP.
B18: Ciclo de conversión de efectivo | C18: =IFERROR(365*DATOS!C39/DATOS!C14+365*DATOS!C38/DATOS!C11-365*DATOS!C49/DATOS!C14,"n/d") -> 0 | D18: =IFERROR(365*DATOS!D39/DATOS!D14+365*DATOS!D38/DATOS!D11-365*DATOS!D49/DATOS!D14,"n/d") -> 0 | E18: =IFERROR(365*DATOS!E39/DATOS!E14+365*DATOS!E38/DATOS!E11-365*DATOS!E49/DATOS!E14,"n/d") -> 334.9808 | F18: PME+PMC−PMP. Días que financia el negocio.
B19: Rotación activos totales | C19: =IFERROR(DATOS!C11/DATOS!C48,"n/d") -> n/d | D19: =IFERROR(DATOS!D11/DATOS!D48,"n/d") -> n/d | E19: =IFERROR(DATOS!E11/DATOS!E48,"n/d") -> 0.18344985 | F19: Ventas/Activos. MUY baja: caja ociosa.
B20: 3 · ENDEUDAMIENTO
B21: Nivel de endeudamiento | C21: =IFERROR(DATOS!C59/DATOS!C48,"n/d") -> n/d | D21: =IFERROR(DATOS!D59/DATOS!D48,"n/d") -> n/d | E21: =IFERROR(DATOS!E59/DATOS!E48,"n/d") -> 0.68719081 | F21: Pasivo/Activo. FY25 ~69%.
B22: Apalancamiento total | C22: =IFERROR(DATOS!C59/DATOS!C60,"n/d") -> n/d | D22: =IFERROR(DATOS!D59/DATOS!D60,"n/d") -> 0 | E22: =IFERROR(DATOS!E59/DATOS!E60,"n/d") -> 2.196837 | F22: Pasivo/Patrimonio.
B23: Deuda financiera/Patrimonio | C23: =IFERROR(DATOS!C55/DATOS!C60,"n/d") -> n/d | D23: =IFERROR(DATOS!D55/DATOS!D60,"n/d") -> 0 | E23: =IFERROR(DATOS!E55/DATOS!E60,"n/d") -> 1.5354856 | F23: Solo deuda financiera.
B24: Cubrimiento de intereses | C24: =IFERROR(DATOS!C21/DATOS!C23,"n/d") -> n/d | D24: =IFERROR(DATOS!D21/DATOS!D23,"n/d") -> n/d | E24: =IFERROR(DATOS!E21/DATOS!E23,"n/d") -> n/d | F24: EBIT/Intereses. (FY25 op income disp.)
B25: 4 · RENTABILIDAD
B26: Margen bruto | C26: =IFERROR(DATOS!C15/DATOS!C11,"n/d") -> 0.35009369 | D26: =IFERROR(DATOS!D15/DATOS!D11,"n/d") -> 0.25226244 | E26: =IFERROR(DATOS!E15/DATOS!E11,"n/d") -> 0.26186762 | F26: UB/Ventas. Alto ~26-35%.
B27: Margen operativo | C27: =IFERROR(DATOS!C21/DATOS!C11,"n/d") -> 0 | D27: =IFERROR(DATOS!D21/DATOS!D11,"n/d") -> 0 | E27: =IFERROR(DATOS!E21/DATOS!E11,"n/d") -> 0.11187876 | F27: Op income/Ventas. (FY25).
B28: Margen neto | C28: =IFERROR(DATOS!C29/DATOS!C11,"n/d") -> 0.26358526 | D28: =IFERROR(DATOS!D29/DATOS!D11,"n/d") -> 0.16561086 | E28: =IFERROR(DATOS!E29/DATOS!E11,"n/d") -> 0.17338979 | F28: UN/Ventas. Alto por inversión+one-times.
B29: ROA | C29: =IFERROR(DATOS!C29/DATOS!C48,"n/d") -> n/d | D29: =IFERROR(DATOS!D29/DATOS!D48,"n/d") -> n/d | E29: =IFERROR(DATOS!E29/DATOS!E48,"n/d") -> 0.031808332 | F29: UN/Activos. Bajo: balance con caja ociosa.
B30: ROE | C30: =IFERROR(DATOS!C29/DATOS!C60,"n/d") -> n/d | D30: =IFERROR(DATOS!D29/DATOS!D60,"n/d") -> 0.4535316 | E30: =IFERROR(DATOS!E29/DATOS!E60,"n/d") -> 0.10168605 | F30: UN/Patrimonio. FY25 ~10%.
B31: 5 · DUPONT (descompone el ROE)
B32: (1) Margen neto | C32: =IFERROR(DATOS!C29/DATOS!C11,"n/d") -> 0.26358526 | D32: =IFERROR(DATOS!D29/DATOS!D11,"n/d") -> 0.16561086 | E32: =IFERROR(DATOS!E29/DATOS!E11,"n/d") -> 0.17338979 | F32: Rentabilidad.
B33: (2) Rotación de activos | C33: =IFERROR(DATOS!C11/DATOS!C48,"n/d") -> n/d | D33: =IFERROR(DATOS!D11/DATOS!D48,"n/d") -> n/d | E33: =IFERROR(DATOS!E11/DATOS!E48,"n/d") -> 0.18344985 | F33: Eficiencia. Bajísima por la caja.
B34: (3) Multiplicador de capital | C34: =IFERROR(DATOS!C48/DATOS!C60,"n/d") -> n/d | D34: =IFERROR(DATOS!D48/DATOS!D60,"n/d") -> 0 | E34: =IFERROR(DATOS!E48/DATOS!E60,"n/d") -> 3.196837 | F34: Apalancamiento.
B35: ROE = (1)×(2)×(3) | C35: =IFERROR((DATOS!C29/DATOS!C11)*(DATOS!C11/DATOS!C48)*(DATOS!C48/DATOS!C60),"n/d") -> n/d | D35: =IFERROR((DATOS!D29/DATOS!D11)*(DATOS!D11/DATOS!D48)*(DATOS!D48/DATOS!D60),"n/d") -> n/d | E35: =IFERROR((DATOS!E29/DATOS!E11)*(DATOS!E11/DATOS!E48)*(DATOS!E48/DATOS!E60),"n/d") -> 0.10168605 | F35: Verificación DuPont. Debe = ROE.
B37: Diagnóstico DuPont: el ROE de ~10% NO viene de eficiencia (rotación de activos ~0.18x, bajísima) sino del margen alto y el apalancamiento. La razón: ~$1.9B de caja "ociosa" inflan los activos y hunden la rotación. Traducción financiera: hoy Centrus es un negocio rentable pequeño sentado sobre una montaña de caja. El valor no está en exprimir las operaciones actuales, sino en convertir esa caja en capacidad productiva (la expansión). Ahí está toda la tesis.

Sheet Proyecciones
B2: MODELO DE TRES ESTADOS PROYECTADOS Y ENLAZADOS (5 años) — Centrus Energy
B3: LEU ya es rentable (GAAP): el modelo proyecta el crecimiento con la expansión de enriquecimiento HALEU. El margen EBIT sube de 11% a 16% con la escala. La caja de ~$1.9B financia el CapEx. DESCUADRE verifica el cuadre (=0).
B6: Concepto ($M) | C6: Base FY25 | D6: Año 1 | E6: Año 2 | F6: Año 3 | G6: Año 4 | H6: Año 5 | I6: Notas / enlace
B7: 1 · ESTADO DE RESULTADOS
B8: Ingresos totales | C8: =DATOS!$K$83 -> 448.7 | D8: =C8*(1+DATOS!$K$84) -> 502.544 | E8: =D8*(1+DATOS!$K$85) -> 593.00192 | F8: =E8*(1+DATOS!$K$86) -> 711.6023 | G8: =F8*(1+DATOS!$K$87) -> 818.34265 | H8: =G8*(1+DATOS!$K$88) -> 916.54377 | I8: Crece con contratos + expansión HALEU.
B9: Crecimiento % | D9: =D8/C8-1 -> 0.12 | E9: =E8/D8-1 -> 0.18 | F9: =F8/E8-1 -> 0.2 | G9: =G8/F8-1 -> 0.15 | H9: =H8/G8-1 -> 0.12
B10: Ingreso operativo (EBIT) | D10: =D8*DATOS!$K$89 -> 55.27984 | E10: =E8*DATOS!$K$90 -> 71.16023 | F10: =F8*DATOS!$K$91 -> 99.624323 | G10: =G8*DATOS!$K$92 -> 122.7514 | H10: =H8*DATOS!$K$93 -> 146.647 | I10: Ventas × margen EBIT.
B11: Margen EBIT % | D11: =DATOS!$K$89 -> 0.11 | E11: =DATOS!$K$90 -> 0.12 | F11: =DATOS!$K$91 -> 0.14 | G11: =DATOS!$K$92 -> 0.15 | H11: =DATOS!$K$93 -> 0.16 | I11: De 11% a 16% con escala.
B12: (+) Ingreso por inversiones (caja) | D12: =C18*DATOS!$K$98 -> 74.74 | E12: =D18*DATOS!$K$98 -> 76.515387 | F12: =E18*DATOS!$K$98 -> 78.267181 | G12: =F18*DATOS!$K$98 -> 80.330541 | H12: =G18*DATOS!$K$98 -> 82.834118 | I12: ~4% sobre la caja del año anterior. Importante en LEU.
B13: Utilidad antes de impuestos | D13: =D10+D12 -> 130.01984 | E13: =E10+E12 -> 147.67562 | F13: =F10+F12 -> 177.8915 | G13: =G10+G12 -> 203.08194 | H13: =H10+H12 -> 229.48112
B14: (−) Impuestos | D14: =MAX(0,D13)*DATOS!K73 -> 27.304166 | E14: =MAX(0,E13)*DATOS!K73 -> 31.01188 | F14: =MAX(0,F13)*DATOS!K73 -> 37.357216 | G14: =MAX(0,G13)*DATOS!K73 -> 42.647207 | H14: =MAX(0,H13)*DATOS!K73 -> 48.191035 | I14: Tasa efectiva.
B15: UTILIDAD NETA | D15: =D13-D14 -> 102.71567 | E15: =E13-E14 -> 116.66374 | F15: =F13-F14 -> 140.53429 | G15: =G13-G14 -> 160.43473 | H15: =H13-H14 -> 181.29009
B17: 2 · BALANCE GENERAL
B18: Caja y equivalentes | C18: =DATOS!I37 -> 1868.5 | D18: =D39 -> 1912.8847 | E18: =E39 -> 1956.6795 | F18: =F39 -> 2008.2635 | G18: =G39 -> 2070.8529 | H18: =H39 -> 2145.7585 | I18: ← Caja final del Flujo. El gran colchón.
B19: Cuentas por cobrar | C19: =DATOS!I38 -> 25.6 | D19: =D8*(DATOS!I38/DATOS!$K$83) -> 28.672 | E19: =E8*(DATOS!I38/DATOS!$K$83) -> 33.83296 | F19: =F8*(DATOS!I38/DATOS!$K$83) -> 40.599552 | G19: =G8*(DATOS!I38/DATOS!$K$83) -> 46.689485 | H19: =H8*(DATOS!I38/DATOS!$K$83) -> 52.292223 | I19: Ratio CxC/ventas.
B20: Inventarios | C20: =DATOS!I39 -> 377.1 | D20: =D8*(DATOS!I39/DATOS!$K$83) -> 422.352 | E20: =E8*(DATOS!I39/DATOS!$K$83) -> 498.37536 | F20: =F8*(DATOS!I39/DATOS!$K$83) -> 598.05043 | G20: =G8*(DATOS!I39/DATOS!$K$83) -> 687.758 | H20: =H8*(DATOS!I39/DATOS!$K$83) -> 770.28896 | I20: SWU + uranio (lumpy).
B21: PP&E neto | C21: =DATOS!I48*0+60 -> 60 | D21: =C21+D8*DATOS!$K$96-D8*DATOS!$K$95 -> 110.2544 | E21: =D21+E8*DATOS!$K$96-E8*DATOS!$K$95 -> 169.55459 | F21: =E21+F8*DATOS!$K$96-F8*DATOS!$K$95 -> 240.71482 | G21: =F21+G8*DATOS!$K$96-G8*DATOS!$K$95 -> 322.54909 | H21: =G21+H8*DATOS!$K$96-H8*DATOS!$K$95 -> 414.20346 | I21: + CapEx − depreciación (expansión).
B22: Otros activos (resto) | C22: =DATOS!I48-DATOS!I37-DATOS!I38-DATOS!I39-60 -> 199.8 | D22: =C22 -> 199.8 | E22: =D22 -> 199.8 | F22: =E22 -> 199.8 | G22: =F22 -> 199.8 | H22: =G22 -> 199.8 | I22: Resto constante.
B23: TOTAL ACTIVOS | C23: =C18+C19+C20+C21+C22 -> 2531 | D23: =D18+D19+D20+D21+D22 -> 2673.9631 | E23: =E18+E19+E20+E21+E22 -> 2858.2424 | F23: =F18+F19+F20+F21+F22 -> 3087.4283 | G23: =G18+G19+G20+G21+G22 -> 3327.6495 | H23: =H18+H19+H20+H21+H22 -> 3582.3431
B24: Pasivos operativos | C24: =DATOS!I59-DATOS!I55 -> 508.1 | D24: =D8*((DATOS!I59-DATOS!I55)/DATOS!$K$83) -> 569.072 | E24: =E8*((DATOS!I59-DATOS!I55)/DATOS!$K$83) -> 671.50496 | F24: =F8*((DATOS!I59-DATOS!I55)/DATOS!$K$83) -> 805.80595 | G24: =G8*((DATOS!I59-DATOS!I55)/DATOS!$K$83) -> 926.67684 | H24: =H8*((DATOS!I59-DATOS!I55)/DATOS!$K$83) -> 1037.8781 | I24: Ratio pasivos oper./ventas.
B25: Deuda (plug de cuadre) | C25: =DATOS!I55 -> 1177.5 | D25: =D23-D24-D27 -> 1156.7754 | E25: =E23-E24-E27 -> 1121.9581 | F25: =F23-F24-F27 -> 1076.3087 | G25: =G23-G24-G27 -> 1035.2242 | H25: =H23-H24-H27 -> 997.42655 | I25: PLUG: cuadra el balance.
B26: TOTAL PASIVOS | C26: =C24+C25 -> 1685.6 | D26: =D24+D25 -> 1725.8474 | E26: =E24+E25 -> 1793.463 | F26: =F24+F25 -> 1882.1146 | G26: =G24+G25 -> 1961.9011 | H26: =H24+H25 -> 2035.3046
B27: PATRIMONIO | C27: =DATOS!I60 -> 845.4 | D27: =C27+D15 -> 948.11567 | E27: =D27+E15 -> 1064.7794 | F27: =E27+F15 -> 1205.3137 | G27: =F27+G15 -> 1365.7484 | H27: =G27+H15 -> 1547.0385 | I27: Previo + utilidad.
B28: TOTAL PASIVO + PATRIMONIO | C28: =C26+C27 -> 2531 | D28: =D26+D27 -> 2673.9631 | E28: =E26+E27 -> 2858.2424 | F28: =F26+F27 -> 3087.4283 | G28: =G26+G27 -> 3327.6495 | H28: =H26+H27 -> 3582.3431
B29: DESCUADRE (Activo − Pas − Patr) | C29: =C23-C28 -> 0 | D29: =D23-D28 -> 0 | E29: =E23-E28 -> 0 | F29: =F23-F28 -> 0 | G29: =G23-G28 -> 0 | H29: =H23-H28 -> 0 | I29: DEBE SER 0.
B31: 3 · FLUJO DE CAJA
B32: Utilidad neta | D32: =D15 -> 102.71567 | E32: =E15 -> 116.66374 | F32: =F15 -> 140.53429 | G32: =G15 -> 160.43473 | H32: =H15 -> 181.29009 | I32: ← Resultados.
B33: (+) Depreciación | D33: =D8*DATOS!$K$95 -> 20.10176 | E33: =E8*DATOS!$K$95 -> 23.720077 | F33: =F8*DATOS!$K$95 -> 28.464092 | G33: =G8*DATOS!$K$95 -> 32.733706 | H33: =H8*DATOS!$K$95 -> 36.661751 | I33: No-caja.
B34: (−) Δ Capital de trabajo | D34: =-(D8-C8)*DATOS!$K$97 -> -8.0766 | E34: =-(E8-D8)*DATOS!$K$97 -> -13.568688 | F34: =-(F8-E8)*DATOS!$K$97 -> -17.790058 | G34: =-(G8-F8)*DATOS!$K$97 -> -16.011052 | H34: =-(H8-G8)*DATOS!$K$97 -> -14.730168 | I34: Alto en LEU (inventario lumpy).
B35: Flujo de caja operativo | D35: =D32+D33+D34 -> 114.74083 | E35: =E32+E33+E34 -> 126.81513 | F35: =F32+F33+F34 -> 151.20832 | G35: =G32+G33+G34 -> 177.15739 | H35: =H32+H33+H34 -> 203.22167
B36: (−) CapEx | D36: =-D8*DATOS!$K$96 -> -70.35616 | E36: =-E8*DATOS!$K$96 -> -83.020269 | F36: =-F8*DATOS!$K$96 -> -99.624323 | G36: =-G8*DATOS!$K$96 -> -114.56797 | H36: =-H8*DATOS!$K$96 -> -128.31613 | I36: % de ventas (expansión).
B37: Flujo de caja libre (FCF) | D37: =D35+D36 -> 44.384674 | E37: =E35+E36 -> 43.794858 | F37: =F35+F36 -> 51.584 | G37: =G35+G36 -> 62.589415 | H37: =H35+H36 -> 74.905541 | I37: OCF − CapEx. Alimenta el DCF.
B38: Caja inicial | D38: =DATOS!I37 -> 1868.5 | E38: =D39 -> 1912.8847 | F38: =E39 -> 1956.6795 | G38: =F39 -> 2008.2635 | H38: =G39 -> 2070.8529
B39: Caja final | D39: =D38+D37 -> 1912.8847 | E39: =E38+E37 -> 1956.6795 | F39: =F38+F37 -> 2008.2635 | G39: =G38+G37 -> 2070.8529 | H39: =H38+H37 -> 2145.7585 | I39: → Caja del Balance.
B41: Cómo leerlo: LEU es el más maduro de los cuatro — ya gana dinero GAAP, así que el DCF parte de una base sólida sin necesidad de esperar un breakeven. El motor de valor es doble: el crecimiento operativo (expansión HALEU) más el ingreso por inversiones sobre los ~$1.9B de caja (fila 12), que es una fuente real de utilidad en LEU. El working capital es alto por el inventario lumpy de SWU/uranio. Descuadre=0 confirma el cuadre. Cambia crecimiento o márgenes en DATOS y los tres estados responden juntos.

Sheet Valoración
B2: VALORACIÓN — WACC (CAPM) · KTNO · NOPLAT · ROIC · g endógeno · DCF
B3: Metodología de tus modelos, adaptada a empresa USD (sin EMBI/devaluación; beta sector Damodaran). Amarillo = editable (viene de DATOS). Verde = jala de DATOS.
B5: 1 · COSTO DE CAPITAL (WACC vía CAPM)
B6: Tasa libre de riesgo (Rf) | C6: =DATOS!K70 -> 0.043 | E6: Treasury 10y. De DATOS.
B7: Prima de riesgo de mercado (ERP) | C7: =DATOS!K71 -> 0.055 | E7: Equity risk premium. De DATOS.
B8: Beta desapalancado (βu) | C8: =DATOS!K72 -> 0.85 | E8: Sector Damodaran. De DATOS.
B9: Valor de mercado del equity (E) | C9: =DATOS!K66*DATOS!K67 -> 3318.483 | E9: Precio × acciones (de DATOS).
B10: Valor de la deuda (D) | C10: =DATOS!I55 -> 1177.5 | E10: Deuda LP (jun26, de DATOS).
B11: Peso deuda D/(D+E) | C11: =C10/(C10+C9) -> 0.26190046 | E11: Estructura de capital.
B12: Peso equity E/(D+E) | C12: =C9/(C10+C9) -> 0.73809954
B13: Tasa impositiva (t) | C13: =DATOS!K73 -> 0.21 | E13: De DATOS.
B14: Beta apalancado (βL, Hamada) | C14: =C8*(1+(1-C13)*C10/C9) -> 1.0882689 | E14: βu×(1+(1−t)×D/E).
B15: Costo del equity (Ke = CAPM) | C15: =C6+C14*C7 -> 0.10285479 | E15: Rf + βL × ERP.
B16: Costo de la deuda (Kd) | C16: =DATOS!K74 -> 0.045 | E16: De DATOS.
B17: Kd después de impuestos | C17: =C16*(1-C13) -> 0.03555 | E17: Kd×(1−t). Escudo fiscal.
B18: WACC | C18: =C12*C15+C11*C17 -> 0.085227634 | E18: We×Ke + Wd×Kd(1−t).
B20: 2 · CREACIÓN DE VALOR (NOPLAT · ROIC · g endógeno)
B21: Cálculo sobre FY2025 (último año completo)
B22: Capital de trabajo neto operativo (KTNO) | C22: =(DATOS!E38+DATOS!E39+DATOS!E40+DATOS!E41)-(DATOS!E49+DATOS!E51+DATOS!E52) -> 41 | E22: AC operativos − PC operativos (excluye caja y deuda).
B23: (+) Activos fijos netos (PP&E+intang) | C23: =DATOS!E43+DATOS!E45 -> 50.7 | E23: Inversión de largo plazo.
B24: Capital invertido neto | C24: =C22+C23 -> 91.7 | E24: KTNO + activos fijos. Lo que el negocio realmente emplea.
B25: NOPLAT (op. income × (1−t)) | C25: =DATOS!E21*(1-C13) -> 39.658 | E25: Utilidad operativa neta de impuestos.
B26: ROIC (NOPLAT / Capital invertido) | C26: =C25/C24 -> 0.43247546 | E26: NOPLAT/Capital invertido. OJO: sale alto (~43%) porque el capital invertido es bajo HOY (PP&E recién crece). Se normalizará a la baja cuando la expansión entre en la base de capital.
B27: Spread (ROIC − WACC) | C27: =C26-C18 -> 0.34724783 | E27: >0 = crea valor. <0 = destruye valor sobre ese capital.
B28: Índice de reinversión (IR) — supuesto | C28: 0.6 | E28: % de NOPLAT reinvertido. Editable. Alto por fase de expansión.
B29: g endógeno (ROIC × IR) | C29: =C26*C28 -> 0.25948528 | E29: Crecimiento sostenible = retorno × reinversión.
B31: DCF — Flujo de Caja Libre proyectado (desde Proyecciones)
B32: LEU ya es rentable con FCF positivo: el DCF es el más limpio de los cuatro modelos.
B33: Año | C33: FCF ($M) | D33: VP ($M) | E33: FCF de Proyecciones.
B34: 1 | C34: =Proyecciones!D37 -> 44.384674 | D34: =C34/(1+C18)^1 -> 40.898953
B35: 2 | C35: =Proyecciones!E37 -> 43.794858 | D35: =C35/(1+C18)^2 -> 37.186168
B36: 3 | C36: =Proyecciones!F37 -> 51.584 | D36: =C36/(1+C18)^3 -> 40.360123
B37: 4 | C37: =Proyecciones!G37 -> 62.589415 | D37: =C37/(1+C18)^4 -> 45.125031
B38: 5 | C38: =Proyecciones!H37 -> 74.905541 | D38: =C38/(1+C18)^5 -> 49.763363
B39: FCF terminal normalizado ($M) | C39: =Proyecciones!H8*DATOS!K94*(1-DATOS!K73) -> 115.85113 | E39: Ventas año5 × margen EBIT terminal × (1−t).
B40: Valor terminal (Gordon, g=3%) | C40: =C39*(1.03)/(C18-0.03) -> 2160.6333 | D40: =C40/(1+C18)^5 -> 1435.4129 | E40: Crecimiento perpetuo 3%.
B41: Valor empresa (EV) ($M) | C41: =SUM(D34:D38)+D40 -> 1648.7466
B42: (+) Caja − deuda ($M) | C42: =DATOS!I37-DATOS!I55 -> 691 | E42: Puente EV→equity. LEU tiene posición neta de caja.
B43: Valor del patrimonio ($M) | C43: =C41+C42 -> 2339.7466
B44: Valor intrínseco por acción — DCF ($) | C44: =C43/DATOS!K67 -> 117.28053
...

Sheet Sensibilidad
B2: ANÁLISIS DE SENSIBILIDAD — Valor por acción (DCF)
B3: WACC (filas) × crecimiento perpetuo g (columnas). Como LEU ya es rentable, la sensibilidad al terminal es más estable que en los mineros.
B5: WACC \ g → | C5: 0.02 | D5: 0.025 | E5: 0.03 | F5: 0.035 | G5: 0.04
B6: 0.065 | C6: =((Proyecciones!D37/(1+$B6)^1+Proyecciones!E37/(1+$B6)^2+Proyecciones!F37/(1+$B6)^3+Proyecciones!G37/(1+$B6)^4+Proyecciones!H37/(1+$B6)^5+(Proyecciones!H8*DATOS!K94*(1-DATOS!K73)*(1+C$5)/($B6-C$5))/(1+$B6)^5)+(DATOS!I37-DATOS!I55))/DATOS!K67 -> 142.05279 | D6: =((Proyecciones!D37/(1+$B6)^1+Proyecciones!E37/(1+$B6)^2+Proyecciones!F37/(1+$B6)^3+Proyecciones!G37/(1+$B6)^4+Proyecciones!H37/(1+$B6)^5+(Proyecciones!H8*DATOS!K94*(1-DATOS!K73)*(1+D$5)/($B6-D$5))/(1+$B6)^5)+(DATOS!I37-DATOS!I55))/DATOS!K67 -> 154.5916 | E6: =((Proyecciones!D37/(1+$B6)^1+Proyecciones!E37/(1+$B6)^2+Proyecciones!F37/(1+$B6)^3+Proyecciones!G37/(1+$B6)^4+Proyecciones!H37/(1+$B6)^5+(Proyecciones!H8*DATOS!K94*(1-DATOS!K73)*(1+E$5)/($B6-E$5))/(1+$B6)^5)+(DATOS!I37-DATOS!I55))/DATOS!K67 -> 170.71293 | F6: =((Proyecciones!D37/(1+$B6)^1+Proyecciones!E37/(1+$B6)^2+Proyecciones!F37/(1+$B6)^3+Proyecciones!G37/(1+$B6)^4+Proyecciones!H37/(1+$B6)^5+(Proyecciones!H8*DATOS!K94*(1-DATOS!K73)*(1+F$5)/($B6-F$5))/(1+$B6)^5)+(DATOS!I37-DATOS!I55))/DATOS!K67 -> 192.20804 | G6: =((Proyecciones!D37/(1+$B6)^1+Proyecciones!E37/(1+$B6)^2+Proyecciones!F37/(1+$B6)^3+Proyecciones!G37/(1+$B6)^4+Proyecciones!H37/(1+$B6)^5+(Proyecciones!H8*DATOS!K94*(1-DATOS!K73)*(1+G$5)/($B6-G$5))/(1+$B6)^5)+(DATOS!I37-DATOS!I55))/DATOS!K67 -> 222.3012
B7: 0.075 | C7: =((Proyecciones!D37/(1+$B7)^1+Proyecciones!E37/(1+$B7)^2+Proyecciones!F37/(1+$B7)^3+Proyecciones!G37/(1+$B7)^4+Proyecciones!H37/(1+$B7)^5+(Proyecciones!H8*DATOS!K94*(1-DATOS!K73)*(1+C$5)/($B7-C$5))/(1+$B7)^5)+(DATOS!I37-DATOS!I55))/DATOS!K67 -> 120.66746 | D7: =((Proyecciones!D37/(1+$B7)^1+Proyecciones!E37/(1+$B7)^2+Proyecciones!F37/(1+$B7)^3+Proyecciones!G37/(1+$B7)^4+Proyecciones!H37/(1+$B7)^5+(Proyecciones!H8*DATOS!K94*(1-DATOS!K73)*(1+D$5)/($B7-D$5))/(1+$B7)^5)+(DATOS!I37-DATOS!I55))/DATOS!K67 -> 128.57354 | E7: =((Proyecciones!D37/(1+$B7)^1+Proyecciones!E37/(1+$B7)^2+Proyecciones!F37/(1+$B7)^3+Proyecciones!G37/(1+$B7)^4+Proyecciones!H37/(1+$B7)^5+(Proyecciones!H8*DATOS!K94*(1-DATOS!K73)*(1+E$5)/($B7-E$5))/(1+$B7)^5)+(DATOS!I37-DATOS!I55))/DATOS!K67 -> 138.23651 | F7: =((Proyecciones!D37/(1+$B7)^1+Proyecciones!E37/(1+$B7)^2+Proyecciones!F37/(1+$B7)^3+Proyecciones!G37/(1+$B7)^4+Proyecciones!H37/(1+$B7)^5+(Proyecciones!H8*DATOS!K94*(1-DATOS!K73)*(1+F$5)/($B7-F$5))/(1+$B7)^5)+(DATOS!I37-DATOS!I55))/DATOS!K67 -> 150.31524 | G7: =((Proyecciones!D37/(1+$B7)^1+Proyecciones!E37/(1+$B7)^2+Proyecciones!F37/(1+$B7)^3+Proyecciones!G37/(1+$B7)^4+Proyecciones!H37/(1+$B7)^5+(Proyecciones!H8*DATOS!K94*(1-DATOS!K73)*(1+G$5)/($B7-G$5))/(1+$B7)^5)+(DATOS!I37-DATOS!I55))/DATOS!K67 -> 165.84502
B8: 0.085 | C8: =((Proyecciones!D37/(1+$B8)^1+Proyecciones!E37/(1+$B8)^2+Proyecciones!F37/(1+$B8)^3+Proyecciones!G37/(1+$B8)^4+Proyecciones!H37/(1+$B8)^5+(Proyecciones!H8*DATOS!K94*(1-DATOS!K73)*(1+C$5)/($B8-C$5))/(1+$B8)^5)+(DATOS!I37-DATOS!I55))/DATOS!K67 -> 105.9402 | D8: =((Proyecciones!D37/(1+$B8)^1+Proyecciones!E37/(1+$B8)^2+Proyecciones!F37/(1+$B8)^3+Proyecciones!G37/(1+$B8)^4+Proyecciones!H37/(1+$B8)^5+(Proyecciones!H8*DATOS!K94*(1-DATOS!K73)*(1+D$5)/($B8-D$5))/(1+$B8)^5)+(DATOS!I37-DATOS!I55))/DATOS!K67 -> 111.3123 | E8: =((Proyecciones!D37/(1+$B8)^1+Proyecciones!E37/(1+$B8)^2+Proyecciones!F37/(1+$B8)^3+Proyecciones!G37/(1+$B8)^4+Proyecciones!H37/(1+$B8)^5+(Proyecciones!H8*DATOS!K94*(1-DATOS!K73)*(1+E$5)/($B8-E$5))/(1+$B8)^5)+(DATOS!I37-DATOS!I55))/DATOS!K67 -> 117.66114 | F8: =((Proyecciones!D37/(1+$B8)^1+Proyecciones!E37/(1+$B8)^2+Proyecciones!F37/(1+$B8)^3+Proyecciones!G37/(1+$B8)^4+Proyecciones!H37/(1+$B8)^5+(Proyecciones!H8*DATOS!K94*(1-DATOS!K73)*(1+F$5)/($B8-F$5))/(1+$B8)^5)+(DATOS!I37-DATOS!I55))/DATOS!K67 -> 125.27975 | G8: =((Proyecciones!D37/(1+$B8)^1+Proyecciones!E37/(1+$B8)^2+Proyecciones!F37/(1+$B8)^3+Proyecciones!G37/(1+$B8)^4+Proyecciones!H37/(1+$B8)^5+(Proyecciones!H8*DATOS!K94*(1-DATOS!K73)*(1+G$5)/($B8-G$5))/(1+$B8)^5)+(DATOS!I37-DATOS!I55))/DATOS!K67 -> 134.59139
B9: 0.095 | C9: =((Proyecciones!D37/(1+$B9)^1+Proyecciones!E37/(1+$B9)^2+Proyecciones!F37/(1+$B9)^3+Proyecciones!G37/(1+$B9)^4+Proyecciones!H37/(1+$B9)^5+(Proyecciones!H8*DATOS!K94*(1-DATOS!K73)*(1+C$5)/($B9-C$5))/(1+$B9)^5)+(DATOS!I37-DATOS!I55))/DATOS!K67 -> 95.203771 | D9: =((Proyecciones!D37/(1+$B9)^1+Proyecciones!E37/(1+$B9)^2+Proyecciones!F37/(1+$B9)^3+Proyecciones!G37/(1+$B9)^4+Proyecciones!H37/(1+$B9)^5+(Proyecciones!H8*DATOS!K94*(1-DATOS!K73)*(1+D$5)/($B9-D$5))/(1+$B9)^5)+(DATOS!I37-DATOS!I55))/DATOS!K67 -> 99.050677 | E9: =((Proyecciones!D37/(1+$B9)^1+Proyecciones!E37/(1+$B9)^2+Proyecciones!F37/(1+$B9)^3+Proyecciones!G37/(1+$B9)^4+Proyecciones!H37/(1+$B9)^5+(Proyecciones!H8*DATOS!K94*(1-DATOS!K73)*(1+E$5)/($B9-E$5))/(1+$B9)^5)+(DATOS!I37-DATOS!I55))/DATOS!K67 -> 103.48942 | F9: =((Proyecciones!D37/(1+$B9)^1+Proyecciones!E37/(1+$B9)^2+Proyecciones!F37/(1+$B9)^3+Proyecciones!G37/(1+$B9)^4+Proyecciones!H37/(1+$B9)^5+(Proyecciones!H8*DATOS!K94*(1-DATOS!K73)*(1+F$5)/($B9-F$5))/(1+$B9)^5)+(DATOS!I37-DATOS!I55))/DATOS!K67 -> 108.66794 | G9: =((Proyecciones!D37/(1+$B9)^1+Proyecciones!E37/(1+$B9)^2+Proyecciones!F37/(1+$B9)^3+Proyecciones!G37/(1+$B9)^4+Proyecciones!H37/(1+$B9)^5+(Proyecciones!H8*DATOS!K94*(1-DATOS!K73)*(1+G$5)/($B9-G$5))/(1+$B9)^5)+(DATOS!I37-DATOS!I55))/DATOS!K67 -> 114.78802
B10: 0.105 | C10: =((Proyecciones!D37/(1+$B10)^1+Proyecciones!E37/(1+$B10)^2+Proyecciones!F37/(1+$B10)^3+Proyecciones!G37/(1+$B10)^4+Proyecciones!H37/(1+$B10)^5+(Proyecciones!H8*DATOS!K94*(1-DATOS!K73)*(1+C$5)/($B10-C$5))/(1+$B10)^5)+(DATOS!I37-DATOS!I55))/DATOS!K67 -> 87.046344 | D10: =((Proyecciones!D37/(1+$B10)^1+Proyecciones!E37/(1+$B10)^2+Proyecciones!F37/(1+$B10)^3+Proyecciones!G37/(1+$B10)^4+Proyecciones!H37/(1+$B10)^5+(Proyecciones!H8*DATOS!K94*(1-DATOS!K73)*(1+D$5)/($B10-D$5))/(1+$B10)^5)+(DATOS!I37-DATOS!I55))/DATOS!K67 -> 89.91032 | E10: =((Proyecciones!D37/(1+$B10)^1+Proyecciones!E37/(1+$B10)^2+Proyecciones!F37/(1+$B10)^3+Proyecciones!G37/(1+$B10)^4+Proyecciones!H37/(1+$B10)^5+(Proyecciones!H8*DATOS!K94*(1-DATOS!K73)*(1+E$5)/($B10-E$5))/(1+$B10)^5)+(DATOS!I37-DATOS!I55))/DATOS!K67 -> 93.156159 | F10: =((Proyecciones!D37/(1+$B10)^1+Proyecciones!E37/(1+$B10)^2+Proyecciones!F37/(1+$B10)^3+Proyecciones!G37/(1+$B10)^4+Proyecciones!H37/(1+$B10)^5+(Proyecciones!H8*DATOS!K94*(1-DATOS!K73)*(1+F$5)/($B10-F$5))/(1+$B10)^5)+(DATOS!I37-DATOS!I55))/DATOS!K67 -> 96.86569 | G10: =((Proyecciones!D37/(1+$B10)^1+Proyecciones!E37/(1+$B10)^2+Proyecciones!F37/(1+$B10)^3+Proyecciones!G37/(1+$B10)^4+Proyecciones!H37/(1+$B10)^5+(Proyecciones!H8*DATOS!K94*(1-DATOS!K73)*(1+G$5)/($B10-G$5))/(1+$B10)^5)+(DATOS!I37-DATOS!I55))/DATOS!K67 -> 101.14592
B12: Precio de mercado: | C12: =DATOS!K66 -> 166.34 | D12: Compara cada celda con el precio de ~$166.
B14: Lectura: el DCF de LEU valora el negocio de enriquecimiento ACTUAL. Como en los otros, el precio de mercado incorpora una prima grande por la opción estratégica: convertirse en el productor occidental de HALEU a escala para SMRs e IA, respaldado por el gobierno de EE.UU. La sensibilidad muestra que ni el escenario más optimista de flujos actuales alcanza el precio — la tesis descansa en esa opción, no en el negocio de hoy.

Sheet Comparables
B2: ANÁLISIS DE COMPARABLES (Comps) — combustible nuclear y enriquecimiento
B3: Ancla LEU contra la cadena nuclear (uranio, enriquecimiento, servicios). LEU es rentable → P/U y EV/EBITDA aplican. Múltiplos aproximados/editables (azul).
B5: Empresa | C5: Ticker | D5: P/U | E5: EV/EBITDA | F5: P/VC | G5: Comentario
B6: Cameco | C6: CCJ | D6: 35 | E6: 22 | F6: 3.8 | G6: Líder uranio integrado. Referencia premium.
B7: BWX Technologies | C7: BWXT | D7: 30 | E7: 18 | F7: 10 | G7: Componentes nucleares USA. Rentable, defensivo.
B8: Oklo | C8: OKLO | D8: n/d | E8: n/d | F8: 8 | G8: SMR pre-ingreso. Comparable de opción HALEU.
B9: NuScale Power | C9: SMR | D9: n/d | E9: n/d | F9: 12 | G9: SMR pre-ingreso. Demanda de HALEU.
B10: Uranium Energy | C10: UEC | D10: n/d | E10: n/d | F10: 4.5 | G10: Uranio junior USA.
B11: Nexgen Energy | C11: NXE | D11: n/d | E11: n/d | F11: 3.5 | G11: Uranio pre-producción.
B12: MEDIANA | D12: =MEDIAN(D6:D11) -> 32.5 | E12: =MEDIAN(E6:E11) -> 20 | F12: =MEDIAN(F6:F11) -> 6.25
B14: VALORACIÓN IMPLÍCITA DE LEU
B15: Método | C15: Base LEU | D15: × múltiplo | E15: Valor/acción | H15: Nota
B16: Por P/U (utilidad año1) | C16: =Proyecciones!D15 -> 102.71567 | D16: =D12 -> 32.5 | E16: =Proyecciones!D15*D12/DATOS!K67 -> 167.3313 | F16: Utilidad año1 × P/U mediana.
B17: Por EV/EBITDA (año1) | C17: =Proyecciones!D10+Proyecciones!D33 -> 75.3816 | D17: =E12 -> 20 | E17: =((Proyecciones!D10+Proyecciones!D33)*E12+DATOS!I37-DATOS!I55)/DATOS!K67 -> 110.20712 | F17: (EBITDA×múlt + caja − deuda)/acciones.
B18: Precio de mercado ($) | E18: =DATOS!K66 -> 166.34
B20: Nota: LEU no tiene un comp puro — es el único enricher occidental cotizado. Cameco (uranio) y BWXT (componentes) enmarcan la parte rentable; Oklo y NuScale (SMR pre-ingreso) capturan la prima de opción HALEU que el mercado paga. Los múltiplos sobre el negocio actual quedan por debajo del precio, confirmando que el mercado descuenta el rol estratégico futuro de LEU en la cadena de enriquecimiento de EE.UU.
