Workbook

Sheet Resumen
B2: PURE CYCLE (NASDAQ: PCYO) — Resumen Ejecutivo
B3: Modelo profesional profundo (metodología Celsia/Murray). Arquitectura DATOS→fórmulas. Datos SEC hasta Q3 FY2026 (may-2026).
B5: CIFRAS CLAVE (de DATOS)
B6: Precio de la acción | C6: =DATOS!I55 -> 10 | D6: ~$10 (jul 2026).
B7: Capitalización de mercado | C7: =DATOS!I55*DATOS!I28 -> 241 | D7: ~24.1M acciones ≈ $241M.
B8: Ingresos 9M FY2026 | C8: =DATOS!I11 -> 22.53 | D8: +51% vs 9M FY25.
B9: Utilidad neta 9M FY2026 | C9: =DATOS!I25 -> 8.62 | D9: 28 trimestres seguidos rentable.
B10: Margen operativo 9M | C10: =DATOS!I19/DATOS!I11 -> 0.30004439 | D10: Saltó de 12% a 30%.
B11: Patrimonio | C11: =DATOS!G47 -> 151.58 | D11: Casi sin deuda.
B12: Note receivable (CAB) | C12: =DATOS!G38 -> 59.06 | D12: $59M a cobrar, 6% interés.
B13: Derechos agua (activo) | C13: =DATOS!G35 -> 72.27 | D13: A costo histórico. Vale mucho más.
B14: Conexiones usadas / capacidad | C14: =DATOS!I60/DATOS!I59 -> 0.0303 | D14: 1,818 de 60,000: 3% usado.
B16: VEREDICTO
B17: Tipo de inversión | C17: Compounder de activos | D17: Rentable y predecible en su núcleo, con opción enorme sobre agua escasa.
B18: Negocio hoy | C18: Sólido y rentable | D18: 28 trimestres seguidos con ganancias. 3 segmentos que se complementan.
B19: Balance | C19: Fortaleza | D19: Casi sin deuda (D/E ~9%), patrimonio 86% de activos. Note receivable de $59M.
B20: El activo oculto | C20: Derechos de agua | D20: Capacidad para 60,000 conexiones, solo 1,818 usadas. A costo histórico en libros.
B21: Valoración | C21: DCF + NAV agua | D21: Rentable → DCF aplica. NAV añade el valor de los derechos de agua ociosos.
B22: Riesgo/premio | C22: Lento pero asimétrico | D22: Cíclico con la vivienda; maduración de años. Upside en agua es opción de largo plazo.
B24: COMPARACIÓN DE LAS CUATRO (materiales/recursos críticos)
B25: LEU (Centrus) | C25: Rentable · enriquecimiento | D25: Gana dinero. DCF + opción HALEU. La más grande y cara en múltiplos.
B26: MP (MP Materials) | C26: Cruzando breakeven · imanes | D26: EBITDA+. Múltiplo EBITDA + NAV. Camino claro a rentabilidad.
B27: UUUU (Energy Fuels) | C27: Pierde dinero · opción REE | D27: Solo NAV. Balance tipo fondo. La más especulativa.
B28: PCYO (Pure Cycle) | C28: Rentable · agua/tierra | D28: El único compounder rentable y predecible. DCF + NAV agua. Maduración lenta.
B30: GUÍA DE HOJAS: DATOS (fuente+drivers) · Estado Resultados · Balance · Análisis Financiero (6 bloques) · Proyecciones (3 estados enlazados) · Valoración (DCF real+NAV) · Sensibilidad (WACC×g) · Comparables.
B31: DESCARGO: material educativo, no asesoría financiera. Verifica en SEC EDGAR. Alto riesgo; puedes perder capital.

Sheet DATOS
B2: PURE CYCLE (PCYO) — HOJA DE DATOS CRUDOS (SEC 10-K / 10-Q). Año fiscal = agosto.
B3: Fuente única. Azul = de SEC. Demás hojas jalan con fórmulas. Edita SOLO aquí. Agua + tierras + alquiler en Colorado. FY termina 31-ago: Q1=nov, Q2=feb, Q3=may. Montos en millones USD (salvo por acción y por conexión).
C5: ANUALES (FY ago) | F5: Q3 may (homólogo) | H5: 9 meses (9M) | J5: Q2 feb (homólogo)
B6: Concepto ($M) | C6: FY2023 | D6: FY2024 | E6: FY2025 | F6: Q3-25 | G6: Q3-26 | H6: 9M-25 | I6: 9M-26 | J6: Q2-25 | K6: Q2-26 | L6: Fuente / nota
B7: ESTADO DE RESULTADOS (por segmento)
B8: Ingresos — Agua y wastewater | E8: 11.6 | F8: 2.13 | G8: 4.66 | H8: 7.52 | I8: 10.1 | L8: Water+wastewater. FY25 aprox.
B9: Ingresos — Desarrollo de tierras | E9: 12.8 | F9: 2.88 | G9: 3.33 | H9: 6.99 | I9: 11.92 | L9: Lot sales + fees. Sky Ranch.
B10: Ingresos — Alquiler (SFR) | E10: 0.5 | F10: 0.13 | G10: 0.23 | H10: 0.37 | I10: 0.51 | L10: Single-family rentals.
B11: INGRESOS TOTALES | C11: 26.1 | D11: 23.1 | E11: 26.1 | F11: 5.14 | G11: 8.22 | H11: 14.89 | I11: 22.53 | J11: 4 | K11: 5.2 | L11: Total revenues.
B12: Costo — Agua y wastewater | F12: 1.2 | G12: 1.94 | H12: 3.36 | I12: 4.6 | L12: Incl deprec/depletion.
B13: Costo — Tierras | F13: 0.65 | G13: 1.92 | H13: 2.94 | I13: 4.43 | L13: Land dev cost.
B14: Costo — Alquiler | F14: 0.04 | G14: 0.08 | H14: 0.13 | I14: 0.18 | L14: SFR cost.
B15: Costo de ventas total | F15: 1.88 | G15: 3.94 | H15: 6.44 | I15: 9.21 | L15: Total cost of revenues.
B16: UTILIDAD BRUTA | F16: 3.26 | G16: 4.29 | H16: 8.45 | I16: 13.32 | L16: Segment profit total (gross).
B17: Gastos generales y admin (G&A) | F17: 1.8 | G17: 1.94 | H17: 6.3 | I17: 6 | L17: G&A expenses.
B18: Depreciación (corporativa) | F18: 0.13 | G18: 0.23 | H18: 0.43 | I18: 0.56 | L18: Depreciation.
B19: INGRESO OPERATIVO | F19: 1.33 | G19: 2.11 | H19: 1.73 | I19: 6.76 | L19: Operating income.
B20: Ingreso por intereses | F20: 0.63 | G20: 0.94 | H20: 1.9 | I20: 2.8 | L20: Interest income (note receivable 6-8%).
B21: Gasto por intereses | F21: 0.1 | G21: 0.16 | H21: 0.32 | I21: 0.39 | L21: Interest expense.
B22: Regalías petróleo y gas | E22: 6.7 | F22: 1.14 | G22: 0.98 | H22: 5.86 | I22: 2.24 | L22: Oil & gas royalty (Sky Ranch wells). Variable.
B23: Utilidad antes de impuestos | F23: 2.99 | G23: 3.9 | H23: 9.28 | I23: 11.45 | L23: Pretax income.
B24: Impuesto sobre la renta | F24: 0.74 | G24: 0.96 | H24: 2.28 | I24: 2.83 | L24: Income tax (~24%).
B25: UTILIDAD NETA | F25: 2.26 | G25: 2.95 | H25: 7 | I25: 8.62 | J25: 0.8 | K25: 1.1 | L25: Net income. 28 trimestres seguidos positivos.
B26: EBITDA | E26: 20.2 | L26: FY25 EBITDA reportado ($20.2M).
B27: EPS diluido ($) | F27: 0.09 | G27: 0.12 | H27: 0.29 | I27: 0.36 | J27: 0.03 | K27: 0.05 | L27: Diluted EPS.
B28: Acciones en circulación (M) | I28: 24.1 | L28: 24.10M (jul 2026).
B29: BALANCE GENERAL (fin de periodo)
B30: Caja y equivalentes | E30: 21.93 | G30: 8.44 | L30: Cash. Baja por CapEx de Sky Ranch.
B31: Caja restringida | E31: 6.45 | G31: 6.19 | L31: Restricted (garantías LOC).
B32: Cuentas por cobrar | E32: 1.33 | G32: 2.49 | L32: Accounts receivable.
B33: Tierra en desarrollo (corriente) | E33: 7.39 | G33: 4.13 | L33: Land under development.
B34: Total activo corriente | E34: 31.65 | G34: 15.61 | L34: Current assets.
B35: Inversión en agua y sistemas, neto | E35: 67.52 | G35: 72.27 | L35: CLAVE: derechos de agua + infraestructura.
B36: Tierra y minerales para desarrollo | E36: 4.17 | G36: 5.72 | L36: Land held for development.
B37: Casas de alquiler (SFR) | E37: 5.24 | G37: 14.57 | L37: Single-family rental units. Crece.
B38: Note receivable (Sky Ranch CAB), neto | E38: 45 | G38: 59.06 | L38: Reembolso de mejoras públicas, 6% interés. Activo clave.
B39: TOTAL ACTIVOS | E39: 162.28 | G39: 175.98 | L39: Total assets.
B40: Cuentas por pagar y acumulados | E40: 7.85 | G40: 5.98 | L40: AP + accrued.
B41: Ingreso diferido | E41: 3.36 | G41: 2.75 | L41: Deferred revenue (land dev).
... B48: Déficit acumulado | E48: -32.79 | G48: -24.37 | L48: Se reduce cada trimestre (rentable).
...

Sheet Estado Resultados
B2: ESTADO DE RESULTADOS — comparación homogénea y análisis por segmento (jala de DATOS)
B3: Q3 vs Q3, Q2 vs Q2 con Δ%, acumulado 9 meses, y anuales. Se analiza cada segmento por separado (agua/tierras/alquiler).
C5: ANUALES | F5: Q3 (25→26) | I5: 9M (25→26)
B6: Concepto ($M) | C6: FY23 | D6: FY24 | E6: FY25 | F6: Q3 25 | G6: Q3 26 | H6: Δ% | I6: 9M 25 | J6: 9M 26 | K6: Δ%
B7: INGRESOS POR SEGMENTO
B8: Agua y wastewater | C8: =DATOS!C8 | D8: =DATOS!D8 | E8: =DATOS!E8 -> 11.6 | F8: =DATOS!F8 -> 2.13 | G8: =DATOS!G8 -> 4.66 | H8: =IFERROR((DATOS!G8-DATOS!F8)/ABS(DATOS!F8),"—") -> 1.1877934 | I8: =DATOS!H8 -> 7.52 | J8: =DATOS!I8 -> 10.1 | K8: =IFERROR((DATOS!I8-DATOS!H8)/ABS(DATOS!H8),"—") -> 0.34308511
B9: Desarrollo de tierras | C9: =DATOS!C9 | D9: =DATOS!D9 | E9: =DATOS!E9 -> 12.8 | F9: =DATOS!F9 -> 2.88 | G9: =DATOS!G9 -> 3.33 | H9: =IFERROR((DATOS!G9-DATOS!F9)/ABS(DATOS!F9),"—") -> 0.15625 | I9: =DATOS!H9 -> 6.99 | J9: =DATOS!I9 -> 11.92 | K9: =IFERROR((DATOS!I9-DATOS!H9)/ABS(DATOS!H9),"—") -> 0.70529328
B10: Alquiler (SFR) | C10: =DATOS!C10 | D10: =DATOS!D10 | E10: =DATOS!E10 -> 0.5 | F10: =DATOS!F10 -> 0.13 | G10: =DATOS!G10 -> 0.23 | H10: =IFERROR((DATOS!G10-DATOS!F10)/ABS(DATOS!F10),"—") -> 0.76923077 | I10: =DATOS!H10 -> 0.37 | J10: =DATOS!I10 -> 0.51 | K10: =IFERROR((DATOS!I10-DATOS!H10)/ABS(DATOS!H10),"—") -> 0.37837838
B11: INGRESOS TOTALES | C11: =DATOS!C11 -> 26.1 | D11: =DATOS!D11 -> 23.1 | E11: =DATOS!E11 -> 26.1 | F11: =DATOS!F11 -> 5.14 | G11: =DATOS!G11 -> 8.22 | H11: =IFERROR((DATOS!G11-DATOS!F11)/ABS(DATOS!F11),"—") -> 0.59922179 | I11: =DATOS!H11 -> 14.89 | J11: =DATOS!I11 -> 22.53 | K11: =IFERROR((DATOS!I11-DATOS!H11)/ABS(DATOS!H11),"—") -> 0.51309604
B12: Agua % del total | C12: =IFERROR(DATOS!C8/DATOS!C11,"—") -> 0 | D12: =IFERROR(DATOS!D8/DATOS!D11,"—") -> 0 | E12: =IFERROR(DATOS!E8/DATOS!E11,"—") -> 0.44444444 | F12: =IFERROR(DATOS!F8/DATOS!F11,"—") -> 0.41439689 | G12: =IFERROR(DATOS!G8/DATOS!G11,"—") -> 0.56690998 | I12: =IFERROR(DATOS!H8/DATOS!H11,"—") -> 0.50503694 | J12: =IFERROR(DATOS!I8/DATOS!I11,"—") -> 0.44829117
B13: Tierras % del total | C13: =IFERROR(DATOS!C9/DATOS!C11,"—") -> 0 | D13: =IFERROR(DATOS!D9/DATOS!D11,"—") -> 0 | E13: =IFERROR(DATOS!E9/DATOS!E11,"—") -> 0.49042146 | F13: =IFERROR(DATOS!F9/DATOS!F11,"—") -> 0.56031128 | G13: =IFERROR(DATOS!G9/DATOS!G11,"—") -> 0.40510949 | I13: =IFERROR(DATOS!H9/DATOS!H11,"—") -> 0.46944258 | J13: =IFERROR(DATOS!I9/DATOS!I11,"—") -> 0.52907235
B15: COSTOS Y UTILIDAD BRUTA
B16: Costo de ventas | C16: =DATOS!C15 | D16: =DATOS!D15 | E16: =DATOS!E15 | F16: =DATOS!F15 -> 1.88 | G16: =DATOS!G15 -> 3.94 | H16: =IFERROR((DATOS!G15-DATOS!F15)/ABS(DATOS!F15),"—") -> 1.0957447 | I16: =DATOS!H15 -> 6.44 | J16: =DATOS!I15 -> 9.21 | K16: =IFERROR((DATOS!I15-DATOS!H15)/ABS(DATOS!H15),"—") -> 0.43012422
B17: UTILIDAD BRUTA (segment profit) | C17: =DATOS!C16 | D17: =DATOS!D16 | E17: =DATOS!E16 | F17: =DATOS!F16 -> 3.26 | G17: =DATOS!G16 -> 4.29 | H17: =IFERROR((DATOS!G16-DATOS!F16)/ABS(DATOS!F16),"—") -> 0.31595092 | I17: =DATOS!H16 -> 8.45 | J17: =DATOS!I16 -> 13.32 | K17: =IFERROR((DATOS!I16-DATOS!H16)/ABS(DATOS!H16),"—") -> 0.57633136
B18: Margen bruto % | C18: =IFERROR(DATOS!C16/DATOS!C11,"—") -> 0 | D18: =IFERROR(DATOS!D16/DATOS!D11,"—") -> 0 | E18: =IFERROR(DATOS!E16/DATOS!E11,"—") -> 0 | F18: =IFERROR(DATOS!F16/DATOS!F11,"—") -> 0.63424125 | G18: =IFERROR(DATOS!G16/DATOS!G11,"—") -> 0.52189781 | I18: =IFERROR(DATOS!H16/DATOS!H11,"—") -> 0.56749496 | J18: =IFERROR(DATOS!I16/DATOS!I11,"—") -> 0.59121172
B19: G&A | C19: =DATOS!C17 | D19: =DATOS!D17 | E19: =DATOS!E17 | F19: =DATOS!F17 -> 1.8 | G19: =DATOS!G17 -> 1.94 | H19: =IFERROR((DATOS!G17-DATOS!F17)/ABS(DATOS!F17),"—") -> 0.077777778 | I19: =DATOS!H17 -> 6.3 | J19: =DATOS!I17 -> 6 | K19: =IFERROR((DATOS!I17-DATOS!H17)/ABS(DATOS!H17),"—") -> -0.047619048
B20: Depreciación | C20: =DATOS!C18 | D20: =DATOS!D18 | E20: =DATOS!E18 | F20: =DATOS!F18 -> 0.13 | G20: =DATOS!G18 -> 0.23 | H20: =IFERROR((DATOS!G18-DATOS!F18)/ABS(DATOS!F18),"—") -> 0.76923077 | I20: =DATOS!H18 -> 0.43 | J20: =DATOS!I18 -> 0.56 | K20: =IFERROR((DATOS!I18-DATOS!H18)/ABS(DATOS!H18),"—") -> 0.30232558
B21: INGRESO OPERATIVO | C21: =DATOS!C19 | D21: =DATOS!D19 | E21: =DATOS!E19 | F21: =DATOS!F19 -> 1.33 | G21: =DATOS!G19 -> 2.11 | H21: =IFERROR((DATOS!G19-DATOS!F19)/ABS(DATOS!F19),"—") -> 0.58646617 | I21: =DATOS!H19 -> 1.73 | J21: =DATOS!I19 -> 6.76 | K21: =IFERROR((DATOS!I19-DATOS!H19)/ABS(DATOS!H19),"—") -> 2.9075145
B22: Margen operativo % | C22: =IFERROR(DATOS!C19/DATOS!C11,"—") -> 0 | D22: =IFERROR(DATOS!D19/DATOS!D11,"—") -> 0 | E22: =IFERROR(DATOS!E19/DATOS!E11,"—") -> 0 | F22: =IFERROR(DATOS!F19/DATOS!F11,"—") -> 0.25875486 | G22: =IFERROR(DATOS!G19/DATOS!G11,"—") -> 0.256691 | I22: =IFERROR(DATOS!H19/DATOS!H11,"—") -> 0.11618536 | J22: =IFERROR(DATOS!I19/DATOS!I11,"—") -> 0.30004439
B24: OTRAS PARTIDAS Y RESULTADO
B25: Ingreso por intereses | C25: =DATOS!C20 | D25: =DATOS!D20 | E25: =DATOS!E20 | F25: =DATOS!F20 -> 0.63 | G25: =DATOS!G20 -> 0.94 | H25: =IFERROR((DATOS!G20-DATOS!F20)/ABS(DATOS!F20),"—") -> 0.49206349 | I25: =DATOS!H20 -> 1.9 | J25: =DATOS!I20 -> 2.8 | K25: =IFERROR((DATOS!I20-DATOS!H20)/ABS(DATOS!H20),"—") -> 0.47368421
B26: Regalías petróleo y gas | C26: =DATOS!C22 | D26: =DATOS!D22 | E26: =DATOS!E22 -> 6.7 | F26: =DATOS!F22 -> 1.14 | G26: =DATOS!G22 -> 0.98 | H26: =IFERROR((DATOS!G22-DATOS!F22)/ABS(DATOS!F22),"—") -> -0.14035088 | I26: =DATOS!H22 -> 5.86 | J26: =DATOS!I22 -> 2.24 | K26: =IFERROR((DATOS!I22-DATOS!H22)/ABS(DATOS!H22),"—") -> -0.61774744
B27: Utilidad antes de impuestos | C27: =DATOS!C23 | D27: =DATOS!D23 | E27: =DATOS!E23 | F27: =DATOS!F23 -> 2.99 | G27: =DATOS!G23 -> 3.9 | H27: =IFERROR((DATOS!G23-DATOS!F23)/ABS(DATOS!F23),"—") -> 0.30434783 | I27: =DATOS!H23 -> 9.28 | J27: =DATOS!I23 -> 11.45 | K27: =IFERROR((DATOS!I23-DATOS!H23)/ABS(DATOS!H23),"—") -> 0.23383621
B28: Impuestos | C28: =DATOS!C24 | D28: =DATOS!D24 | E28: =DATOS!E24 | F28: =DATOS!F24 -> 0.74 | G28: =DATOS!G24 -> 0.96 | H28: =IFERROR((DATOS!G24-DATOS!F24)/ABS(DATOS!F24),"—") -> 0.2972973 | I28: =DATOS!H24 -> 2.28 | J28: =DATOS!I24 -> 2.83 | K28: =IFERROR((DATOS!I24-DATOS!H24)/ABS(DATOS!H24),"—") -> 0.24122807
B29: UTILIDAD NETA | C29: =DATOS!C25 | D29: =DATOS!D25 | E29: =DATOS!E25 | F29: =DATOS!F25 -> 2.26 | G29: =DATOS!G25 -> 2.95 | H29: =IFERROR((DATOS!G25-DATOS!F25)/ABS(DATOS!F25),"—") -> 0.30530973 | I29: =DATOS!H25 -> 7 | J29: =DATOS!I25 -> 8.62 | K29: =IFERROR((DATOS!I25-DATOS!H25)/ABS(DATOS!H25),"—") -> 0.23142857
B30: Margen neto % | C30: =IFERROR(DATOS!C25/DATOS!C11,"—") -> 0 | D30: =IFERROR(DATOS!D25/DATOS!D11,"—") -> 0 | E30: =IFERROR(DATOS!E25/DATOS!E11,"—") -> 0 | F30: =IFERROR(DATOS!F25/DATOS!F11,"—") -> 0.43968872 | G30: =IFERROR(DATOS!G25/DATOS!G11,"—") -> 0.35888078 | I30: =IFERROR(DATOS!H25/DATOS!H11,"—") -> 0.47011417 | J30: =IFERROR(DATOS!I25/DATOS!I11,"—") -> 0.38260098
B31: EPS diluido ($) | C31: =DATOS!C27 | D31: =DATOS!D27 | E31: =DATOS!E27 | F31: =DATOS!F27 -> 0.09 | G31: =DATOS!G27 -> 0.12 | H31: =IFERROR((DATOS!G27-DATOS!F27)/ABS(DATOS!F27),"—") -> 0.33333333 | I31: =DATOS!H27 -> 0.29 | J31: =DATOS!I27 -> 0.36 | K31: =IFERROR((DATOS!I27-DATOS!H27)/ABS(DATOS!H27),"—") -> 0.24137931
B33: TRIMESTRE Q2 (feb) — homólogo
B34: Concepto ($M) | C34: Q2 2025 | D34: Q2 2026 | E34: Δ% | F34: Lectura
B35: Ingresos totales | C35: =DATOS!J11 -> 4 | D35: =DATOS!K11 -> 5.2 | E35: =IFERROR((DATOS!K11-DATOS!J11)/ABS(DATOS!J11),"—") -> 0.3 | F35: +30% en el trimestre feb.
B36: Utilidad neta | C36: =DATOS!J25 -> 0.8 | D36: =DATOS!K25 -> 1.1 | E36: =IFERROR((DATOS!K25-DATOS!J25)/ABS(DATOS!J25),"—") -> 0.375 | F36: +38%. Rentabilidad creciente y consistente.
B38: Lectura clave: los ingresos son "lumpy" (irregulares) por dos motivos — las ventas de lotes se reconocen por avance de obra (percent-of-completion) y las regalías de petróleo/gas varían mucho (de $5.9M en 9M25 a $2.2M en 9M26). Por eso hay que mirar tendencias, no un trimestre. Lo consistente y creciente es el NÚCLEO: agua/wastewater (+34% en 9M, disparado por ventas industriales a petroleras) y el desarrollo de Sky Ranch (+70%). El margen operativo saltó de 12% a 30% en 9 meses. La utilidad neta encadena 28 trimestres positivos. Es un compounder lento pero muy predecible en su núcleo, con opcionalidad enorme en los derechos de agua.

Sheet Balance
B2: BALANCE GENERAL — ago-2025 (fin FY) → may-2026 (Q3) ($M)
B3: Dos cortes. El activo clave son los derechos de agua ($72M) + el note receivable ($59M). Verde = de DATOS.
B5: Partida ($M) | C5: Ago-25 | D5: May-26 | E5: Comentario
B6: ACTIVOS
B7: Caja y equivalentes | C7: =DATOS!E30 -> 21.93 | D7: =DATOS!G30 -> 8.44 | E7: Baja por CapEx acelerado en Sky Ranch.
B8: Caja restringida | C8: =DATOS!E31 -> 6.45 | D8: =DATOS!G31 -> 6.19
B9: Cuentas por cobrar | C9: =DATOS!E32 -> 1.33 | D9: =DATOS!G32 -> 2.49
B10: Tierra en desarrollo | C10: =DATOS!E33 -> 7.39 | D10: =DATOS!G33 -> 4.13 | E10: Inventario de lotes en construcción.
B11: Total activo corriente | C11: =DATOS!E34 -> 31.65 | D11: =DATOS!G34 -> 15.61
B12: Inversión en agua y sistemas | C12: =DATOS!E35 -> 67.52 | D12: =DATOS!G35 -> 72.27 | E12: CLAVE: derechos de agua + infraestructura. El activo estrella.
B13: Tierra para desarrollo | C13: =DATOS!E36 -> 4.17 | D13: =DATOS!G36 -> 5.72
B14: Casas de alquiler (SFR) | C14: =DATOS!E37 -> 5.24 | D14: =DATOS!G37 -> 14.57 | E14: Crece 5→15M: nueva línea de ingresos recurrentes.
B15: Note receivable (Sky Ranch CAB) | C15: =DATOS!E38 -> 45 | D15: =DATOS!G38 -> 59.06 | E15: $59M a cobrar del CAB, 6% interés. Activo real subestimado.
B16: TOTAL ACTIVOS | C16: =DATOS!E39 -> 162.28 | D16: =DATOS!G39 -> 175.98
B17: PASIVOS Y PATRIMONIO
B18: Cuentas por pagar y acumulados | C18: =DATOS!E40 -> 7.85 | D18: =DATOS!G40 -> 5.98
B19: Ingreso diferido | C19: =DATOS!E41 -> 3.36 | D19: =DATOS!G41 -> 2.75
B20: Total pasivo corriente | C20: =DATOS!E43 -> 11.62 | D20: =DATOS!G43 -> 10.18
B21: Deuda de largo plazo | C21: =DATOS!E44 -> 6.38 | D21: =DATOS!G44 -> 12.67 | E21: SFR notes + Lost Creek (agua) + facility.
B22: TOTAL PASIVOS | C22: =DATOS!E46 -> 19.54 | D22: =DATOS!G46 -> 24.39
B23: PATRIMONIO TOTAL | C23: =DATOS!E47 -> 142.74 | D23: =DATOS!G47 -> 151.58 | E23: Crece por utilidades retenidas.
B24: Déficit acumulado | C24: =DATOS!E48 -> -32.79 | D24: =DATOS!G48 -> -24.37 | E24: Se reduce cada trimestre: −33→−24M.
B26: MÉTRICAS DEL BALANCE
B27: Deuda neta (deuda − caja) | C27: =IFERROR(DATOS!E45-DATOS!E30,"n/d") -> -15.14 | D27: =IFERROR(DATOS!G45-DATOS!G30,"n/d") -> 5.68 | E27: Baja: poca deuda vs caja.
B28: Razón corriente | C28: =IFERROR(DATOS!E34/DATOS!E43,"n/d") -> 2.7237522 | D28: =IFERROR(DATOS!G34/DATOS!G43,"n/d") -> 1.5333988 | E28: Sólida.
B29: Deuda / Patrimonio | C29: =IFERROR(DATOS!E45/DATOS!E47,"n/d") -> 0.047569007 | D29: =IFERROR(DATOS!G45/DATOS!G47,"n/d") -> 0.093152131 | E29: Muy baja (~9%): apenas apalancada.
B30: Patrimonio / Activos | C30: =IFERROR(DATOS!E47/DATOS!E39,"n/d") -> 0.87959083 | D30: =IFERROR(DATOS!G47/DATOS!G39,"n/d") -> 0.86134788 | E30: ~86%: estructura muy sólida.
B31: Valor contable por acción ($) | C31: =IFERROR(DATOS!E47/DATOS!I28,"n/d") -> 5.9228216 | D31: =IFERROR(DATOS!G47/DATOS!I28,"n/d") -> 6.2896266 | E31: Patrimonio / acciones.
B33: Lectura: balance excepcionalmente sólido para una empresa de su tamaño. Casi sin deuda (D/E ~9%), patrimonio = 86% de los activos. Dos activos que el mercado tiende a subestimar: (1) los derechos de agua contabilizados a costo histórico ($72M) pero cuyo valor de mercado es múltiplos mayores dado que sirven para 60,000 conexiones; (2) el note receivable de $59M del Sky Ranch CAB que devenga 6%. El déficit acumulado se reduce trimestre a trimestre. La contrapartida: mucho capital "atrapado" en activos de desarrollo de lenta maduración.

Sheet Análisis Financiero
B2: ANÁLISIS FINANCIERO PROFUNDO — Liquidez · Actividad · Endeudamiento · Rentabilidad · DuPont · Segmentos
B3: Metodología completa (Celsia/Murray). Calculado sobre FY2025 (año completo) y 9M-2026 (últimos datos). Todo jala de DATOS.
B5: Indicador | C5: FY2025 | D5: 9M-2026 | E5: Fórmula e interpretación
B6: 1 · LIQUIDEZ
B7: Razón corriente | C7: =IFERROR(DATOS!E34/DATOS!E43,"n/d") -> 2.7237522 | D7: =IFERROR(DATOS!G34/DATOS!G43,"n/d") -> 1.5333988 | E7: AC/PC. Capacidad de cubrir pasivos de corto plazo.
B8: Prueba ácida | C8: =IFERROR((DATOS!E34-DATOS!E33)/DATOS!E43,"n/d") -> 2.0877797 | D8: =IFERROR((DATOS!G34-DATOS!G33)/DATOS!G43,"n/d") -> 1.1277014 | E8: (AC−tierra en desarrollo)/PC. Excluye el inventario menos líquido.
B9: Prueba hiper-ácida (caja) | C9: =IFERROR(DATOS!E30/DATOS!E43,"n/d") -> 1.8872633 | D9: =IFERROR(DATOS!G30/DATOS!G43,"n/d") -> 0.82907662 | E9: Caja/PC. Liquidez inmediata.
B10: Capital de trabajo ($M) | C10: =IFERROR(DATOS!E34-DATOS!E43,"n/d") -> 20.03 | D10: =IFERROR(DATOS!G34-DATOS!G43,"n/d") -> 5.43 | E10: AC−PC. Colchón operativo.
B11: Caja + restringida + note recv ($M) | C11: =IFERROR(DATOS!E30+DATOS!E31+DATOS!E38,"n/d") -> 73.38 | D11: =IFERROR(DATOS!G30+DATOS!G31+DATOS!G38,"n/d") -> 73.69 | E11: Liquidez ampliada incluyendo cobros del CAB.
B12: 2 · ACTIVIDAD (eficiencia)
B13: Rotación de CxC | C13: =IFERROR(DATOS!E11/DATOS!E32,"n/d") -> 19.62406 | D13: =IFERROR(DATOS!I11/DATOS!G32,"n/d") -> 9.0481928 | E13: Ventas/CxC. Velocidad de cobro.
B14: Días de CxC (PMC) | C14: =IFERROR(365*DATOS!E32/DATOS!E11,"n/d") -> 18.599617 | D14: =IFERROR(365*DATOS!G32/DATOS!I11,"n/d") -> 40.339547 | E14: Periodo medio de cobro.
B15: Rotación de tierra en desarrollo | C15: =IFERROR(DATOS!E15/DATOS!E33,"n/d") -> 0 | D15: =IFERROR(DATOS!I15/DATOS!G33,"n/d") -> 2.2300242 | E15: Costo/inventario de lotes. Ritmo de venta de lotes.
B16: Días de inventario de lotes (PME) | C16: =IFERROR(365*DATOS!E33/DATOS!E15,"n/d") -> n/d | D16: =IFERROR(365*DATOS!G33/DATOS!I15,"n/d") -> 163.67535 | E16: Cuánto tarda en vender el inventario de lotes.
B17: Rotación de CxP | C17: =IFERROR(DATOS!E15/DATOS!E40,"n/d") -> 0 | D17: =IFERROR(DATOS!I15/DATOS!G40,"n/d") -> 1.5401338 | E17: Costo/CxP.
B18: Días de CxP (PMP) | C18: =IFERROR(365*DATOS!E40/DATOS!E15,"n/d") -> n/d | D18: =IFERROR(365*DATOS!G40/DATOS!I15,"n/d") -> 236.9924 | E18: Periodo medio de pago.
B19: Ciclo de conversión de efectivo | C19: =IFERROR(365*DATOS!E33/DATOS!E15+365*DATOS!E32/DATOS!E11-365*DATOS!E40/DATOS!E15,"n/d") -> n/d | D19: =IFERROR(365*DATOS!G33/DATOS!I15+365*DATOS!G32/DATOS!I11-365*DATOS!G40/DATOS!I15,"n/d") -> -32.977499 | E19: PME+PMC−PMP. Días que la empresa financia el ciclo.
B20: Rotación de activos totales | C20: =IFERROR(DATOS!E11/DATOS!E39,"n/d") -> 0.16083313 | D20: =IFERROR(DATOS!I11/DATOS!G39,"n/d") -> 0.12802591 | E20: Ventas/Activos. Baja: negocio intensivo en activos (agua/tierra).
B21: Rotación de activos de agua | C21: =IFERROR(DATOS!E8/DATOS!E35,"n/d") -> 0.17180095 | D21: =IFERROR(DATOS!I8/DATOS!G35,"n/d") -> 0.1397537 | E21: Ingresos de agua / activos de agua. Aún muy baja: infrautilizados.
B22: 3 · ENDEUDAMIENTO Y SOLVENCIA
B23: Nivel de endeudamiento | C23: =IFERROR(DATOS!E46/DATOS!E39,"n/d") -> 0.12040917 | D23: =IFERROR(DATOS!G46/DATOS!G39,"n/d") -> 0.13859529 | E23: Pasivo/Activo. Muy bajo (~13%).
B24: Apalancamiento (Pasivo/Patrimonio) | C24: =IFERROR(DATOS!E46/DATOS!E47,"n/d") -> 0.13689225 | D24: =IFERROR(DATOS!G46/DATOS!G47,"n/d") -> 0.16090513 | E24: Estructura conservadora.
B25: Deuda financiera/Patrimonio | C25: =IFERROR(DATOS!E45/DATOS!E47,"n/d") -> 0.047569007 | D25: =IFERROR(DATOS!G45/DATOS!G47,"n/d") -> 0.093152131 | E25: Solo deuda con costo. ~9%.
B26: Cobertura de intereses | C26: =IFERROR(DATOS!E19/DATOS!E21,"n/d") -> n/d | D26: =IFERROR(DATOS!I19/DATOS!I21,"n/d") -> 17.333333 | E26: EBIT/Intereses. Holgadísima.
B27: Concentración deuda CP | C27: =IFERROR(DATOS!E42/DATOS!E45,"n/d") -> 0.060382916 | D27: =IFERROR(DATOS!G42/DATOS!G45,"n/d") -> 0.10269122 | E27: % de deuda que vence en un año.
B28: 4 · RENTABILIDAD
B29: Margen bruto | C29: =IFERROR(DATOS!E16/DATOS!E11,"n/d") -> 0 | D29: =IFERROR(DATOS!I16/DATOS!I11,"n/d") -> 0.59121172 | E29: UB/Ventas.
B30: Margen operativo | C30: =IFERROR(DATOS!E19/DATOS!E11,"n/d") -> 0 | D30: =IFERROR(DATOS!I19/DATOS!I11,"n/d") -> 0.30004439 | E30: Op income/Ventas. Saltó a ~30% en 9M26.
B31: Margen EBITDA | C31: =IFERROR(DATOS!E26/DATOS!E11,"n/d") -> 0.77394636 | D31: =IFERROR(DATOS!I26/DATOS!I11,"n/d") -> 0 | E31: FY25 EBITDA/Ventas (~77%, incl. regalías).
B32: Margen neto | C32: =IFERROR(DATOS!E25/DATOS!E11,"n/d") -> 0 | D32: =IFERROR(DATOS!I25/DATOS!I11,"n/d") -> 0.38260098 | E32: UN/Ventas.
B33: ROA | C33: =IFERROR(DATOS!E25/DATOS!E39,"n/d") -> 0 | D33: =IFERROR(DATOS!I25/DATOS!G39,"n/d") -> 0.048982839 | E33: UN/Activos. Bajo: activos de lenta maduración.
B34: ROE | C34: =IFERROR(DATOS!E25/DATOS!E47,"n/d") -> 0 | D34: =IFERROR(DATOS!I25/DATOS!G47,"n/d") -> 0.056867661 | E34: UN/Patrimonio.
B35: ROIC aprox (NOPLAT/cap. invertido) | C35: =IFERROR((DATOS!E19*(1-0.24))/(DATOS!E47+DATOS!E45-DATOS!E30),"n/d") -> 0 | D35: =IFERROR((DATOS!I19*(1-0.24))/(DATOS!G47+DATOS!G45-DATOS!G30),"n/d") -> 0.032669465 | E35: Retorno sobre capital invertido. Mejora con la maduración.
B36: 5 · ANÁLISIS DUPONT (descompone el ROE)
B37: (1) Margen neto | C37: =IFERROR(DATOS!E25/DATOS!E11,"n/d") -> 0 | D37: =IFERROR(DATOS!I25/DATOS!I11,"n/d") -> 0.38260098 | E37: Rentabilidad.
B38: (2) Rotación de activos | C38: =IFERROR(DATOS!E11/DATOS!E39,"n/d") -> 0.16083313 | D38: =IFERROR(DATOS!I11/DATOS!G39,"n/d") -> 0.12802591 | E38: Eficiencia. Baja (intensivo en activos).
B39: (3) Multiplicador de capital | C39: =IFERROR(DATOS!E39/DATOS!E47,"n/d") -> 1.1368923 | D39: =IFERROR(DATOS!G39/DATOS!G47,"n/d") -> 1.1609711 | E39: Apalancamiento. Bajo (~1.16x).
B40: ROE = (1)×(2)×(3) | C40: =IFERROR((DATOS!E25/DATOS!E11)*(DATOS!E11/DATOS!E39)*(DATOS!E39/DATOS!E47),"n/d") -> 0 | D40: =IFERROR((DATOS!I25/DATOS!I11)*(DATOS!I11/DATOS!G39)*(DATOS!G39/DATOS!G47),"n/d") -> 0.056867661 | E40: Verificación DuPont. Debe igualar el ROE de arriba.
B41: 6 · MARGEN BRUTO POR SEGMENTO (9M-2026)
B42: Segmento | C42: Margen | D42: Ingreso 9M | E42: Nota
...

Sheet Proyecciones
B2: MODELO DE TRES ESTADOS PROYECTADOS Y ENLAZADOS (5 años)
B3: Resultados → Balance → Flujo de caja, enlazados. Drivers en DATOS (amarillo). DESCUADRE verifica Activo = Pasivo+Patrimonio (=0). El flujo de caja conecta la utilidad con la caja del balance.
B6: Concepto ($M) | C6: Base FY25 | D6: Año 1 | E6: Año 2 | F6: Año 3 | G6: Año 4 | H6: Año 5 | I6: Notas / enlace
B7: 1 · ESTADO DE RESULTADOS
B8: Ingresos totales | C8: =DATOS!$K$78 -> 26.1 | D8: =C8*(1+DATOS!$K$79) -> 30.015 | E8: =D8*(1+DATOS!$K$80) -> 33.91695 | F8: =E8*(1+DATOS!$K$81) -> 37.647815 | G8: =F8*(1+DATOS!$K$82) -> 41.036118 | H8: =G8*(1+DATOS!$K$83) -> 43.908646 | I8: Crece por drivers.
B9: Crecimiento % | D9: =D8/C8-1 -> 0.15 | E9: =E8/D8-1 -> 0.13 | F9: =F8/E8-1 -> 0.11 | G9: =G8/F8-1 -> 0.09 | H9: =H8/G8-1 -> 0.07
B10: Costo de ventas | C10: =DATOS!E15 | D10: =D8*(1-DATOS!$K$84) -> 13.50675 | E10: =E8*(1-DATOS!$K$84) -> 15.262628 | F10: =F8*(1-DATOS!$K$84) -> 16.941517 | G10: =G8*(1-DATOS!$K$84) -> 18.466253 | H10: =H8*(1-DATOS!$K$84) -> 19.758891 | I10: Ventas×(1−margen bruto).
B11: Utilidad bruta | C11: =C8-C10 -> 26.1 | D11: =D8-D10 -> 16.50825 | E11: =E8-E10 -> 18.654322 | F11: =F8-F10 -> 20.706298 | G11: =G8-G10 -> 22.569865 | H11: =H8-H10 -> 24.149755
B12: G&A | D12: =D8*DATOS!$K$85 -> 7.2036 | E12: =E8*DATOS!$K$85 -> 8.140068 | F12: =F8*DATOS!$K$85 -> 9.0354755 | G12: =G8*DATOS!$K$85 -> 9.8486683 | H12: =H8*DATOS!$K$85 -> 10.538075 | I12: % de ventas.
B13: Depreciación | D13: =D8*DATOS!$K$86 -> 0.750375 | E13: =E8*DATOS!$K$86 -> 0.84792375 | F13: =F8*DATOS!$K$86 -> 0.94119536 | G13: =G8*DATOS!$K$86 -> 1.0259029 | H13: =H8*DATOS!$K$86 -> 1.0977162 | I13: % de ventas.
B14: Ingreso operativo (EBIT) | C14: =C11 -> 26.1 | D14: =D11-D12-D13 -> 8.554275 | E14: =E11-E12-E13 -> 9.6663308 | F14: =F11-F12-F13 -> 10.729627 | G14: =G11-G12-G13 -> 11.695294 | H14: =H11-H12-H13 -> 12.513964
B15: (+) Interés sobre note receivable | D15: =C26*DATOS!$K$90 -> 2.7 | E15: =D26*DATOS!$K$90 -> 2.781 | F15: =E26*DATOS!$K$90 -> 2.86443 | G15: =F26*DATOS!$K$90 -> 2.9503629 | H15: =G26*DATOS!$K$90 -> 3.0388738 | I15: 6% sobre note recv del año anterior (enlace al balance).
B16: (+) Regalías petróleo y gas | D16: =DATOS!$K$89 -> 3 | E16: =DATOS!$K$89 -> 3 | F16: =DATOS!$K$89 -> 3 | G16: =DATOS!$K$89 -> 3 | H16: =DATOS!$K$89 -> 3 | I16: Driver.
B17: (−) Gasto por intereses (deuda) | D17: =C32*DATOS!$K$90 -> 0.4074 | E17: =D32*DATOS!$K$90 -> 0.518355 | F17: =E32*DATOS!$K$90 -> 0.56406615 | G17: =F32*DATOS!$K$90 -> 0.61393403 | H17: =G32*DATOS!$K$90 -> 0.66969131 | I17: Sobre deuda del año anterior.
B18: Utilidad antes de impuestos | D18: =D14+D15+D16-D17 -> 13.846875 | E18: =E14+E15+E16-E17 -> 14.928976 | F18: =F14+F15+F16-F17 -> 16.029991 | G18: =G14+G15+G16-G17 -> 17.031722 | H18: =H14+H15+H16-H17 -> 17.883147
B19: (−) Impuestos | D19: =D18*DATOS!K66 -> 3.32325 | E19: =E18*DATOS!K66 -> 3.5829542 | F19: =F18*DATOS!K66 -> 3.8471978 | G19: =G18*DATOS!K66 -> 4.0876134 | H19: =H18*DATOS!K66 -> 4.2919552 | I19: Tasa efectiva de DATOS.
B20: UTILIDAD NETA | D20: =D18-D19 -> 10.523625 | E20: =E18-E19 -> 11.346022 | F20: =F18-F19 -> 12.182793 | G20: =G18-G19 -> 12.944109 | H20: =H18-H19 -> 13.591191
B22: 2 · BALANCE GENERAL
B23: Caja y equivalentes | C23: =DATOS!E30 -> 21.93 | D23: =D49 -> 24.00375 | E23: =E49 -> 25.827513 | F23: =F49 -> 27.470614 | G23: =G49 -> 28.960375 | H23: =H49 -> 30.333063 | I23: ← Caja final del Flujo de caja (enlace clave).
B24: Cuentas por cobrar | C24: =DATOS!E32 -> 1.33 | D24: =D8*(DATOS!E32/DATOS!E11) -> 1.5295 | E24: =E8*(DATOS!E32/DATOS!E11) -> 1.728335 | F24: =F8*(DATOS!E32/DATOS!E11) -> 1.9184519 | G24: =G8*(DATOS!E32/DATOS!E11) -> 2.0911125 | H24: =H8*(DATOS!E32/DATOS!E11) -> 2.2374904 | I24: Mantiene ratio CxC/ventas base.
B25: Tierra en desarrollo | C25: =DATOS!E33 -> 7.39 | D25: =D8*(DATOS!E33/DATOS!E11) -> 8.4985 | E25: =E8*(DATOS!E33/DATOS!E11) -> 9.603305 | F25: =F8*(DATOS!E33/DATOS!E11) -> 10.659669 | G25: =G8*(DATOS!E33/DATOS!E11) -> 11.619039 | H25: =H8*(DATOS!E33/DATOS!E11) -> 12.432371 | I25: Ratio inventario/ventas.
B26: Note receivable (CAB) | C26: =DATOS!E38 -> 45 | D26: =C26*1.03 -> 46.35 | E26: =D26*1.03 -> 47.7405 | F26: =E26*1.03 -> 49.172715 | G26: =F26*1.03 -> 50.647896 | H26: =G26*1.03 -> 52.167333 | I26: Crece ~3%/año (mejoras públicas netas de cobros).
B27: Inversión en agua y sistemas | C27: =DATOS!E35 -> 67.52 | D27: =C27+D8*DATOS!$K$87*0.5-D13 -> 71.271875 | E27: =D27+E8*DATOS!$K$87*0.5-E13 -> 75.511494 | F27: =E27+F8*DATOS!$K$87*0.5-F13 -> 80.217471 | G27: =F27+G8*DATOS!$K$87*0.5-G13 -> 85.346985 | H27: =G27+H8*DATOS!$K$87*0.5-H13 -> 90.835566 | I27: + mitad del CapEx − depreciación.
B28: Casas de alquiler + otros fijos | C28: =DATOS!E37 -> 5.24 | D28: =C28+D8*DATOS!$K$87*0.5 -> 9.74225 | E28: =D28+E8*DATOS!$K$87*0.5 -> 14.829792 | F28: =E28+F8*DATOS!$K$87*0.5 -> 20.476965 | G28: =F28+G8*DATOS!$K$87*0.5 -> 26.632382 | H28: =G28+H8*DATOS!$K$87*0.5 -> 33.218679 | I28: + mitad del CapEx (SFR/otros).
B29: Otros activos (resto) | C29: =DATOS!E39-DATOS!E30-DATOS!E32-DATOS!E33-DATOS!E38-DATOS!E35-DATOS!E37 -> 13.87 | D29: =C29 -> 13.87 | E29: =D29 -> 13.87 | F29: =E29 -> 13.87 | G29: =F29 -> 13.87 | H29: =G29 -> 13.87 | I29: Resto de activos, constante.
B30: TOTAL ACTIVOS | C30: =C23+C24+C25+C26+C27+C28+C29 -> 162.28 | D30: =D23+D24+D25+D26+D27+D28+D29 -> 175.26587 | E30: =E23+E24+E25+E26+E27+E28+E29 -> 189.11094 | F30: =F23+F24+F25+F26+F27+F28+F29 -> 203.78588 | G30: =G23+G24+G25+G26+G27+G28+G29 -> 219.16779 | H30: =H23+H24+H25+H26+H27+H28+H29 -> 235.0945
B31: Cuentas por pagar y otros | C31: =DATOS!E43 -> 11.62 | D31: =D8*(DATOS!E43/DATOS!E11) -> 13.363 | E31: =E8*(DATOS!E43/DATOS!E11) -> 15.10019 | F31: =F8*(DATOS!E43/DATOS!E11) -> 16.761211 | G31: =G8*(DATOS!E43/DATOS!E11) -> 18.26972 | H31: =H8*(DATOS!E43/DATOS!E11) -> 19.5486 | I31: Ratio pasivo corriente/ventas.
B32: Deuda total | C32: =DATOS!E45 -> 6.79 | D32: =D30-D31-D34 -> 8.63925 | E32: =E30-E31-E34 -> 9.4011025 | F32: =F30-F31-F34 -> 10.232234 | G32: =G30-G31-G34 -> 11.161522 | H32: =H30-H31-H34 -> 12.218163 | I32: Deuda previa + variación del flujo de financiación.
B33: TOTAL PASIVOS | C33: =C31+C32 -> 18.41 | D33: =D31+D32 -> 22.00225 | E33: =E31+E32 -> 24.501293 | F33: =F31+F32 -> 26.993445 | G33: =G31+G32 -> 29.431242 | H33: =H31+H32 -> 31.766763
B34: PATRIMONIO | C34: =DATOS!E47 -> 142.74 | D34: =C34+D20-D20*DATOS!$K$91 -> 153.26362 | E34: =D34+E20-E20*DATOS!$K$91 -> 164.60965 | F34: =E34+F20-F20*DATOS!$K$91 -> 176.79244 | G34: =F34+G20-G20*DATOS!$K$91 -> 189.73655 | H34: =G34+H20-H20*DATOS!$K$91 -> 203.32774 | I34: Patrimonio previo + utilidad − dividendos.
B35: TOTAL PASIVO + PATRIMONIO | C35: =C33+C34 -> 161.15 | D35: =D33+D34 -> 175.26587 | E35: =E33+E34 -> 189.11094 | F35: =F33+F34 -> 203.78588 | G35: =G33+G34 -> 219.16779 | H35: =H33+H34 -> 235.0945
B36: DESCUADRE (Activo − Pas − Patr) | C36: =C30-C35 -> 1.13 | D36: =D30-D35 -> 0 | E36: =E30-E35 -> 0 | F36: =F30-F35 -> 0 | G36: =G30-G35 -> 0 | H36: =H30-H35 -> 0 | I36: DEBE SER ~0. Verifica cuadre contable.
B38: 3 · FLUJO DE CAJA
B39: Utilidad neta | D39: =D20 -> 10.523625 | E39: =E20 -> 11.346022 | F39: =F20 -> 12.182793 | G39: =G20 -> 12.944109 | H39: =H20 -> 13.591191 | I39: ← del Estado de resultados.
B40: (+) Depreciación | D40: =D13 -> 0.750375 | E40: =E13 -> 0.84792375 | F40: =F13 -> 0.94119536 | G40: =G13 -> 1.0259029 | H40: =H13 -> 1.0977162 | I40: No-caja, se suma.
B41: (−) Δ Capital de trabajo | D41: =-(D8-C8)*DATOS!$K$88 -> -0.19575 | E41: =-(E8-D8)*DATOS!$K$88 -> -0.1950975 | F41: =-(F8-E8)*DATOS!$K$88 -> -0.18654323 | G41: =-(G8-F8)*DATOS!$K$88 -> -0.16941517 | H41: =-(H8-G8)*DATOS!$K$88 -> -0.14362641 | I41: Crecimiento de ventas × % NWC.
B42: Flujo de caja operativo | D42: =D39+D40+D41 -> 11.07825 | E42: =E39+E40+E41 -> 11.998848 | F42: =F39+F40+F41 -> 12.937445 | G42: =G39+G40+G41 -> 13.800597 | H42: =H39+H40+H41 -> 14.545281
B43: (−) CapEx | D43: =-D8*DATOS!$K$87 -> -9.0045 | E43: =-E8*DATOS!$K$87 -> -10.175085 | F43: =-F8*DATOS!$K$87 -> -11.294344 | G43: =-G8*DATOS!$K$87 -> -12.310835 | H43: =-H8*DATOS!$K$87 -> -13.172594 | I43: % de ventas.
B44: Flujo de caja libre (FCF) | D44: =D42+D43 -> 2.07375 | E44: =E42+E43 -> 1.8237628 | F44: =F42+F43 -> 1.6431009 | G44: =G42+G43 -> 1.4897615 | H44: =H42+H43 -> 1.3726873 | I44: OCF − CapEx. ESTE alimenta el DCF.
B45: (+/−) Variación de deuda | D45: =MAX(0,-(D44)) -> 0 | E45: =MAX(0,-(E44)) -> 0 | F45: =MAX(0,-(F44)) -> 0 | G45: =MAX(0,-(G44)) -> 0 | H45: =MAX(0,-(H44)) -> 0 | I45: Si el FCF no cubre, toma deuda (plug simple).
...

Sheet Valoración
B2: VALORACIÓN PROFUNDA — WACC · NOPLAT/ROIC/g · DCF · Múltiplos · NAV (suma de partes)
B3: PCYO es rentable → se puede valorar por DCF (a diferencia de UUUU). Además NAV por derechos de agua. Amarillo = editable.
B5: 1 · COSTO DE CAPITAL (WACC vía CAPM)
B6: Tasa libre de riesgo (Rf) | C6: =DATOS!K63 -> 0.043 | E6: De DATOS.
B7: Prima de riesgo (ERP) | C7: =DATOS!K64 -> 0.055 | E7: De DATOS.
B8: Beta desapalancado (βu) | C8: =DATOS!K65 -> 0.75 | E8: Utility de agua: defensivo, beta bajo. De DATOS.
B9: Valor de mercado del equity (E) | C9: =DATOS!I55*DATOS!I28 -> 241 | E9: Precio × 24.1M acciones.
B10: Valor de la deuda (D) | C10: =DATOS!G45 -> 14.12 | E10: Deuda total (de DATOS).
B11: Peso deuda D/(D+E) | C11: =C10/(C10+C9) -> 0.055346504
B12: Peso equity E/(D+E) | C12: =C9/(C10+C9) -> 0.9446535
B13: Tasa impositiva (t) | C13: =DATOS!K66 -> 0.24
B14: Beta apalancado (βL, Hamada) | C14: =C8*(1+(1-C13)*C10/C9) -> 0.78339585 | E14: βu×(1+(1−t)×D/E).
B15: Costo del equity (Ke = CAPM) | C15: =C6+C14*C7 -> 0.086086772 | E15: Rf + βL × ERP.
B16: Costo de la deuda (Kd) | C16: =DATOS!K67 -> 0.06
B17: WACC | C17: =C12*C15+C11*C16*(1-C13) -> 0.083845971 | E17: We×Ke + Wd×Kd(1−t).
B19: 2 · CREACIÓN DE VALOR (NOPLAT · ROIC · g endógeno) — base 9M-2026 anualizado
B20: Ingreso operativo anualizado (9M×4/3) ($M) | C20: =DATOS!I19*4/3 -> 9.0133333 | E20: Anualiza los 9 meses. Aproximación.
B21: NOPLAT (op × (1−t)) ($M) | C21: =C20*(1-C13) -> 6.8501333 | E21: Utilidad operativa neta de impuestos.
B22: Capital invertido ($M) | C22: =DATOS!G47+DATOS!G45-DATOS!G30 -> 157.26 | E22: Patrimonio + deuda − caja.
B23: ROIC (NOPLAT/Capital invertido) | C23: =C21/C22 -> 0.043559286 | E23: Retorno sobre capital. Bajo hoy (activos infrautilizados); sube con la maduración.
B24: Spread (ROIC − WACC) | C24: =C23-C17 -> -0.040286684 | E24: >0 crea valor; <0 lo destruye (hoy). Mejora con volumen de conexiones.
B25: 3 · DCF — Flujo de Caja Libre REAL (desde Proyecciones)
B26: Año | C26: FCF ($M) | D26: VP ($M) | E26: FCF viene de la hoja Proyecciones (fila FCF).
B27: 1 | C27: =Proyecciones!D44 -> 2.07375 | D27: =C27/(1+C17)^1 -> 1.9133254
B28: 2 | C28: =Proyecciones!E44 -> 1.8237628 | D28: =C28/(1+C17)^2 -> 1.5525058
B29: 3 | C29: =Proyecciones!F44 -> 1.6431009 | D29: =C29/(1+C17)^3 -> 1.2905105
B30: 4 | C30: =Proyecciones!G44 -> 1.4897615 | D30: =C30/(1+C17)^4 -> 1.0795592
B31: 5 | C31: =Proyecciones!H44 -> 1.3726873 | D31: =C31/(1+C17)^5 -> 0.91776986
B32: Valor terminal (Gordon) | C32: =(Proyecciones!H14*(1-DATOS!K66)*(1+DATOS!K68))/(C17-DATOS!K68) -> 181.92505 | D32: =C32/(1+C17)^5 -> 121.63391 | E32: Terminal sobre FCF NORMALIZADO (EBIT×(1−t), CapEx=deprec en madurez). Evita subvalorar por CapEx de crecimiento.
B33: Valor empresa (EV) ($M) | C33: =SUM(D27:D31)+D32 -> 128.38758
B34: (+) Caja + note recv − deuda ($M) | C34: =DATOS!G30+DATOS!G38-DATOS!G45 -> 53.38 | E34: Puente EV→equity.
B35: Valor del patrimonio ($M) | C35: =C33+C34 -> 181.76758
B36: Valor intrínseco por acción — DCF ($) | C36: =C35/DATOS!I28 -> 7.5422234
B47: 4 · NAV / SUMA DE PARTES (valor de los activos, incl. derechos de agua)
B48: (+) Patrimonio contable ($M) | C48: =DATOS!G47 -> 151.58 | E48: Book value actual.
B49: (+) Valor derechos de agua no usados | C49: =(DATOS!I59-DATOS!I60)*DATOS!K69/1000 -> 1745.46 | E49: (60,000−1,818) conexiones × $30K neto/conexión. MUY editable — el gran comodín.
B50: NAV total (con opción agua) ($M) | C50: =DATOS!G47+C49 -> 1897.04 | E50: Book value + valor de los derechos de agua ociosos.
B51: NAV por acción ($) | C51: =C50/DATOS!I28 -> 78.715353
B53: 5 · SÍNTESIS Y MÚLTIPLOS
B54: Capitalización de mercado ($M) | C54: =DATOS!I55*DATOS!I28 -> 241 | E54: Precio × acciones.
...

Sheet Sensibilidad
B2: ANÁLISIS DE SENSIBILIDAD — Valor intrínseco por acción
B3: Muestra cómo cambia el valor por acción del DCF según WACC (filas) y crecimiento perpetuo g (columnas). El centro (resaltado) es el escenario base. Así se ve el RANGO de valor, no un número único — lo que exige un análisis profesional.
B5: WACC \ g → | C5: 0.02 | D5: 0.025 | E5: 0.03 | F5: 0.035 | G5: 0.04
B6: 0.065 | C6: =((Proyecciones!D44/(1+$B6)^1+Proyecciones!E44/(1+$B6)^2+Proyecciones!F44/(1+$B6)^3+Proyecciones!G44/(1+$B6)^4+Proyecciones!H44/(1+$B6)^5+(Proyecciones!H14*(1-DATOS!K66)*(1+C$5)/($B6-C$5))/(1+$B6)^5)+(DATOS!G30+DATOS!G38-DATOS!G45))/DATOS!I28 -> 9.0372836 | D6: =((Proyecciones!D44/(1+$B6)^1+Proyecciones!E44/(1+$B6)^2+Proyecciones!F44/(1+$B6)^3+Proyecciones!G44/(1+$B6)^4+Proyecciones!H44/(1+$B6)^5+(Proyecciones!H14*(1-DATOS!K66)*(1+D$5)/($B6-D$5))/(1+$B6)^5)+(DATOS!G30+DATOS!G38-DATOS!G45))/DATOS!I28 -> 9.8893835 | E6: =((Proyecciones!D44/(1+$B6)^1+Proyecciones!E44/(1+$B6)^2+Proyecciones!F44/(1+$B6)^3+Proyecciones!G44/(1+$B6)^4+Proyecciones!H44/(1+$B6)^5+(Proyecciones!H14*(1-DATOS!K66)*(1+E$5)/($B6-E$5))/(1+$B6)^5)+(DATOS!G30+DATOS!G38-DATOS!G45))/DATOS!I28 -> 10.984941 | F6: =((Proyecciones!D44/(1+$B6)^1+Proyecciones!E44/(1+$B6)^2+Proyecciones!F44/(1+$B6)^3+Proyecciones!G44/(1+$B6)^4+Proyecciones!H44/(1+$B6)^5+(Proyecciones!H14*(1-DATOS!K66)*(1+F$5)/($B6-F$5))/(1+$B6)^5)+(DATOS!G30+DATOS!G38-DATOS!G45))/DATOS!I28 -> 12.445683 | G6: =((Proyecciones!D44/(1+$B6)^1+Proyecciones!E44/(1+$B6)^2+Proyecciones!F44/(1+$B6)^3+Proyecciones!G44/(1+$B6)^4+Proyecciones!H44/(1+$B6)^5+(Proyecciones!H14*(1-DATOS!K66)*(1+G$5)/($B6-G$5))/(1+$B6)^5)+(DATOS!G30+DATOS!G38-DATOS!G45))/DATOS!I28 -> 14.490723
B7: 0.075 | C7: =((Proyecciones!D44/(1+$B7)^1+Proyecciones!E44/(1+$B7)^2+Proyecciones!F44/(1+$B7)^3+Proyecciones!G44/(1+$B7)^4+Proyecciones!H44/(1+$B7)^5+(Proyecciones!H14*(1-DATOS!K66)*(1+C$5)/($B7-C$5))/(1+$B7)^5)+(DATOS!G30+DATOS!G38-DATOS!G45))/DATOS!I28 -> 7.5991542 | D7: =((Proyecciones!D44/(1+$B7)^1+Proyecciones!E44/(1+$B7)^2+Proyecciones!F44/(1+$B7)^3+Proyecciones!G44/(1+$B7)^4+Proyecciones!H44/(1+$B7)^5+(Proyecciones!H14*(1-DATOS!K66)*(1+D$5)/($B7-D$5))/(1+$B7)^5)+(DATOS!G30+DATOS!G38-DATOS!G45))/DATOS!I28 -> 8.136427 | E7: =((Proyecciones!D44/(1+$B7)^1+Proyecciones!E44/(1+$B7)^2+Proyecciones!F44/(1+$B7)^3+Proyecciones!G44/(1+$B7)^4+Proyecciones!H44/(1+$B7)^5+(Proyecciones!H14*(1-DATOS!K66)*(1+E$5)/($B7-E$5))/(1+$B7)^5)+(DATOS!G30+DATOS!G38-DATOS!G45))/DATOS!I28 -> 8.7930939 | F7: =((Proyecciones!D44/(1+$B7)^1+Proyecciones!E44/(1+$B7)^2+Proyecciones!F44/(1+$B7)^3+Proyecciones!G44/(1+$B7)^4+Proyecciones!H44/(1+$B7)^5+(Proyecciones!H14*(1-DATOS!K66)*(1+F$5)/($B7-F$5))/(1+$B7)^5)+(DATOS!G30+DATOS!G38-DATOS!G45))/DATOS!I28 -> 9.6139274 | G7: =((Proyecciones!D44/(1+$B7)^1+Proyecciones!E44/(1+$B7)^2+Proyecciones!F44/(1+$B7)^3+Proyecciones!G44/(1+$B7)^4+Proyecciones!H44/(1+$B7)^5+(Proyecciones!H14*(1-DATOS!K66)*(1+G$5)/($B7-G$5))/(1+$B7)^5)+(DATOS!G30+DATOS!G38-DATOS!G45))/DATOS!I28 -> 10.669285
B8: 0.084 | C8: =((Proyecciones!D44/(1+$B8)^1+Proyecciones!E44/(1+$B8)^2+Proyecciones!F44/(1+$B8)^3+Proyecciones!G44/(1+$B8)^4+Proyecciones!H44/(1+$B8)^5+(Proyecciones!H14*(1-DATOS!K66)*(1+C$5)/($B8-C$5))/(1+$B8)^5)+(DATOS!G30+DATOS!G38-DATOS!G45))/DATOS!I28 -> 6.6971571 | D8: =((Proyecciones!D44/(1+$B8)^1+Proyecciones!E44/(1+$B8)^2+Proyecciones!F44/(1+$B8)^3+Proyecciones!G44/(1+$B8)^4+Proyecciones!H44/(1+$B8)^5+(Proyecciones!H14*(1-DATOS!K66)*(1+D$5)/($B8-D$5))/(1+$B8)^5)+(DATOS!G30+DATOS!G38-DATOS!G45))/DATOS!I28 -> 7.0756104 | E8: =((Proyecciones!D44/(1+$B8)^1+Proyecciones!E44/(1+$B8)^2+Proyecciones!F44/(1+$B8)^3+Proyecciones!G44/(1+$B8)^4+Proyecciones!H44/(1+$B8)^5+(Proyecciones!H14*(1-DATOS!K66)*(1+E$5)/($B8-E$5))/(1+$B8)^5)+(DATOS!G30+DATOS!G38-DATOS!G45))/DATOS!I28 -> 7.5241477 | F8: =((Proyecciones!D44/(1+$B8)^1+Proyecciones!E44/(1+$B8)^2+Proyecciones!F44/(1+$B8)^3+Proyecciones!G44/(1+$B8)^4+Proyecciones!H44/(1+$B8)^5+(Proyecciones!H14*(1-DATOS!K66)*(1+F$5)/($B8-F$5))/(1+$B8)^5)+(DATOS!G30+DATOS!G38-DATOS!G45))/DATOS!I28 -> 8.0642233 | G8: =((Proyecciones!D44/(1+$B8)^1+Proyecciones!E44/(1+$B8)^2+Proyecciones!F44/(1+$B8)^3+Proyecciones!G44/(1+$B8)^4+Proyecciones!H44/(1+$B8)^5+(Proyecciones!H14*(1-DATOS!K66)*(1+G$5)/($B8-G$5))/(1+$B8)^5)+(DATOS!G30+DATOS!G38-DATOS!G45))/DATOS!I28 -> 8.7270432
B9: 0.095 | C9: =((Proyecciones!D44/(1+$B9)^1+Proyecciones!E44/(1+$B9)^2+Proyecciones!F44/(1+$B9)^3+Proyecciones!G44/(1+$B9)^4+Proyecciones!H44/(1+$B9)^5+(Proyecciones!H14*(1-DATOS!K66)*(1+C$5)/($B9-C$5))/(1+$B9)^5)+(DATOS!G30+DATOS!G38-DATOS!G45))/DATOS!I28 -> 5.8969982 | D9: =((Proyecciones!D44/(1+$B9)^1+Proyecciones!E44/(1+$B9)^2+Proyecciones!F44/(1+$B9)^3+Proyecciones!G44/(1+$B9)^4+Proyecciones!H44/(1+$B9)^5+(Proyecciones!H14*(1-DATOS!K66)*(1+D$5)/($B9-D$5))/(1+$B9)^5)+(DATOS!G30+DATOS!G38-DATOS!G45))/DATOS!I28 -> 6.1584223 | E9: =((Proyecciones!D44/(1+$B9)^1+Proyecciones!E44/(1+$B9)^2+Proyecciones!F44/(1+$B9)^3+Proyecciones!G44/(1+$B9)^4+Proyecciones!H44/(1+$B9)^5+(Proyecciones!H14*(1-DATOS!K66)*(1+E$5)/($B9-E$5))/(1+$B9)^5)+(DATOS!G30+DATOS!G38-DATOS!G45))/DATOS!I28 -> 6.4600655 | F9: =((Proyecciones!D44/(1+$B9)^1+Proyecciones!E44/(1+$B9)^2+Proyecciones!F44/(1+$B9)^3+Proyecciones!G44/(1+$B9)^4+Proyecciones!H44/(1+$B9)^5+(Proyecciones!H14*(1-DATOS!K66)*(1+F$5)/($B9-F$5))/(1+$B9)^5)+(DATOS!G30+DATOS!G38-DATOS!G45))/DATOS!I28 -> 6.8119826 | G9: =((Proyecciones!D44/(1+$B9)^1+Proyecciones!E44/(1+$B9)^2+Proyecciones!F44/(1+$B9)^3+Proyecciones!G44/(1+$B9)^4+Proyecciones!H44/(1+$B9)^5+(Proyecciones!H14*(1-DATOS!K66)*(1+G$5)/($B9-G$5))/(1+$B9)^5)+(DATOS!G30+DATOS!G38-DATOS!G45))/DATOS!I28 -> 7.2278847
B10: 0.105 | C10: =((Proyecciones!D44/(1+$B10)^1+Proyecciones!E44/(1+$B10)^2+Proyecciones!F44/(1+$B10)^3+Proyecciones!G44/(1+$B10)^4+Proyecciones!H44/(1+$B10)^5+(Proyecciones!H14*(1-DATOS!K66)*(1+C$5)/($B10-C$5))/(1+$B10)^5)+(DATOS!G30+DATOS!G38-DATOS!G45))/DATOS!I28 -> 5.3558456 | D10: =((Proyecciones!D44/(1+$B10)^1+Proyecciones!E44/(1+$B10)^2+Proyecciones!F44/(1+$B10)^3+Proyecciones!G44/(1+$B10)^4+Proyecciones!H44/(1+$B10)^5+(Proyecciones!H14*(1-DATOS!K66)*(1+D$5)/($B10-D$5))/(1+$B10)^5)+(DATOS!G30+DATOS!G38-DATOS!G45))/DATOS!I28 -> 5.5504728 | E10: =((Proyecciones!D44/(1+$B10)^1+Proyecciones!E44/(1+$B10)^2+Proyecciones!F44/(1+$B10)^3+Proyecciones!G44/(1+$B10)^4+Proyecciones!H44/(1+$B10)^5+(Proyecciones!H14*(1-DATOS!K66)*(1+E$5)/($B10-E$5))/(1+$B10)^5)+(DATOS!G30+DATOS!G38-DATOS!G45))/DATOS!I28 -> 5.7710502 | F10: =((Proyecciones!D44/(1+$B10)^1+Proyecciones!E44/(1+$B10)^2+Proyecciones!F44/(1+$B10)^3+Proyecciones!G44/(1+$B10)^4+Proyecciones!H44/(1+$B10)^5+(Proyecciones!H14*(1-DATOS!K66)*(1+F$5)/($B10-F$5))/(1+$B10)^5)+(DATOS!G30+DATOS!G38-DATOS!G45))/DATOS!I28 -> 6.0231387 | G10: =((Proyecciones!D44/(1+$B10)^1+Proyecciones!E44/(1+$B10)^2+Proyecciones!F44/(1+$B10)^3+Proyecciones!G44/(1+$B10)^4+Proyecciones!H44/(1+$B10)^5+(Proyecciones!H14*(1-DATOS!K66)*(1+G$5)/($B10-G$5))/(1+$B10)^5)+(DATOS!G30+DATOS!G38-DATOS!G45))/DATOS!I28 -> 6.3140101
B12: Precio de mercado actual: | D12: =DATOS!I55 -> 10 | E12: Compara cada celda contra este precio: verde = infravalorada, rojo = sobrevalorada.
B14: Lectura: el valor por acción NO es un número único sino un rango. Con WACC de 8.4% y g de 3% (centro), el DCF da el valor base. Bajar el WACC o subir g dispara el valor (esquina inferior derecha); lo contrario lo hunde (esquina superior izquierda). Esto es lo que un comité de inversión quiere ver: cuánto depende la tesis de los supuestos. Si toda la esquina supera el precio de mercado, el margen de seguridad es robusto; si solo unas celdas, es frágil.

Sheet Comparables
B2: ANÁLISIS DE COMPARABLES (Comps) — múltiplos de mercado
B3: Ancla la valoración de PCYO contra empresas similares (agua, tierras, utilities de recursos). Los múltiplos son aproximados/editables (azul) — en un caso real se sacan de Bloomberg/CapIQ. Se aplica la mediana a PCYO.
B5: Empresa | C5: Ticker | D5: P/U | E5: P/VC | F5: EV/EBITDA | G5: Comentario
B6: American States Water | C6: AWR | D6: 28 | E6: 3.1 | F6: 15 | G6: Utility de agua regulada, premium.
B7: California Water Service | C7: CWT | D7: 24 | E7: 2.2 | F7: 11.5 | G7: Utility de agua, California.
B8: SJW Group | C8: SJW | D8: 22 | E8: 1.7 | F8: 12 | G8: Utility de agua regional.
B9: The St. Joe Company | C9: JOE | D9: 30 | E9: 3.5 | F9: 22 | G9: Desarrollo de tierras (Florida). Comparable de land.
B10: Texas Pacific Land | C10: TPL | D10: 35 | E10: 12 | F10: 28 | G10: Tierra + agua + regalías. Premium extremo.
B11: Limoneira | C11: LMNR | D11: 40 | E11: 1.3 | F11: 18 | G11: Agua + tierra agrícola.
B12: MEDIANA | D12: =MEDIAN(D6:D11) -> 29 | E12: =MEDIAN(E6:E11) -> 2.65 | F12: =MEDIAN(F6:F11) -> 16.5 | G12: Mediana: menos sensible a extremos (TPL).
B14: VALORACIÓN IMPLÍCITA DE PCYO POR COMPS
B15: Métrica | C15: PCYO base | D15: × múltiplo med. | E15: Valor/acción | F15: Base
B16: Por P/U | C16: =(DATOS!I25*4/3) -> 11.493333 | D16: =D12 -> 29 | E16: =(DATOS!I25*4/3)*D12/DATOS!I28 -> 13.830152 | F16: Utilidad neta anualizada × P/U mediana.
B17: Por P/VC | C17: =DATOS!G47 -> 151.58 | D17: =E12 -> 2.65 | E17: =DATOS!G47*E12/DATOS!I28 -> 16.66751 | F17: Patrimonio × P/VC mediana.
B18: Por EV/EBITDA | C18: =DATOS!E26 -> 20.2 | D18: =F12 -> 16.5 | E18: =(DATOS!E26*F12+DATOS!G30-DATOS!G45)/DATOS!I28 -> 13.594191 | F18: (EBITDA × múltiplo + caja − deuda)/acciones.
B19: PROMEDIO COMPS | E19: =AVERAGE(E16:E18) -> 14.697284 | F19: Promedio de los tres métodos de comps.
B21: Precio de mercado actual: | E21: =DATOS!I55 -> 10
B23: Nota metodológica: los comps de utilities de agua (AWR, CWT, SJW) capturan el segmento recurrente; los de tierra (JOE, TPL) el desarrollo. TPL es un outlier premium (tierra+agua+regalías en Texas), por eso se usa la MEDIANA y no el promedio. PCYO comparte rasgos de ambos grupos, lo que justifica un múltiplo mixto. Los comps por P/VC suelen subvalorar a PCYO porque sus derechos de agua están a costo histórico — de ahí que el NAV (hoja Valoración) sea un complemento necesario.
