Workbook

Sheet Resumen
B2: USA RARE EARTH (NASDAQ: USAR) — Resumen Ejecutivo
B3: Modelo profesional con 4 capas: 3 estados enlazados, DCF real, sensibilidad, comparables — más un NAV por ser empresa de opción. Datos SEC hasta Q2 2026 (jun-2026). Cifras en USD.
B5: CIFRAS CLAVE (de DATOS)
B6: Precio de la acción | C6: =DATOS!K44 -> 17.34 | D6: ~$17.3 (ago 2026). Rango 52s: $11–44.
B7: Ingresos Q2 2026 | C7: =DATOS!G8 -> 5.82 | D7: Solo metales (LCM). Aún sin imanes ni mina.
B8: Pérdida operativa H1 2026 | C8: =DATOS!I14 -> -82.99 | D8: La pérdida "real" (sin ruido de warrants).
B9: Caja + equivalentes (jun-2026) | C9: =DATOS!K22 -> 1530.1 | D9: ~$1.53B tras PIPE de $1.5B. El gran colchón.
B10: Deuda financiera real | C10: =DATOS!K39 -> 0 | D10: CERO: repagó su único préstamo.
B11: Patrimonio (jun-2026) | C11: =DATOS!K38 -> 2537 | D11: ~$2.54B. Financiada con capital.
B12: Caja por acción | C12: =DATOS!K22/DATOS!K20 -> 6.2529628 | D12: Buena parte del precio es caja pura.
B13: Respaldo CHIPS Act | C13: =DATOS!K46 -> 1577 | D13: Hasta $1.6B en fondos y garantías del gobierno.
B15: VEREDICTO
B16: Tipo de inversión | C16: Opción a gran escala | D16: Valor casi todo en el futuro (cadena mina-a-imán), no en el negocio de hoy.
B17: Negocio hoy | C17: En construcción | D17: Casi sin ingresos; pierde dinero mientras construye mina y plantas.
B18: Balance | C18: Fortaleza excepcional | D18: ~$1.53B en caja, sin deuda. De los balances más fuertes del sector junior.
B19: El gran potencial | C19: Mina-a-imán USA | D19: Round Top (Texas) + planta de imanes (Oklahoma). Meta: $700–800M ingresos.
B20: Valoración | C20: DCF≈NAV, precio arriba | D20: Precio (~$17) muy por encima del valor fundamentado (~$8): prima estratégica.
B21: Riesgo/premio | C21: Muy alto/muy asimétrico | D21: Ejecución (construir a tiempo), dilución (Serra Verde) y litigio con MP.
B23: COMPARACIÓN DEL PORTAFOLIO (7 empresas)
B24: LEU (Centrus) | C24: Rentable · enriquecimiento | D24: El más maduro; precio justificado por fundamentales.
B25: HSAI (Hesai) | C25: Crecimiento rentable · LiDAR | D25: Recién rentable, crecimiento explosivo. Alto upside, riesgo China.
B26: MP (MP Materials) | C26: Cruzando breakeven · imanes | D26: EBITDA+; prima estratégica. El gemelo maduro de USAR.
B27: PCYO (Pure Cycle) | C27: Rentable · agua | D27: Compounder lento y predecible; opción sobre derechos de agua.
B28: UUUU (Energy Fuels) | C28: Pierde dinero · opción REE | D28: Especulativo; se valora por NAV.
B29: ASPI (ASP Isotopes) | C29: Desarrollo · isótopos/nuclear | D29: Muy temprano, opción pura. Balance fuerte, ejecución por probar.
B30: USAR (USA Rare Earth) | C30: Construcción · imanes REE | D30: Opción a gran escala. Balance descomunal ($1.5B), precio con prima.
B32: GUÍA DE HOJAS: DATOS (fuente+drivers) · Estado Resultados · Balance · Análisis Financiero · Proyecciones (3 estados enlazados) · Valoración (WACC+DCF+NAV) · Sensibilidad · Comparables.
B33: DESCARGO: material educativo, no asesoría financiera. Empresa en construcción: riesgo muy alto, dilución probable, posible pérdida. Verifica en SEC EDGAR.

Sheet DATOS
B2: USA RARE EARTH (USAR) — HOJA DE DATOS CRUDOS (SEC 10-K / 10-Q). Cifras en millones USD.
B3: Fuente única. Azul = de SEC. Demás hojas jalan con fórmulas. Edita SOLO aquí. Plataforma mina-a-imán de tierras raras (EE.UU.). Pre-rentabilidad en construcción, con balance descomunal (~$1.5B). Salió a bolsa en 2025 (reverse merger). FY = dic.
C5: ANUALES (FY dic) | F5: Q2 (homólogo) | H5: H1 / 6 meses | J5: Balance (cortes)
B6: Concepto ($M) | C6: FY2024 | D6: FY2025 | E6: FY2026e | F6: Q2-25 | G6: Q2-26 | H6: H1-25 | I6: H1-26 | J6: Dic-25 | K6: Jun-26 | L6: Fuente / nota
B7: ESTADO DE RESULTADOS
B8: INGRESOS (metales, vía Less Common Metals) | C8: 0 | D8: 3 | E8: 24 | F8: 0 | G8: 5.82 | H8: 0 | I8: 11.52 | L8: Solo de metales LCM. FY26e anualizado. Aún sin imanes ni mina.
B9: Costo de ventas | C9: 0 | D9: 3.5 | E9: 26 | F9: 0 | G9: 7.4 | H9: 0 | I9: 13 | L9: > ingresos: márgenes negativos al arrancar.
B10: UTILIDAD (PÉRDIDA) BRUTA | C10: 0 | D10: -0.5 | E10: -2 | F10: 0 | G10: -1.58 | H10: 0 | I10: -1.48 | L10: Gross loss: costos de arranque > ventas.
B11: Gastos de ventas, generales y admin | F11: 6.23 | G11: 32.61 | H11: 13.26 | I11: 53.78 | L11: SG&A. Sube fuerte: construir la plataforma.
B12: I+D (R&D) | F12: 2.58 | G12: 10.77 | H12: 4.27 | I12: 25.02 | L12: R&D. Desarrollo del flujo de Round Top.
B13: Gastos operativos totales | F13: 8.8 | G13: 44.73 | H13: 17.52 | I13: 81.51 | L13: Total opex.
B14: PÉRDIDA OPERATIVA | C14: -30 | D14: -60 | E14: -160 | F14: -8.8 | G14: -46.31 | H14: -17.52 | I14: -82.99 | L14: La pérdida "real". FY26e ~anualizado H1. Crece con la inversión.
B15: Ingreso por intereses + dividendos | F15: 0.77 | G15: 14.95 | H15: 0.95 | I15: 26.92 | L15: Sobre la caja (~$1.5B en money markets). AMORTIGUA la pérdida.
B16: Ajuste valor razonable (warrants/earnout) | F16: -134.66 | G16: 22.42 | H16: -74.36 | I16: -21.14 | L16: NO-CAJA. Ruido que infla/desinfla la neta. IGNORAR para el análisis.
B17: PÉRDIDA NETA (a la matriz) | C17: -45 | D17: -90 | E17: -155 | F17: -142.51 | G17: -10.33 | H17: -90.67 | I17: -77.32 | L17: Muy distorsionada por FV. Mirar la OPERATIVA.
B18: Pérdida neta ajustada (no-GAAP) | F18: -19.1 | G18: -33.5 | H18: -28 | I18: -57.6 | L18: Ex partidas no-caja. La cifra "limpia".
B19: EPS (US$) | F19: -1.54 | G19: -0.05 | H19: -0.99 | I19: -0.37 | L19: Diluted EPS.
B20: Acciones en circulación (M) | D20: 148.1 | F20: 92.8 | G20: 230.1 | H20: 91.6 | I20: 213.3 | J20: 148.1 | K20: 244.7 | L20: 244.7M a ago-2026. OJO dilución (Serra Verde +126.8M pendiente).
B21: BALANCE GENERAL (fin de periodo)
B22: Caja + equivalentes | J22: 359.9 | K22: 1530.1 | L22: CLAVE: ~$1.53B tras PIPE $1.5B (ene-2026).
B23: Caja restringida | J23: 0 | K23: 64.2 | L23: Escrow (planta Blacksburg).
B24: Cuentas por cobrar | J24: 3.76 | K24: 6.27 | L24: Accounts receivable.
B25: Inventarios | J25: 18.54 | K25: 50.14 | L25: Materias primas + producto. Sube (arranca producción).
B26: Total activo corriente | J26: 385.4 | K26: 1672.6 | L26: Current assets. Dominado por caja.
B27: Propiedad, planta y equipo neto | J27: 86.4 | K27: 146.8 | L27: PP&E. Plantas Stillwater/Blacksburg. Crece.
B28: Intereses mineros (Round Top) | J28: 17.3 | K28: 17.3 | L28: Derechos mineros Round Top (Texas).
B29: Goodwill + intangibles | J29: 203.5 | K29: 200.7 | L29: De adquisiciones (Less Common Metals).
B30: Costos diferidos de arreglo (CHIPS) | J30: 0 | K30: 912.1 | L30: Contrapartida contable del CHIPS Act (acciones+warrant al gobierno).
B31: TOTAL ACTIVOS | J31: 695 | K31: 2998.8 | L31: Total assets. Salta por PIPE + CHIPS.
B32: Cuentas por pagar y acumulados | J32: 25.1 | K32: 49 | L32: AP + accrued.
B33: Total pasivo corriente | J33: 37.9 | K33: 51 | L33: Current liabilities.
... B39: Deuda financiera real | J39: 1.8 | K39: 0 | L39: Repagó préstamo Barclays. SIN deuda tradicional.
B40: FLUJO DE CAJA (H1 / semestral)
B41: Flujo de caja operativo (H1) | H41: -18.24 | I41: -75.32 | L41: Quema operativa H1: −75M (sube con la escala).
B42: CapEx + depósitos equipo (H1) | H42: -6.3 | I42: -108.39 | L42: Inversión fuerte: construir plantas.
B43: MERCADO Y OPERATIVO (editable)
B44: Precio de la acción (US$) | K44: 17.34 | L44: ACTUALIZAR. ~$17.3 (ago 2026). Rango 52s: $11–44.
B45: Potencial de ingresos (meta, $M) | K45: 750 | L45: Meta declarada: $700–800M con cadena de imanes completa.
B46: CHIPS Act — capacidad total ($M) | K46: 1577 | L46: $277M funding directo + $1,300M garantía préstamos.
B47: SUPUESTOS DE VALORACIÓN (editable)
...

Sheet Estado Resultados
B2: ESTADO DE RESULTADOS — comparación homogénea ($M, jala de DATOS)
B3: Empresa en construcción: casi sin ingresos, pierde dinero. Lo relevante no es la ganancia, sino la tendencia de la pérdida operativa y la quema de caja. La pérdida NETA está distorsionada por ajustes no-caja de warrants.
C5: ANUALES | F5: Q2 (25→26) | I5: H1 (25→26)
B6: Concepto ($M) | C6: FY24 | D6: FY25 | E6: FY26e | F6: Q2 25 | G6: Q2 26 | H6: Δ% | I6: H1 25 | J6: H1 26 | K6: Δ%
B7: Ingresos (metales LCM) | C7: =DATOS!C8 -> 0 | D7: =DATOS!D8 -> 3 | E7: =DATOS!E8 -> 24 | F7: =DATOS!F8 -> 0 | G7: =DATOS!G8 -> 5.82 | H7: =IFERROR((DATOS!G8-DATOS!F8)/ABS(DATOS!F8),"—") -> — | I7: =DATOS!H8 -> 0 | J7: =DATOS!I8 -> 11.52 | K7: =IFERROR((DATOS!I8-DATOS!H8)/ABS(DATOS!H8),"—") -> —
B8: Costo de ventas | C8: =DATOS!C9 -> 0 | D8: =DATOS!D9 -> 3.5 | E8: =DATOS!E9 -> 26 | F8: =DATOS!F9 -> 0 | G8: =DATOS!G9 -> 7.4 | H8: =IFERROR((DATOS!G9-DATOS!F9)/ABS(DATOS!F9),"—") -> — | I8: =DATOS!H9 -> 0 | J8: =DATOS!I9 -> 13 | K8: =IFERROR((DATOS!I9-DATOS!H9)/ABS(DATOS!H9),"—") -> —
B9: Utilidad (pérdida) bruta | C9: =DATOS!C10 -> 0 | D9: =DATOS!D10 -> -0.5 | E9: =DATOS!E10 -> -2 | F9: =DATOS!F10 -> 0 | G9: =DATOS!G10 -> -1.58 | H9: =IFERROR((DATOS!G10-DATOS!F10)/ABS(DATOS!F10),"—") -> — | I9: =DATOS!H10 -> 0 | J9: =DATOS!I10 -> -1.48 | K9: =IFERROR((DATOS!I10-DATOS!H10)/ABS(DATOS!H10),"—") -> —
B10: SG&A | C10: =DATOS!C11 | D10: =DATOS!D11 | E10: =DATOS!E11 | F10: =DATOS!F11 -> 6.23 | G10: =DATOS!G11 -> 32.61 | H10: =IFERROR((DATOS!G11-DATOS!F11)/ABS(DATOS!F11),"—") -> 4.2343499 | I10: =DATOS!H11 -> 13.26 | J10: =DATOS!I11 -> 53.78 | K10: =IFERROR((DATOS!I11-DATOS!H11)/ABS(DATOS!H11),"—") -> 3.0558069
B11: I+D | C11: =DATOS!C12 | D11: =DATOS!D12 | E11: =DATOS!E12 | F11: =DATOS!F12 -> 2.58 | G11: =DATOS!G12 -> 10.77 | H11: =IFERROR((DATOS!G12-DATOS!F12)/ABS(DATOS!F12),"—") -> 3.1744186 | I11: =DATOS!H12 -> 4.27 | J11: =DATOS!I12 -> 25.02 | K11: =IFERROR((DATOS!I12-DATOS!H12)/ABS(DATOS!H12),"—") -> 4.8594848
B12: PÉRDIDA OPERATIVA | C12: =DATOS!C14 -> -30 | D12: =DATOS!D14 -> -60 | E12: =DATOS!E14 -> -160 | F12: =DATOS!F14 -> -8.8 | G12: =DATOS!G14 -> -46.31 | H12: =IFERROR((DATOS!G14-DATOS!F14)/ABS(DATOS!F14),"—") -> -4.2625 | I12: =DATOS!H14 -> -17.52 | J12: =DATOS!I14 -> -82.99 | K12: =IFERROR((DATOS!I14-DATOS!H14)/ABS(DATOS!H14),"—") -> -3.7368721
B13: Ingreso por intereses | C13: =DATOS!C15 | D13: =DATOS!D15 | E13: =DATOS!E15 | F13: =DATOS!F15 -> 0.77 | G13: =DATOS!G15 -> 14.95 | H13: =IFERROR((DATOS!G15-DATOS!F15)/ABS(DATOS!F15),"—") -> 18.415584 | I13: =DATOS!H15 -> 0.95 | J13: =DATOS!I15 -> 26.92 | K13: =IFERROR((DATOS!I15-DATOS!H15)/ABS(DATOS!H15),"—") -> 27.336842
B14: Ajuste valor razonable (no-caja) | C14: =DATOS!C16 | D14: =DATOS!D16 | E14: =DATOS!E16 | F14: =DATOS!F16 -> -134.66 | G14: =DATOS!G16 -> 22.42 | H14: =IFERROR((DATOS!G16-DATOS!F16)/ABS(DATOS!F16),"—") -> 1.1664934 | I14: =DATOS!H16 -> -74.36 | J14: =DATOS!I16 -> -21.14 | K14: =IFERROR((DATOS!I16-DATOS!H16)/ABS(DATOS!H16),"—") -> 0.71570737
B15: PÉRDIDA NETA | C15: =DATOS!C17 -> -45 | D15: =DATOS!D17 -> -90 | E15: =DATOS!E17 -> -155 | F15: =DATOS!F17 -> -142.51 | G15: =DATOS!G17 -> -10.33 | H15: =IFERROR((DATOS!G17-DATOS!F17)/ABS(DATOS!F17),"—") -> 0.92751386 | I15: =DATOS!H17 -> -90.67 | J15: =DATOS!I17 -> -77.32 | K15: =IFERROR((DATOS!I17-DATOS!H17)/ABS(DATOS!H17),"—") -> 0.14723723
B16: Pérdida neta ajustada (no-GAAP) | C16: =DATOS!C18 | D16: =DATOS!D18 | E16: =DATOS!E18 | F16: =DATOS!F18 -> -19.1 | G16: =DATOS!G18 -> -33.5 | H16: =IFERROR((DATOS!G18-DATOS!F18)/ABS(DATOS!F18),"—") -> -0.7539267 | I16: =DATOS!H18 -> -28 | J16: =DATOS!I18 -> -57.6 | K16: =IFERROR((DATOS!I18-DATOS!H18)/ABS(DATOS!H18),"—") -> -1.0571429
B18: Lectura: este estado hay que leerlo como el de una empresa en plena construcción, no como el de un negocio en marcha. Los ingresos son mínimos ($5.8M en el trimestre) y vienen solo de su filial de metales (Less Common Metals); todavía no hay ventas de imanes ni de la mina, que son el verdadero plan. La pérdida operativa crece —de $8.8M a $46.3M en el trimestre— pero eso es esperado y hasta buena señal: refleja que está invirtiendo con fuerza en construir sus plantas y su equipo. Ojo con dos cosas: primero, la pérdida NETA es engañosa porque incluye ajustes contables enormes y no monetarios sobre sus warrants (en un trimestre resta $135M, en otro suma $22M), que no tienen nada que ver con la operación; por eso conviene mirar la pérdida OPERATIVA o la ajustada. Y segundo, el ingreso por intereses ya es relevante ($15M en el trimestre) porque su colchón de caja de $1.5B genera rendimiento, lo que amortigua parte de la quema.

Sheet Balance
B2: BALANCE GENERAL — dic25 → jun26 (Q2) ($M)
B3: Dos cortes que muestran la transformación por el PIPE de $1.5B (ene-2026) y el CHIPS Act. El balance es la mayor fortaleza. Verde = de DATOS.
B5: Partida ($M) | C5: Dic-25 | D5: Jun-26 | E5: Comentario
B6: ACTIVOS
B7: Caja + equivalentes | C7: =DATOS!J22 -> 359.9 | D7: =DATOS!K22 -> 1530.1 | E7: CLAVE: ~$1.53B tras PIPE. El gran colchón.
B8: Caja restringida | C8: =DATOS!J23 -> 0 | D8: =DATOS!K23 -> 64.2 | E8: Escrow planta Blacksburg.
B9: Inventarios | C9: =DATOS!J25 -> 18.54 | D9: =DATOS!K25 -> 50.14 | E9: Sube: arranca producción.
B10: Total activo corriente | C10: =DATOS!J26 -> 385.4 | D10: =DATOS!K26 -> 1672.6
B11: Propiedad, planta y equipo | C11: =DATOS!J27 -> 86.4 | D11: =DATOS!K27 -> 146.8 | E11: Plantas Stillwater/Blacksburg. Crece.
B12: Intereses mineros (Round Top) | C12: =DATOS!J28 -> 17.3 | D12: =DATOS!K28 -> 17.3 | E12: Derechos del depósito de Texas.
B13: Goodwill + intangibles | C13: =DATOS!J29 -> 203.5 | D13: =DATOS!K29 -> 200.7 | E13: De adquisiciones (LCM).
B14: Costos diferidos CHIPS Act | C14: =DATOS!J30 -> 0 | D14: =DATOS!K30 -> 912.1 | E14: Contrapartida del respaldo gobierno (no-caja).
B15: TOTAL ACTIVOS | C15: =DATOS!J31 -> 695 | D15: =DATOS!K31 -> 2998.8
B16: PASIVOS Y PATRIMONIO
B17: Cuentas por pagar y acumulados | C17: =DATOS!J32 -> 25.1 | D17: =DATOS!K32 -> 49
B18: Pasivo por warrants (no-caja) | C18: =DATOS!J34 -> 19.5 | D18: =DATOS!K34 -> 364.2 | E18: NO es deuda real: se liquida en acciones.
B19: TOTAL PASIVOS | C19: =DATOS!J35 -> 191.8 | D19: =DATOS!K35 -> 451.5
B20: Deuda financiera real | C20: =DATOS!J39 -> 1.8 | D20: =DATOS!K39 -> 0 | E20: Repagó Barclays. SIN deuda tradicional.
B21: PATRIMONIO (total) | C21: =DATOS!J38 -> 494.3 | D21: =DATOS!K38 -> 2537 | E21: Enorme tras el PIPE.
B23: MÉTRICAS DE UNA EMPRESA EN DESARROLLO
B24: Caja neta de deuda ($M) | C24: =IFERROR(DATOS!J22-DATOS!J39,"n/d") -> 358.1 | D24: =IFERROR(DATOS!K22-DATOS!K39,"n/d") -> 1530.1 | E24: Prácticamente igual a la caja: no tiene deuda.
B25: Caja por acción ($) | C25: =IFERROR(DATOS!J22/DATOS!J20,"n/d") -> 2.4301148 | D25: =IFERROR(DATOS!K22/DATOS!K20,"n/d") -> 6.2529628 | E25: Buena parte del precio está respaldada por caja pura.
B26: Razón corriente | C26: =IFERROR(DATOS!J26/DATOS!J33,"n/d") -> 10.168865 | D26: =IFERROR(DATOS!K26/DATOS!K33,"n/d") -> 32.796078 | E26: Altísima: cero problemas de liquidez.
B27: Patrimonio / Activos | C27: =IFERROR(DATOS!J38/DATOS!J31,"n/d") -> 0.71122302 | D27: =IFERROR(DATOS!K38/DATOS!K31,"n/d") -> 0.84600507 | E27: Muy alto: financiada con capital, no deuda.
B29: Lectura: el balance de USA Rare Earth es, con diferencia, su mayor fortaleza — y lo que la distingue de casi cualquier otra empresa junior de su sector. En enero de 2026 levantó $1,500M en una colocación privada (PIPE), lo que la dejó con ~$1.53B en caja y prácticamente sin deuda tras repagar su único préstamo. Para una empresa que aún no genera ingresos significativos, tener más de mil quinientos millones en el banco es un lujo: le da años de pista para construir su mina y sus plantas de imanes sin verse obligada a levantar capital con urgencia. A eso se suma el respaldo del gobierno vía el CHIPS Act (hasta $1.6B en fondos y garantías), que aparece en el balance como "costos diferidos" y "pasivo por warrants" —partidas contables que no son deuda real que haya que pagar en efectivo—. En resumen: un cofre de guerra enorme para financiar una ambición enorme.

Sheet Análisis Financiero
B2: ANÁLISIS FINANCIERO — adaptado a una empresa en construcción
B3: Los ratios de rentabilidad no aplican (aún pierde). El foco: solidez del balance, pista de liquidez (runway) y quema de caja. Metodología Celsia adaptada al caso de opción.
B5: Indicador | C5: Dic-2025 | D5: Jun-2026 | E5: Interpretación
B6: 1 · SOLIDEZ DEL BALANCE (lo más importante aquí)
B7: Caja + equivalentes ($M) | C7: =DATOS!J22 -> 359.9 | D7: =DATOS!K22 -> 1530.1 | E7: El colchón. ~$1.53B: enorme para su tamaño.
B8: Caja neta de deuda ($M) | C8: =DATOS!J22-DATOS!J39 -> 358.1 | D8: =DATOS!K22-DATOS!K39 -> 1530.1 | E8: Sin deuda real: la caja es casi toda neta.
B9: Razón corriente | C9: =IFERROR(DATOS!J26/DATOS!J33,"n/d") -> 10.168865 | D9: =IFERROR(DATOS!K26/DATOS!K33,"n/d") -> 32.796078 | E9: Liquidez de corto plazo. Extremadamente holgada.
B10: Patrimonio / Activos | C10: =IFERROR(DATOS!J38/DATOS!J31,"n/d") -> 0.71122302 | D10: =IFERROR(DATOS!K38/DATOS!K31,"n/d") -> 0.84600507 | E10: Financiada con capital, no deuda.
B11: 2 · QUEMA DE CAJA Y PISTA (RUNWAY)
B12: Quema operativa semestral ($M) | C12: "n/d" | D12: =-DATOS!I41 -> 75.32 | E12: H1-26: −$75M. Sube con la construcción.
B13: Inversión en plantas — CapEx H1 ($M) | C13: "n/d" | D13: =-DATOS!I42 -> 108.39 | E13: H1-26: −$108M. Construyendo capacidad.
B14: Pista de liquidez (años, aprox) | C14: "n/d" | D14: =DATOS!K22/((-DATOS!I41-DATOS!I42)*2) -> 4.164444 | E14: Caja ÷ quema anualizada. Varios años de pista aun invirtiendo fuerte.
B15: 3 · RESPALDO Y ESCALA
B16: Respaldo CHIPS Act ($M) | C16: =DATOS!K46 -> 1577 | D16: =DATOS!K46 -> 1577 | E16: Hasta $1.6B en fondos y garantías del gobierno.
B17: Potencial de ingresos declarado ($M) | C17: =DATOS!K45 -> 750 | D17: =DATOS!K45 -> 750 | E17: Meta: $700–800M con la cadena de imanes completa.
B18: Caja / Pérdida operativa anualizada | C18: "n/d" | D18: =IFERROR(DATOS!K22/(-DATOS!I14*2),"n/d") -> 9.2185806 | E18: Cuántos años de pérdida operativa cubre la caja. Muy alto.
B19: 4 · VALORACIÓN DE MERCADO
B20: Capitalización de mercado ($M) | C20: "n/d" | D20: =DATOS!K44*DATOS!K20 -> 4243.098 | E20: Precio × acciones.
B21: Caja como % del market cap | C21: "n/d" | D21: =IFERROR(DATOS!K22/(DATOS!K44*DATOS!K20),"n/d") -> 0.36060916 | E21: Qué parte del precio es caja pura. El resto es la "opción".
B23: Diagnóstico: como toda empresa en construcción, a USA Rare Earth se le juzga por su capacidad de aguantar el tiempo que tarda en producir, no por lo que gana hoy. Y en ese frente está excepcionalmente bien: su cofre de $1.53B, sin deuda, le da varios años de pista incluso al ritmo agresivo de gasto actual (quema operativa de ~$75M por semestre más ~$108M de inversión en plantas). Encima cuenta con el respaldo del CHIPS Act, que puede aportar hasta $1.6B adicionales en fondos y garantías. Una parte relevante de su precio de bolsa está literalmente respaldada por la caja que tiene en el banco; el resto es lo que el mercado paga por la "opción" de que logre construir la única cadena mina-a-imán integrada de EE.UU. El riesgo no es quedarse sin dinero a corto plazo —eso está cubierto— sino de ejecución (construir a tiempo y a costo) y de dilución (las adquisiciones como Serra Verde emiten muchas acciones nuevas).

Sheet Proyecciones
B2: MODELO DE TRES ESTADOS PROYECTADOS Y ENLAZADOS (5 años) — USA Rare Earth
B3: Empresa en construcción: parte de ingresos mínimos y pérdidas grandes. El margen (driver) cruza a positivo TARDE (año 4), cuando la planta de imanes y la mina escalan. La caja de ~$1.53B financia el camino. DESCUADRE verifica el cuadre (=0).
B6: Concepto ($M) | C6: Base FY26e | D6: Año 1 | E6: Año 2 | F6: Año 3 | G6: Año 4 | H6: Año 5 | I6: Notas / enlace
B7: 1 · ESTADO DE RESULTADOS
B8: Ingresos | C8: =DATOS!$K$64 -> 24 | D8: =C8*(1+DATOS!$K$65) -> 60 | E8: =D8*(1+DATOS!$K$66) -> 138 | F8: =E8*(1+DATOS!$K$67) -> 276 | G8: =F8*(1+DATOS!$K$68) -> 469.2 | H8: =G8*(1+DATOS!$K$69) -> 680.34 | I8: Rampa mina-a-imán hacia la meta de $700-800M.
B9: Crecimiento % | D9: =D8/C8-1 -> 1.5 | E9: =E8/D8-1 -> 1.3 | F9: =F8/E8-1 -> 1 | G9: =G8/F8-1 -> 0.7 | H9: =H8/G8-1 -> 0.45
B10: Ingreso operativo (EBIT) | D10: =D8*DATOS!$K$70 -> -120 | E10: =E8*DATOS!$K$71 -> -110.4 | F10: =F8*DATOS!$K$72 -> -55.2 | G10: =G8*DATOS!$K$73 -> 56.304 | H10: =H8*DATOS!$K$74 -> 170.085 | I10: Ventas × margen EBIT (negativo hasta año 4).
B11: Margen EBIT % | D11: =DATOS!$K$70 -> -2 | E11: =DATOS!$K$71 -> -0.8 | F11: =DATOS!$K$72 -> -0.2 | G11: =DATOS!$K$73 -> 0.12 | H11: =DATOS!$K$74 -> 0.25 | I11: De −200% a +25%. Cruza a positivo en el año 4.
B12: (+) Ingreso por intereses (caja) | D12: =C18*DATOS!$K$79 -> 53.5535 | E12: =D18*DATOS!$K$79 -> 50.450873 | F12: =E18*DATOS!$K$79 -> 46.590753 | G12: =F18*DATOS!$K$79 -> 42.860129 | H12: =G18*DATOS!$K$79 -> 39.989558 | I12: ~3.5% sobre la caja. Amortigua las pérdidas.
B13: Utilidad antes de impuestos | D13: =D10+D12 -> -66.4465 | E13: =E10+E12 -> -59.949128 | F13: =F10+F12 -> -8.609247 | G13: =G10+G12 -> 99.164129 | H13: =H10+H12 -> 210.07456
B14: (−) Impuestos | D14: =MAX(0,D13)*DATOS!K51 -> 0 | E14: =MAX(0,E13)*DATOS!K51 -> 0 | F14: =MAX(0,F13)*DATOS!K51 -> 0 | G14: =MAX(0,G13)*DATOS!K51 -> 20.824467 | H14: =MAX(0,H13)*DATOS!K51 -> 44.115657 | I14: Solo si hay utilidad.
B15: UTILIDAD (PÉRDIDA) NETA | D15: =D13-D14 -> -66.4465 | E15: =E13-E14 -> -59.949128 | F15: =F13-F14 -> -8.609247 | G15: =G13-G14 -> 78.339662 | H15: =H13-H14 -> 165.9589
B17: 2 · BALANCE GENERAL
B18: Caja + inversiones | C18: =DATOS!K22 -> 1530.1 | D18: =D39 -> 1441.4535 | E18: =E39 -> 1331.1644 | F18: =F39 -> 1224.5751 | G18: =G39 -> 1142.5588 | H18: =H39 -> 1086.3515 | I18: ← Caja final del Flujo. El colchón que financia todo.
B19: Cuentas por cobrar | C19: =DATOS!K24 -> 6.27 | D19: =D8*(DATOS!K24/DATOS!$K$64) -> 15.675 | E19: =E8*(DATOS!K24/DATOS!$K$64) -> 36.0525 | F19: =F8*(DATOS!K24/DATOS!$K$64) -> 72.105 | G19: =G8*(DATOS!K24/DATOS!$K$64) -> 122.5785 | H19: =H8*(DATOS!K24/DATOS!$K$64) -> 177.73882 | I19: Ratio CxC/ventas.
B20: Inventarios | C20: =DATOS!K25 -> 50.14 | D20: =D8*(DATOS!K25/DATOS!$K$64) -> 125.35 | E20: =E8*(DATOS!K25/DATOS!$K$64) -> 288.305 | F20: =F8*(DATOS!K25/DATOS!$K$64) -> 576.61 | G20: =G8*(DATOS!K25/DATOS!$K$64) -> 980.237 | H20: =H8*(DATOS!K25/DATOS!$K$64) -> 1421.3437 | I20: Ratio inventario/ventas.
B21: PP&E neto (plantas + mina) | C21: =DATOS!K27+DATOS!K28 -> 164.1 | D21: =C21+D8*DATOS!$K$77-D8*DATOS!$K$76 -> 180.9 | E21: =D21+E8*DATOS!$K$77-E8*DATOS!$K$76 -> 219.54 | F21: =E21+F8*DATOS!$K$77-F8*DATOS!$K$76 -> 296.82 | G21: =F21+G8*DATOS!$K$77-G8*DATOS!$K$76 -> 428.196 | H21: =G21+H8*DATOS!$K$77-H8*DATOS!$K$76 -> 618.6912 | I21: + CapEx − depreciación. Construye mina + plantas.
B22: Otros activos (CHIPS, goodwill, resto) | C22: =DATOS!K31-DATOS!K22-DATOS!K24-DATOS!K25-DATOS!K27-DATOS!K28 -> 1248.19 | D22: =C22 -> 1248.19 | E22: =D22 -> 1248.19 | F22: =E22 -> 1248.19 | G22: =F22 -> 1248.19 | H22: =G22 -> 1248.19 | I22: Costos diferidos CHIPS + goodwill, constante.
B23: TOTAL ACTIVOS | C23: =C18+C19+C20+C21+C22 -> 2998.8 | D23: =D18+D19+D20+D21+D22 -> 3011.5685 | E23: =E18+E19+E20+E21+E22 -> 3123.2519 | F23: =F18+F19+F20+F21+F22 -> 3418.3001 | G23: =G18+G19+G20+G21+G22 -> 3921.7603 | H23: =H18+H19+H20+H21+H22 -> 4552.3152
B24: Pasivos operativos + warrants | C24: =DATOS!K35-DATOS!K39 -> 451.5 | D24: =DATOS!K35-DATOS!K39 -> 451.5 | E24: =DATOS!K35-DATOS!K39 -> 451.5 | F24: =DATOS!K35-DATOS!K39 -> 451.5 | G24: =DATOS!K35-DATOS!K39 -> 451.5 | H24: =DATOS!K35-DATOS!K39 -> 451.5 | I24: Warrants no-caja + operativos, ~constante.
B25: Deuda (plug de cuadre) | C25: =DATOS!K39 -> 0 | D25: =D23-D24-D27 -> 89.515 | E25: =E23-E24-E27 -> 261.1475 | F25: =F23-F24-F27 -> 564.805 | G25: =G23-G24-G27 -> 989.9255 | H25: =H23-H24-H27 -> 1454.5215 | I25: PLUG: cuadra el balance. Positivo=necesita financiar.
B26: TOTAL PASIVOS | C26: =C24+C25 -> 451.5 | D26: =D24+D25 -> 541.015 | E26: =E24+E25 -> 712.6475 | F26: =F24+F25 -> 1016.305 | G26: =G24+G25 -> 1441.4255 | H26: =H24+H25 -> 1906.0215
B27: PATRIMONIO | C27: =DATOS!K38 -> 2537 | D27: =C27+D15 -> 2470.5535 | E27: =D27+E15 -> 2410.6044 | F27: =E27+F15 -> 2401.9951 | G27: =F27+G15 -> 2480.3348 | H27: =G27+H15 -> 2646.2937 | I27: Previo + utilidad (o − pérdida).
B28: TOTAL PASIVO + PATRIMONIO | C28: =C26+C27 -> 2988.5 | D28: =D26+D27 -> 3011.5685 | E28: =E26+E27 -> 3123.2519 | F28: =F26+F27 -> 3418.3001 | G28: =G26+G27 -> 3921.7603 | H28: =H26+H27 -> 4552.3152
B29: DESCUADRE (Activo − Pas − Patr) | C29: =C23-C28 -> 10.3 | D29: =D23-D28 -> 0 | E29: =E23-E28 -> 0 | F29: =F23-F28 -> 0 | G29: =G23-G28 -> 0 | H29: =H23-H28 -> 0 | I29: DEBE SER 0.
B31: 3 · FLUJO DE CAJA
B32: Utilidad (pérdida) neta | D32: =D15 -> -66.4465 | E32: =E15 -> -59.949128 | F32: =F15 -> -8.609247 | G32: =G15 -> 78.339662 | H32: =H15 -> 165.9589 | I32: ← Resultados.
B33: (+) Depreciación | D33: =D8*DATOS!$K$76 -> 7.2 | E33: =E8*DATOS!$K$76 -> 16.56 | F33: =F8*DATOS!$K$76 -> 33.12 | G33: =G8*DATOS!$K$76 -> 56.304 | H33: =H8*DATOS!$K$76 -> 81.6408 | I33: No-caja.
B34: (−) Δ Capital de trabajo | D34: =-(D8-C8)*DATOS!$K$78 -> -5.4 | E34: =-(E8-D8)*DATOS!$K$78 -> -11.7 | F34: =-(F8-E8)*DATOS!$K$78 -> -20.7 | G34: =-(G8-F8)*DATOS!$K$78 -> -28.98 | H34: =-(H8-G8)*DATOS!$K$78 -> -31.671 | I34: Sobre crecimiento de ventas.
B35: Flujo de caja operativo | D35: =D32+D33+D34 -> -64.6465 | E35: =E32+E33+E34 -> -55.089127 | F35: =F32+F33+F34 -> 3.810753 | G35: =G32+G33+G34 -> 105.66366 | H35: =H32+H33+H34 -> 215.9287
B36: (−) CapEx | D36: =-D8*DATOS!$K$77 -> -24 | E36: =-E8*DATOS!$K$77 -> -55.2 | F36: =-F8*DATOS!$K$77 -> -110.4 | G36: =-G8*DATOS!$K$77 -> -187.68 | H36: =-H8*DATOS!$K$77 -> -272.136 | I36: % de ventas (construye mina + plantas).
B37: Flujo de caja libre (FCF) | D37: =D35+D36 -> -88.6465 | E37: =E35+E36 -> -110.28913 | F37: =F35+F36 -> -106.58925 | G37: =G35+G36 -> -82.016338 | H37: =H35+H36 -> -56.2073 | I37: OCF − CapEx. Alimenta el DCF. Negativo los primeros años.
B38: Caja inicial | D38: =DATOS!K22 -> 1530.1 | E38: =D39 -> 1441.4535 | F38: =E39 -> 1331.1644 | G38: =F39 -> 1224.5751 | H38: =G39 -> 1142.5588
B39: Caja final | D39: =D38+D37 -> 1441.4535 | E39: =E38+E37 -> 1331.1644 | F39: =F38+F37 -> 1224.5751 | G39: =G38+G37 -> 1142.5588 | H39: =H38+H37 -> 1086.3515 | I39: → Caja del Balance. El colchón financia la construcción.
B41: Cómo leerlo: esta es una proyección de "opción a gran escala". USA Rare Earth parte de ingresos mínimos (solo metales) y una pérdida grande, pero el modelo traza la rampa hacia su meta declarada de $700-800M en ingresos cuando la cadena mina-a-imán esté completa. El margen sigue negativo los primeros años —normal en un proyecto que construye mina y plantas a la vez— y cruza a positivo alrededor del año 4. La protagonista es la caja de ~$1.53B: financia las pérdidas y el fortísimo CapEx sin necesidad de deuda ni de diluir con urgencia. El FCF es muy negativo al inicio (está invirtiendo miles de millones en construir) y se vuelve positivo al madurar. Todo cuadra (Descuadre=0). La gran incógnita, igual que en cualquier proyecto de construcción: esta senda supone que la mina y la planta de imanes se terminan a tiempo y a costo; si hay retrasos, se consume más caja y el cruce a rentabilidad se corre.

Sheet Valoración
B2: VALORACIÓN — WACC (CAPM) · DCF real · NAV (valor de activos)
B3: Empresa de opción a gran escala: el DCF valora el negocio si la rampa mina-a-imán funciona; el NAV pone un piso con la caja descomunal. Amarillo=editable.
B5: 1 · COSTO DE CAPITAL (WACC vía CAPM)
B6: Tasa libre de riesgo (Rf) | C6: =DATOS!K48 -> 0.043 | E6: De DATOS.
B7: Prima de riesgo (ERP) | C7: =DATOS!K49 -> 0.055 | E7: De DATOS.
B8: Beta desapalancado (βu) | C8: =DATOS!K50 -> 1.7 | E8: Pre-rentabilidad, minero+manufactura. Alto. De DATOS.
B9: Valor de mercado del equity ($M) | C9: =DATOS!K44*DATOS!K20 -> 4243.098 | E9: Precio × ~244.7M acciones.
B10: Valor de la deuda ($M) | C10: =MAX(DATOS!K39,1) -> 1 | E10: Sin deuda real (mínimo 1 para el cálculo).
B11: Peso deuda D/(D+E) | C11: =C10/(C10+C9) -> 0.00023562133
B12: Peso equity E/(D+E) | C12: =C9/(C10+C9) -> 0.99976438
B13: Tasa impositiva (t) | C13: =DATOS!K51 -> 0.21
B14: Beta apalancado (βL, Hamada) | C14: =C8*(1+(1-C13)*C10/C9) -> 1.7003165 | E14: βu×(1+(1−t)×D/E). ~=βu: sin deuda.
B15: Costo del equity (Ke=CAPM) | C15: =C6+C14*C7 -> 0.13651741 | E15: Rf+βL×ERP.
B16: Costo de la deuda (Kd) | C16: =DATOS!K52 -> 0.06
B17: WACC | C17: =C12*C15+C11*C16*(1-C13) -> 0.13649641 | E17: We×Ke+Wd×Kd(1−t). Alto: empresa de riesgo, casi todo equity.
B19: 2 · DCF — Flujo de Caja Libre proyectado
B20: Año | C20: FCF ($M) | D20: VP ($M) | E20: FCF de Proyecciones. Negativo al inicio (invierte en construir).
B21: 1 | C21: =Proyecciones!D37 -> -88.6465 | D21: =C21/(1+C17)^1 -> -77.999806
B22: 2 | C22: =Proyecciones!E37 -> -110.28913 | D22: =C22/(1+C17)^2 -> -85.387946
B23: 3 | C23: =Proyecciones!F37 -> -106.58925 | D23: =C23/(1+C17)^3 -> -72.612132
B24: 4 | C24: =Proyecciones!G37 -> -82.016338 | D24: =C24/(1+C17)^4 -> -49.161837
B25: 5 | C25: =Proyecciones!H37 -> -56.2073 | D25: =C25/(1+C17)^5 -> -29.645063
B26: FCF terminal normalizado ($M) | C26: =Proyecciones!H8*DATOS!K53*(1-DATOS!K51) -> 134.36715 | E26: Ventas año5 × margen EBIT terminal × (1−t). Normaliza el CapEx de construcción.
B27: Valor terminal (Gordon, g=4%) | C27: =C26*(1.04)/(C17-0.04) -> 1448.1558 | D27: =C27/(1+C17)^5 -> 763.79172 | E27: g perpetuo 4% (tierras raras: demanda estructural creciente).
B28: Valor empresa (EV) ($M) | C28: =SUM(D21:D25)+D27 -> 448.98494
B29: (+) Caja − deuda ($M) | C29: =DATOS!K22+DATOS!K23-DATOS!K39 -> 1594.3 | E29: Puente EV→equity. El colchón de $1.5B se suma.
B30: Valor del patrimonio — DCF ($M) | C30: =C28+C29 -> 2043.2849
B31: Valor intrínseco por acción — DCF ($) | C31: =C30/DATOS!K20 -> 8.3501632
B33: 3 · NAV — valor de activos (piso de valor)
B34: Caja + equivalentes + restringida ($M) | C34: =DATOS!K22+DATOS!K23 -> 1594.3 | E34: El activo más líquido y cierto (~$1.6B).
B35: (+) Plantas + mina + inventario ($M) | C35: =DATOS!K27+DATOS!K28+DATOS!K25 -> 214.24 | E35: PP&E + Round Top + inventarios.
B36: (+) Goodwill + intangibles ($M) | C36: =DATOS!K29 -> 200.7 | E36: De adquisiciones (Less Common Metals).
B37: (−) Pasivos reales (ex warrants no-caja) ($M) | C37: =-(DATOS!K35-DATOS!K34) -> -87.3 | E37: Excluye warrants (se liquidan en acciones, no en caja).
B38: NAV total ($M) | C38: =DATOS!K22+DATOS!K23+DATOS!K27+DATOS!K28+DATOS!K25+DATOS!K29-(DATOS!K35-DATOS!K34) -> 1921.94
B39: NAV por acción ($) | C39: =C38/DATOS!K20 -> 7.8542705
B41: 4 · SÍNTESIS
B42: Valor por acción — DCF ($) | C42: =C31 -> 8.3501632 | E42: Escenario en que la rampa mina-a-imán funciona.
B43: Valor por acción — NAV ($) | C43: =C39 -> 7.8542705 | E43: Piso: lo que valen sus activos hoy (casi todo caja).
B44: Precio de mercado ($) | C44: =DATOS!K44 -> 17.34
B45: Margen de seguridad (vs DCF / vs NAV) | C45: =C31/DATOS!K44-1 -> -0.51844503 | D45: =C39/DATOS!K44-1 -> -0.54704322 | E45: Positivo = infravalorada por ese método.
...

Sheet Sensibilidad
B2: ANÁLISIS DE SENSIBILIDAD — Valor por acción (DCF)
B3: WACC (filas) × margen EBIT terminal (columnas). En una empresa de opción, ambos definen si la apuesta paga. Rango amplio = alta incertidumbre.
B5: WACC \ margen term. | C5: 0.15 | D5: 0.2 | E5: 0.25 | F5: 0.3 | G5: 0.35
B6: 0.1 | C6: =((Proyecciones!D37/(1+$B6)^1+Proyecciones!E37/(1+$B6)^2+Proyecciones!F37/(1+$B6)^3+Proyecciones!G37/(1+$B6)^4+Proyecciones!H37/(1+$B6)^5+(Proyecciones!H8*C$5*(1-DATOS!K51)*1.04/($B6-0.04))/(1+$B6)^5)+(DATOS!K22+DATOS!K23-DATOS!K39))/DATOS!K20 -> 8.6606066 | D6: =((Proyecciones!D37/(1+$B6)^1+Proyecciones!E37/(1+$B6)^2+Proyecciones!F37/(1+$B6)^3+Proyecciones!G37/(1+$B6)^4+Proyecciones!H37/(1+$B6)^5+(Proyecciones!H8*D$5*(1-DATOS!K51)*1.04/($B6-0.04))/(1+$B6)^5)+(DATOS!K22+DATOS!K23-DATOS!K39))/DATOS!K20 -> 9.8425803 | E6: =((Proyecciones!D37/(1+$B6)^1+Proyecciones!E37/(1+$B6)^2+Proyecciones!F37/(1+$B6)^3+Proyecciones!G37/(1+$B6)^4+Proyecciones!H37/(1+$B6)^5+(Proyecciones!H8*E$5*(1-DATOS!K51)*1.04/($B6-0.04))/(1+$B6)^5)+(DATOS!K22+DATOS!K23-DATOS!K39))/DATOS!K20 -> 11.024554 | F6: =((Proyecciones!D37/(1+$B6)^1+Proyecciones!E37/(1+$B6)^2+Proyecciones!F37/(1+$B6)^3+Proyecciones!G37/(1+$B6)^4+Proyecciones!H37/(1+$B6)^5+(Proyecciones!H8*F$5*(1-DATOS!K51)*1.04/($B6-0.04))/(1+$B6)^5)+(DATOS!K22+DATOS!K23-DATOS!K39))/DATOS!K20 -> 12.206528 | G6: =((Proyecciones!D37/(1+$B6)^1+Proyecciones!E37/(1+$B6)^2+Proyecciones!F37/(1+$B6)^3+Proyecciones!G37/(1+$B6)^4+Proyecciones!H37/(1+$B6)^5+(Proyecciones!H8*G$5*(1-DATOS!K51)*1.04/($B6-0.04))/(1+$B6)^5)+(DATOS!K22+DATOS!K23-DATOS!K39))/DATOS!K20 -> 13.388501
B7: 0.115 | C7: =((Proyecciones!D37/(1+$B7)^1+Proyecciones!E37/(1+$B7)^2+Proyecciones!F37/(1+$B7)^3+Proyecciones!G37/(1+$B7)^4+Proyecciones!H37/(1+$B7)^5+(Proyecciones!H8*C$5*(1-DATOS!K51)*1.04/($B7-0.04))/(1+$B7)^5)+(DATOS!K22+DATOS!K23-DATOS!K39))/DATOS!K20 -> 7.8145037 | D7: =((Proyecciones!D37/(1+$B7)^1+Proyecciones!E37/(1+$B7)^2+Proyecciones!F37/(1+$B7)^3+Proyecciones!G37/(1+$B7)^4+Proyecciones!H37/(1+$B7)^5+(Proyecciones!H8*D$5*(1-DATOS!K51)*1.04/($B7-0.04))/(1+$B7)^5)+(DATOS!K22+DATOS!K23-DATOS!K39))/DATOS!K20 -> 8.6981671 | E7: =((Proyecciones!D37/(1+$B7)^1+Proyecciones!E37/(1+$B7)^2+Proyecciones!F37/(1+$B7)^3+Proyecciones!G37/(1+$B7)^4+Proyecciones!H37/(1+$B7)^5+(Proyecciones!H8*E$5*(1-DATOS!K51)*1.04/($B7-0.04))/(1+$B7)^5)+(DATOS!K22+DATOS!K23-DATOS!K39))/DATOS!K20 -> 9.5818305 | F7: =((Proyecciones!D37/(1+$B7)^1+Proyecciones!E37/(1+$B7)^2+Proyecciones!F37/(1+$B7)^3+Proyecciones!G37/(1+$B7)^4+Proyecciones!H37/(1+$B7)^5+(Proyecciones!H8*F$5*(1-DATOS!K51)*1.04/($B7-0.04))/(1+$B7)^5)+(DATOS!K22+DATOS!K23-DATOS!K39))/DATOS!K20 -> 10.465494 | G7: =((Proyecciones!D37/(1+$B7)^1+Proyecciones!E37/(1+$B7)^2+Proyecciones!F37/(1+$B7)^3+Proyecciones!G37/(1+$B7)^4+Proyecciones!H37/(1+$B7)^5+(Proyecciones!H8*G$5*(1-DATOS!K51)*1.04/($B7-0.04))/(1+$B7)^5)+(DATOS!K22+DATOS!K23-DATOS!K39))/DATOS!K20 -> 11.349157
B8: 0.13 | C8: =((Proyecciones!D37/(1+$B8)^1+Proyecciones!E37/(1+$B8)^2+Proyecciones!F37/(1+$B8)^3+Proyecciones!G37/(1+$B8)^4+Proyecciones!H37/(1+$B8)^5+(Proyecciones!H8*C$5*(1-DATOS!K51)*1.04/($B8-0.04))/(1+$B8)^5)+(DATOS!K22+DATOS!K23-DATOS!K39))/DATOS!K20 -> 7.2760118 | D8: =((Proyecciones!D37/(1+$B8)^1+Proyecciones!E37/(1+$B8)^2+Proyecciones!F37/(1+$B8)^3+Proyecciones!G37/(1+$B8)^4+Proyecciones!H37/(1+$B8)^5+(Proyecciones!H8*D$5*(1-DATOS!K51)*1.04/($B8-0.04))/(1+$B8)^5)+(DATOS!K22+DATOS!K23-DATOS!K39))/DATOS!K20 -> 7.9648032 | E8: =((Proyecciones!D37/(1+$B8)^1+Proyecciones!E37/(1+$B8)^2+Proyecciones!F37/(1+$B8)^3+Proyecciones!G37/(1+$B8)^4+Proyecciones!H37/(1+$B8)^5+(Proyecciones!H8*E$5*(1-DATOS!K51)*1.04/($B8-0.04))/(1+$B8)^5)+(DATOS!K22+DATOS!K23-DATOS!K39))/DATOS!K20 -> 8.6535947 | F8: =((Proyecciones!D37/(1+$B8)^1+Proyecciones!E37/(1+$B8)^2+Proyecciones!F37/(1+$B8)^3+Proyecciones!G37/(1+$B8)^4+Proyecciones!H37/(1+$B8)^5+(Proyecciones!H8*F$5*(1-DATOS!K51)*1.04/($B8-0.04))/(1+$B8)^5)+(DATOS!K22+DATOS!K23-DATOS!K39))/DATOS!K20 -> 9.3423861 | G8: =((Proyecciones!D37/(1+$B8)^1+Proyecciones!E37/(1+$B8)^2+Proyecciones!F37/(1+$B8)^3+Proyecciones!G37/(1+$B8)^4+Proyecciones!H37/(1+$B8)^5+(Proyecciones!H8*G$5*(1-DATOS!K51)*1.04/($B8-0.04))/(1+$B8)^5)+(DATOS!K22+DATOS!K23-DATOS!K39))/DATOS!K20 -> 10.031178
B9: 0.145 | C9: =((Proyecciones!D37/(1+$B9)^1+Proyecciones!E37/(1+$B9)^2+Proyecciones!F37/(1+$B9)^3+Proyecciones!G37/(1+$B9)^4+Proyecciones!H37/(1+$B9)^5+(Proyecciones!H8*C$5*(1-DATOS!K51)*1.04/($B9-0.04))/(1+$B9)^5)+(DATOS!K22+DATOS!K23-DATOS!K39))/DATOS!K20 -> 6.9114142 | D9: =((Proyecciones!D37/(1+$B9)^1+Proyecciones!E37/(1+$B9)^2+Proyecciones!F37/(1+$B9)^3+Proyecciones!G37/(1+$B9)^4+Proyecciones!H37/(1+$B9)^5+(Proyecciones!H8*D$5*(1-DATOS!K51)*1.04/($B9-0.04))/(1+$B9)^5)+(DATOS!K22+DATOS!K23-DATOS!K39))/DATOS!K20 -> 7.4641349 | E9: =((Proyecciones!D37/(1+$B9)^1+Proyecciones!E37/(1+$B9)^2+Proyecciones!F37/(1+$B9)^3+Proyecciones!G37/(1+$B9)^4+Proyecciones!H37/(1+$B9)^5+(Proyecciones!H8*E$5*(1-DATOS!K51)*1.04/($B9-0.04))/(1+$B9)^5)+(DATOS!K22+DATOS!K23-DATOS!K39))/DATOS!K20 -> 8.0168556 | F9: =((Proyecciones!D37/(1+$B9)^1+Proyecciones!E37/(1+$B9)^2+Proyecciones!F37/(1+$B9)^3+Proyecciones!G37/(1+$B9)^4+Proyecciones!H37/(1+$B9)^5+(Proyecciones!H8*F$5*(1-DATOS!K51)*1.04/($B9-0.04))/(1+$B9)^5)+(DATOS!K22+DATOS!K23-DATOS!K39))/DATOS!K20 -> 8.5695763 | G9: =((Proyecciones!D37/(1+$B9)^1+Proyecciones!E37/(1+$B9)^2+Proyecciones!F37/(1+$B9)^3+Proyecciones!G37/(1+$B9)^4+Proyecciones!H37/(1+$B9)^5+(Proyecciones!H8*G$5*(1-DATOS!K51)*1.04/($B9-0.04))/(1+$B9)^5)+(DATOS!K22+DATOS!K23-DATOS!K39))/DATOS!K20 -> 9.122297
B10: 0.16 | C10: =((Proyecciones!D37/(1+$B10)^1+Proyecciones!E37/(1+$B10)^2+Proyecciones!F37/(1+$B10)^3+Proyecciones!G37/(1+$B10)^4+Proyecciones!H37/(1+$B10)^5+(Proyecciones!H8*C$5*(1-DATOS!K51)*1.04/($B10-0.04))/(1+$B10)^5)+(DATOS!K22+DATOS!K23-DATOS!K39))/DATOS!K20 -> 6.6540139 | D10: =((Proyecciones!D37/(1+$B10)^1+Proyecciones!E37/(1+$B10)^2+Proyecciones!F37/(1+$B10)^3+Proyecciones!G37/(1+$B10)^4+Proyecciones!H37/(1+$B10)^5+(Proyecciones!H8*D$5*(1-DATOS!K51)*1.04/($B10-0.04))/(1+$B10)^5)+(DATOS!K22+DATOS!K23-DATOS!K39))/DATOS!K20 -> 7.1071736 | E10: =((Proyecciones!D37/(1+$B10)^1+Proyecciones!E37/(1+$B10)^2+Proyecciones!F37/(1+$B10)^3+Proyecciones!G37/(1+$B10)^4+Proyecciones!H37/(1+$B10)^5+(Proyecciones!H8*E$5*(1-DATOS!K51)*1.04/($B10-0.04))/(1+$B10)^5)+(DATOS!K22+DATOS!K23-DATOS!K39))/DATOS!K20 -> 7.5603333 | F10: =((Proyecciones!D37/(1+$B10)^1+Proyecciones!E37/(1+$B10)^2+Proyecciones!F37/(1+$B10)^3+Proyecciones!G37/(1+$B10)^4+Proyecciones!H37/(1+$B10)^5+(Proyecciones!H8*F$5*(1-DATOS!K51)*1.04/($B10-0.04))/(1+$B10)^5)+(DATOS!K22+DATOS!K23-DATOS!K39))/DATOS!K20 -> 8.013493 | G10: =((Proyecciones!D37/(1+$B10)^1+Proyecciones!E37/(1+$B10)^2+Proyecciones!F37/(1+$B10)^3+Proyecciones!G37/(1+$B10)^4+Proyecciones!H37/(1+$B10)^5+(Proyecciones!H8*G$5*(1-DATOS!K51)*1.04/($B10-0.04))/(1+$B10)^5)+(DATOS!K22+DATOS!K23-DATOS!K39))/DATOS!K20 -> 8.4666527
B12: Precio de mercado: | C12: =DATOS!K44 -> 17.34 | D12: Compara cada celda con el precio de ~$17.
B14: Lectura: como toda empresa de opción, el rango es muy amplio: en los escenarios pesimistas (WACC alto, margen bajo) el valor es modesto y descansa sobre todo en la caja; en los optimistas (ejecuta bien la cadena mina-a-imán, márgenes altos) vale bastante más que el precio actual. Eso no es un fallo del modelo: es la naturaleza de la apuesta. El valor depende de la ejecución futura, no del negocio de hoy. Por eso el NAV (hoja Valoración) es el complemento imprescindible — pone un piso especialmente firme en este caso, porque casi toda la base de activos es caja.

Sheet Comparables
B2: ANÁLISIS DE COMPARABLES (Comps) — tierras raras e imanes
B3: Ancla USAR contra pares de tierras raras/imanes. MP Materials es el gemelo más maduro. Casi todos pre-rentabilidad → P/VC y EV/Ventas futuras. Múltiplos aprox/editables (azul).
B5: Empresa | C5: Ticker | D5: P/VC | E5: EV/Ventas | F5: Comentario
B6: MP Materials | C6: MP | D6: 24.7 | E6: 8 | F6: El gemelo maduro: mina-a-imán USA, ya con EBITDA+. Referencia clave.
B7: Lynas Rare Earths | C7: LYC | D7: 3.5 | E7: 6 | F7: Productor australiano, rentable. Referencia de productor establecido.
B8: Energy Fuels | C8: UUUU | D8: 10 | E8: 5 | F8: Uranio + tierras raras, pre-rentabilidad. Comparable de opción.
B9: Critical Metals | C9: CRML | D9: 4 | E9: n/d | F9: Tierras raras pre-producción (Greenland/Tanbreez).
B10: Idaho Strategic | C10: IDR | D10: 5 | E10: n/d | F10: Tierras raras + oro USA, junior.
B11: MEDIANA | D11: =MEDIAN(D6:D10) -> 5 | E11: =MEDIAN(E6:E10) -> 6
B13: VALORACIÓN IMPLÍCITA DE USAR ($/acción)
B14: Método | C14: Base ($M) | D14: × múltiplo | E14: Valor/acción | H14: Nota
B15: Por P/VC (patrimonio) | C15: =DATOS!K38 -> 2537 | D15: =D11 -> 5 | E15: =DATOS!K38*D11/DATOS!K20 -> 51.838987 | F15: Patrimonio × P/VC mediana.
B16: Por EV/Ventas (ingreso año4 proj) | C16: =Proyecciones!G8 -> 469.2 | D16: =E11 -> 6 | E16: =(Proyecciones!G8*E11+DATOS!K22+DATOS!K23-DATOS!K39)/DATOS!K20 -> 18.020025 | F16: Ventas futuras (año4) × múltiplo + caja neta.
B17: Precio de mercado ($) | E17: =DATOS!K44 -> 17.34
B19: Nota: el comparable natural de USA Rare Earth es MP Materials — ambas persiguen la cadena mina-a-imán integrada de EE.UU., pero MP va varios años por delante (ya genera EBITDA positivo y tiene operaciones en marcha), lo que explica por qué cotiza a múltiplos más altos. USAR es la versión más temprana y de mayor riesgo de la misma tesis, con la diferencia de un balance aún más cargado de caja. Lynas ancla el extremo "productor establecido"; Energy Fuels y Critical Metals aportan referencias de opción pre-rentabilidad. El comparable por valor en libros mide cuánto paga el mercado por empresas de esta etapa; el de ventas futuras muestra el potencial si ejecuta. Ambos son orientativos: en una empresa tan temprana, la valoración es intrínsecamente incierta y depende de la ejecución.
