Workbook

Sheet Resumen
B2: ENERGY FUELS (NYSE: UUUU) — Resumen Ejecutivo
B3: Modelo profesional (metodología Celsia/Murray). Arquitectura DATOS→fórmulas. Datos SEC hasta Q2 2026 (5-ago-2026).
B5: CIFRAS CLAVE (de DATOS)
B6: Precio de la acción | C6: =DATOS!K35 -> 16.12 | D6: ~$16 (ref. jun 2026).
B7: Capitalización de mercado | C7: =DATOS!K35*DATOS!K16 -> 4158.96 | D7: ~258M acciones.
B8: Ingresos 1S 2026 | C8: =DATOS!K8 -> 60.9 | D8: +189% vs 1S25.
B9: Pérdida neta 1S 2026 | C9: =DATOS!K14 -> -44.6 | D9: Pérdida por crecimiento.
B10: Caja + valores negociables | C10: =DATOS!I18+DATOS!I19 -> 936.7 | D10: ~$937M líquidos.
B11: Deuda convertible | C11: =DATOS!I27 -> 700 | D11: 0.75%, vence 2031.
B12: Capital de trabajo | C12: =DATOS!I30 -> 996 | D12: ~$996M. El colchón.
B13: Inventario uranio (Mlb) | C13: =DATOS!K38 -> 2.265 | D13: 2.27 Mlb físicas.
B15: VEREDICTO
B16: Tipo de inversión | C16: Opción sobre tierras raras | D16: Apuesta al mine-to-magnet occidental, respaldada por balance fuerte y uranio rentable.
B17: Negocio hoy | C17: Pierde dinero | D17: Minero pre-rentabilidad; uranio con costos bajísimos (~$23/lb) pero aún no cubre gastos totales.
B18: Balance | C18: Fortaleza extrema | D18: ~$937M líquidos + inventario, razón corriente ~31x. Años de pista.
B19: Transformación | C19: En marcha | D19: Adquisiciones VAC ($1.9B) + ASM: de minero a plataforma integrada de imanes REE.
B20: Valoración | C20: Por NAV, no DCF | D20: Pierde dinero → DCF no aplica. NAV = líquidos + uranio + minerales + opción REE − deuda.
B21: Riesgo/premio | C21: Muy binario | D21: Piso por los líquidos; techo alto SI el mine-to-magnet funciona. Dilución por adquisiciones es riesgo real.
B23: COMPARACIÓN CON CENTRUS (LEU)
B24: LEU (Centrus) | C24: Rentable, opción HALEU | D24: Gana dinero; se valora por DCF+opción; monopolio de enriquecimiento.
B25: UUUU (Energy Fuels) | C25: Pierde dinero, opción REE | D25: Se valora por NAV; balance de "fondo + minera"; apuesta a tierras raras.
B26: En común | C26: Ambas = opciones estratégicas | D26: Materiales críticos, respaldo de seguridad nacional USA, alto riesgo/premio.
B28: DESCARGO: material educativo, no asesoría financiera. Verifica en SEC EDGAR. Alto riesgo; puedes perder capital.
B61: GUÍA DE HOJAS: DATOS · Estado Resultados · Balance · Análisis Financiero · Proyecciones (3 estados) · Valoración (DCF+NAV) · Sensibilidad · Comparables.

Sheet DATOS
B2: ENERGY FUELS (UUUU) — HOJA DE DATOS CRUDOS (SEC 10-K / 10-Q)
B3: Fuente única. Azul = directo de SEC. Las demás hojas jalan con fórmulas. Edita SOLO aquí para actualizar. UUUU es minero de uranio + tierras raras EN TRANSFORMACIÓN (pierde dinero hoy). Valores en millones USD.
C5: ANUALES COMPLETOS | F5: Q1 (homólogo) | H5: Q2 (homólogo) | J5: 1S acumulado
B6: Concepto ($M) | C6: FY2023 | D6: FY2024 | E6: FY2025 | F6: Q1-25 | G6: Q1-26 | H6: Q2-25 | I6: Q2-26 | J6: 1S-25 | K6: 1S-26 | L6: Fuente / nota
B7: ESTADO DE RESULTADOS
B8: INGRESOS TOTALES | C8: 37.9 | D8: 78.1 | E8: 65.9 | F8: 16.9 | G8: 35.8 | H8: 4.2 | I8: 25.1 | J8: 21.1 | K8: 60.9 | L8: Yahoo/10-Q. 1S = Q1+Q2.
B9: Costo de ventas | C9: 18.2 | D9: 55.9 | E9: 52.2 | F9: 18.1 | L9: FY. Q trimestral no siempre aislado.
B10: UTILIDAD BRUTA | C10: 19.75 | D10: 22.2 | E10: 13.75 | F10: -1.23 | L10: GP. Q1 25 negativo.
B11: Gastos operativos (dev/expl/G&A) | L11: No aislado limpio.
B12: PÉRDIDA OPERATIVA | D12: -52 | E12: -70 | F12: -25 | G12: -15 | H12: -26.2 | I12: -30.6 | K12: -45.6 | L12: Operating loss. Q2 26 = -30.6.
B13: Otros ingresos/ganancias | C13: 130 | D13: 4 | G13: 4 | H13: 4.4 | I13: -3 | L13: 2023: gran ganancia one-time (Base Res.).
B14: UTILIDAD (PÉRDIDA) NETA | C14: 99.8 | D14: -47.8 | E14: -64 | F14: -26.3 | G14: -11 | H14: -21.8 | I14: -33.6 | J14: -48.1 | K14: -44.6 | L14: Net income. 2023 positivo por one-time.
B15: EPS básico ($) | C15: 0.63 | D15: -0.28 | E15: -0.34 | F15: -0.13 | G15: -0.04 | H15: -0.1 | I15: -0.13 | J15: -0.23 | K15: -0.17 | L15: Loss per share.
B16: Acciones en circulación (M) | K16: 258 | L16: ~258M (crece por adquisiciones/ATM).
B17: BALANCE GENERAL (fin de periodo)
B18: Caja y equivalentes | E18: 47 | G18: 108.4 | I18: 58.4 | L18: Cash. Baja: se mueve a securities.
B19: Valores negociables | E19: 812.7 | G19: 802.2 | I19: 878.3 | L19: Marketable securities: T-bills + equities de uranio.
B20: Cuentas por cobrar | G20: 7.6 | I20: 15.1 | L20: Trade receivables.
B21: Inventarios | G21: 69 | I21: 75 | L21: Uranio finished + en proceso.
B22: Total activo corriente | E22: 958.7 | I22: 1033 | L22: Current assets.
B23: PP&E neto | E23: 69.8 | I23: 74.2 | L23: Plantas + White Mesa Mill.
B24: Propiedades minerales netas | E24: 312.3 | I24: 328.6 | L24: Mineral properties. Activo clave del NAV.
B25: TOTAL ACTIVOS | E25: 1411.9 | G25: 1460 | I25: 1533.2 | L25: Total assets.
B26: Total pasivo corriente | E26: 31.2 | I26: 37 | L26: Current liabilities.
B27: Deuda convertible (neta) | E27: 676.7 | G27: 676.7 | I27: 700 | L27: 0.75% Conv. Notes due 2031 ($700M face).
B28: TOTAL PASIVOS | E28: 729.3 | I28: 736.4 | L28: Total liabilities.
B29: PATRIMONIO TOTAL | E29: 682.6 | I29: 796.8 | L29: Equity = Activos − Pasivos.
B30: Capital de trabajo (reportado) | E30: 927.4 | G30: 956.6 | I30: 996 | L30: Working capital reportado por la empresa.
B31: FLUJO DE CAJA (acumulado)
B32: Flujo de caja operativo | E32: -60 | K32: -50 | L32: OCF negativo (pierde dinero). Aproximado.
B33: CapEx | K33: 40 | L33: Inversión en expansión REE. Aproximado.
B34: MERCADO Y OPERATIVO (editable)
B35: Precio de la acción ($) | K35: 16.12 | L35: ACTUALIZAR. ~$16 (jun 2026, ref VAC deal).
B36: Precio spot U3O8 ($/lb) | K36: 86.5 | L36: TradeTech 31-jul-2026.
B37: Precio largo plazo U3O8 ($/lb) | K37: 97 | L37: Long-term price.
B38: Inventario U3O8 (Mlb finished+contained) | K38: 2.265 | L38: 2.265 Mlb totales jun 2026.
B39: Producción 2026E (Mlb, pto medio) | K39: 2 | L39: Guía 1.5-2.5 Mlb.
B40: SUPUESTOS DE VALORACIÓN (editable)
B41: Tasa libre de riesgo (Treasury 10y) | K41: 0.043 | L41: ~4.3%.
B42: Prima de riesgo de mercado | K42: 0.055 | L42: ERP USA.
...

Sheet Estado Resultados
B2: ESTADO DE RESULTADOS — comparación homogénea (jala de DATOS)
B3: Q1 vs Q1, Q2 vs Q2 con Δ%, luego 1S y anuales. UUUU pierde dinero: se busca si la pérdida se estrecha y por qué.
C5: ANUALES | F5: Q1 (25→26) | I5: Q2 (25→26)
B6: Concepto ($M) | C6: FY23 | D6: FY24 | E6: FY25 | F6: Q1 25 | G6: Q1 26 | H6: Δ% | I6: Q2 25 | J6: Q2 26 | K6: Δ%
B7: INGRESOS TOTALES | C7: =DATOS!C8 -> 37.9 | D7: =DATOS!D8 -> 78.1 | E7: =DATOS!E8 -> 65.9 | F7: =DATOS!F8 -> 16.9 | G7: =DATOS!G8 -> 35.8 | H7: =IFERROR((DATOS!G8-DATOS!F8)/ABS(DATOS!F8),"—") -> 1.1183432 | I7: =DATOS!H8 -> 4.2 | J7: =DATOS!I8 -> 25.1 | K7: =IFERROR((DATOS!I8-DATOS!H8)/ABS(DATOS!H8),"—") -> 4.9761905
B8: Utilidad bruta | C8: =DATOS!C10 -> 19.75 | D8: =DATOS!D10 -> 22.2 | E8: =DATOS!E10 -> 13.75 | F8: =DATOS!F10 -> -1.23 | G8: =DATOS!G10 | H8: =IFERROR((DATOS!G10-DATOS!F10)/ABS(DATOS!F10),"—") -> 1 | I8: =DATOS!H10 | J8: =DATOS!I10 | K8: =IFERROR((DATOS!I10-DATOS!H10)/ABS(DATOS!H10),"—") -> —
B9: Pérdida operativa | C9: =DATOS!C12 | D9: =DATOS!D12 -> -52 | E9: =DATOS!E12 -> -70 | F9: =DATOS!F12 -> -25 | G9: =DATOS!G12 -> -15 | H9: =IFERROR((DATOS!G12-DATOS!F12)/ABS(DATOS!F12),"—") -> 0.4 | I9: =DATOS!H12 -> -26.2 | J9: =DATOS!I12 -> -30.6 | K9: =IFERROR((DATOS!I12-DATOS!H12)/ABS(DATOS!H12),"—") -> -0.16793893
B10: Otros ingresos/ganancias | C10: =DATOS!C13 -> 130 | D10: =DATOS!D13 -> 4 | E10: =DATOS!E13 | F10: =DATOS!F13 | G10: =DATOS!G13 -> 4 | H10: =IFERROR((DATOS!G13-DATOS!F13)/ABS(DATOS!F13),"—") -> — | I10: =DATOS!H13 -> 4.4 | J10: =DATOS!I13 -> -3 | K10: =IFERROR((DATOS!I13-DATOS!H13)/ABS(DATOS!H13),"—") -> -1.6818182
B11: UTILIDAD (PÉRDIDA) NETA | C11: =DATOS!C14 -> 99.8 | D11: =DATOS!D14 -> -47.8 | E11: =DATOS!E14 -> -64 | F11: =DATOS!F14 -> -26.3 | G11: =DATOS!G14 -> -11 | H11: =IFERROR((DATOS!G14-DATOS!F14)/ABS(DATOS!F14),"—") -> 0.58174905 | I11: =DATOS!H14 -> -21.8 | J11: =DATOS!I14 -> -33.6 | K11: =IFERROR((DATOS!I14-DATOS!H14)/ABS(DATOS!H14),"—") -> -0.5412844
B12: EPS ($) | C12: =DATOS!C15 -> 0.63 | D12: =DATOS!D15 -> -0.28 | E12: =DATOS!E15 -> -0.34 | F12: =DATOS!F15 -> -0.13 | G12: =DATOS!G15 -> -0.04 | H12: =IFERROR((DATOS!G15-DATOS!F15)/ABS(DATOS!F15),"—") -> 0.69230769 | I12: =DATOS!H15 -> -0.1 | J12: =DATOS!I15 -> -0.13 | K12: =IFERROR((DATOS!I15-DATOS!H15)/ABS(DATOS!H15),"—") -> -0.3
B14: ACUMULADO SEMESTRE (1S)
B15: Concepto ($M) | C15: 1S 2025 | D15: 1S 2026 | E15: Δ% | F15: Lectura
B16: Ingresos totales | C16: =DATOS!J8 -> 21.1 | D16: =DATOS!K8 -> 60.9 | E16: =IFERROR((DATOS!K8-DATOS!J8)/ABS(DATOS!J8),"—") -> 1.8862559 | F16: +189%: uranio a plena venta vs 1S25 flojo.
B17: Pérdida neta | C17: =DATOS!J14 -> -48.1 | D17: =DATOS!K14 -> -44.6 | E17: =IFERROR((DATOS!K14-DATOS!J14)/ABS(DATOS!J14),"—") -> 0.072765073 | F17: Pérdida ~plana: mejora uranio compensada por costos de adquisiciones (VAC/ASM).
B19: Clave: los ingresos casi se triplican en 1S (uranio vendiéndose a ~$80/lb con costos de producción de ~$23/lb en Pinyon Plain, de los más bajos del mundo). Pero la pérdida neta NO mejora porque los costos de las adquisiciones VAC/ASM y la inversión en expansión de tierras raras se comen el margen. Es pérdida por CRECIMIENTO, no por operación deficiente. Lo que hay que vigilar: cuándo el segmento uranio alcanza breakeven consolidado.

Sheet Balance
B2: BALANCE GENERAL — dic25 → mar26 → jun26 ($M)
B3: Balance dominado por valores negociables (~$878M). Verde = de DATOS.
B5: Partida ($M) | C5: Dic-25 | D5: Mar-26 | E5: Jun-26 | F5: Comentario
B6: ACTIVOS
B7: Caja y equivalentes | C7: =DATOS!E18 -> 47 | D7: =DATOS!G18 -> 108.4 | E7: =DATOS!I18 -> 58.4 | F7: Baja: rota hacia securities con interés.
B8: Valores negociables | C8: =DATOS!E19 -> 812.7 | D8: =DATOS!G19 -> 802.2 | E8: =DATOS!I19 -> 878.3 | F8: ~$878M: T-bills + equities de uranio. El grueso del valor.
B9: Cuentas por cobrar | C9: =DATOS!E20 | D9: =DATOS!G20 -> 7.6 | E9: =DATOS!I20 -> 15.1
B10: Inventarios | C10: =DATOS!E21 | D10: =DATOS!G21 -> 69 | E10: =DATOS!I21 -> 75 | F10: Uranio: ~2.27 Mlb físicas.
B11: Total activo corriente | C11: =DATOS!E22 -> 958.7 | D11: =DATOS!G22 | E11: =DATOS!I22 -> 1033
B12: PP&E neto | C12: =DATOS!E23 -> 69.8 | D12: =DATOS!G23 | E12: =DATOS!I23 -> 74.2 | F12: White Mesa Mill + minas.
B13: Propiedades minerales netas | C13: =DATOS!E24 -> 312.3 | D13: =DATOS!G24 | E13: =DATOS!I24 -> 328.6 | F13: Activo clave para el NAV: reservas.
B14: TOTAL ACTIVOS | C14: =DATOS!E25 -> 1411.9 | D14: =DATOS!G25 -> 1460 | E14: =DATOS!I25 -> 1533.2
B15: PASIVOS Y PATRIMONIO
B16: Total pasivo corriente | C16: =DATOS!E26 -> 31.2 | D16: =DATOS!G26 | E16: =DATOS!I26 -> 37
B17: Deuda convertible | C17: =DATOS!E27 -> 676.7 | D17: =DATOS!G27 -> 676.7 | E17: =DATOS!I27 -> 700 | F17: $700M face, 0.75%, vence 2031.
B18: TOTAL PASIVOS | C18: =DATOS!E28 -> 729.3 | D18: =DATOS!G28 | E18: =DATOS!I28 -> 736.4
B19: PATRIMONIO TOTAL | C19: =DATOS!E29 -> 682.6 | D19: =DATOS!G29 | E19: =DATOS!I29 -> 796.8 | F19: Activos − Pasivos.
B21: MÉTRICAS
B22: Caja+securities − deuda ($M) | C22: =IFERROR(DATOS!E18+DATOS!E19-DATOS!E27,"n/d") -> 183 | D22: =IFERROR(DATOS!G18+DATOS!G19-DATOS!G27,"n/d") -> 233.9 | E22: =IFERROR(DATOS!I18+DATOS!I19-DATOS!I27,"n/d") -> 236.7 | F22: Posición financiera neta. Muy positiva.
B23: Razón corriente | C23: =IFERROR(DATOS!E22/DATOS!E26,"n/d") -> 30.727564 | D23: =IFERROR(DATOS!G22/DATOS!G26,"n/d") -> n/d | E23: =IFERROR(DATOS!I22/DATOS!I26,"n/d") -> 27.918919 | F23: Enorme (~27x): casi sin pasivo corriente.
B24: Deuda/Patrimonio | C24: =IFERROR(DATOS!E27/DATOS!E29,"n/d") -> 0.99135658 | D24: =IFERROR(DATOS!G27/DATOS!G29,"n/d") -> n/d | E24: =IFERROR(DATOS!I27/DATOS!I29,"n/d") -> 0.87851406 | F24: Apalancamiento moderado.
B26: Lectura: el balance de UUUU es casi el de un fondo de inversión con una minera encima. ~$878M en valores negociables + inventario físico de uranio, contra solo $700M de deuda convertible barata (0.75%). Esa fortaleza es lo que le permite financiar las adquisiciones VAC/ASM y la expansión de tierras raras sin depender del mercado. El activo "propiedades minerales" ($329M) es la base del NAV minero.

Sheet Análisis Financiero
B2: ANÁLISIS FINANCIERO — Liquidez · Actividad · Endeudamiento · Rentabilidad · DuPont
B3: Metodología Celsia/Murray. OJO: como UUUU pierde dinero, márgenes y ROE/ROIC son negativos — es lo esperado en un minero pre-rentabilidad.
B5: Indicador | C5: FY2023 | D5: FY2024 | E5: FY2025 | F5: Interpretación
B6: 1 · LIQUIDEZ
B7: Razón corriente | C7: =IFERROR(DATOS!C22/DATOS!C26,"n/d") -> n/d | D7: =IFERROR(DATOS!D22/DATOS!D26,"n/d") -> n/d | E7: =IFERROR(DATOS!E22/DATOS!E26,"n/d") -> 30.727564 | F7: FY25 ~31x. Liquidez extrema.
B8: Capital de trabajo ($M) | C8: =IFERROR(DATOS!C22-DATOS!C26,"n/d") -> 0 | D8: =IFERROR(DATOS!D22-DATOS!D26,"n/d") -> 0 | E8: =IFERROR(DATOS!E22-DATOS!E26,"n/d") -> 927.5 | F8: ~$927M. El colchón de la tesis.
B9: 2 · ACTIVIDAD
B10: Rotación de activos | C10: =IFERROR(DATOS!C8/DATOS!C25,"n/d") -> n/d | D10: =IFERROR(DATOS!D8/DATOS!D25,"n/d") -> n/d | E10: =IFERROR(DATOS!E8/DATOS!E25,"n/d") -> 0.046674694 | F10: Bajísima: activos financieros, no operativos.
B11: Días de inventario | C11: =IFERROR(365*DATOS!C21/DATOS!C9,"n/d") -> 0 | D11: =IFERROR(365*DATOS!D21/DATOS!D9,"n/d") -> 0 | E11: =IFERROR(365*DATOS!E21/DATOS!E9,"n/d") -> 0 | F11: Inventario de uranio estratégico.
B12: 3 · ENDEUDAMIENTO
B13: Nivel de endeudamiento | C13: =IFERROR(DATOS!C28/DATOS!C25,"n/d") -> n/d | D13: =IFERROR(DATOS!D28/DATOS!D25,"n/d") -> n/d | E13: =IFERROR(DATOS!E28/DATOS!E25,"n/d") -> 0.516538 | F13: FY25 ~52%: casi todo la convertible.
B14: Deuda/Patrimonio | C14: =IFERROR(DATOS!C27/DATOS!C29,"n/d") -> n/d | D14: =IFERROR(DATOS!D27/DATOS!D29,"n/d") -> n/d | E14: =IFERROR(DATOS!E27/DATOS!E29,"n/d") -> 0.99135658 | F14: ~1x. Moderado.
B15: Caja+securities/Deuda | C15: =IFERROR((DATOS!C18+DATOS!C19)/DATOS!C27,"n/d") -> n/d | D15: =IFERROR((DATOS!D18+DATOS!D19)/DATOS!D27,"n/d") -> n/d | E15: =IFERROR((DATOS!E18+DATOS!E19)/DATOS!E27,"n/d") -> 1.27043 | F15: >1.2x: cubre la deuda solo con líquidos.
B16: 4 · RENTABILIDAD (negativa: pre-breakeven)
B17: Margen bruto | C17: =IFERROR(DATOS!C10/DATOS!C8,"n/d") -> 0.52110818 | D17: =IFERROR(DATOS!D10/DATOS!D8,"n/d") -> 0.28425096 | E17: =IFERROR(DATOS!E10/DATOS!E8,"n/d") -> 0.20864947 | F17: Positivo pero volátil por costos de standby.
B18: Margen neto | C18: =IFERROR(DATOS!C14/DATOS!C8,"n/d") -> 2.6332454 | D18: =IFERROR(DATOS!D14/DATOS!D8,"n/d") -> -0.61203585 | E18: =IFERROR(DATOS!E14/DATOS!E8,"n/d") -> -0.97116844 | F18: FY23 positivo por one-time; FY24-25 negativo.
B19: ROA | C19: =IFERROR(DATOS!C14/DATOS!C25,"n/d") -> n/d | D19: =IFERROR(DATOS!D14/DATOS!D25,"n/d") -> n/d | E19: =IFERROR(DATOS!E14/DATOS!E25,"n/d") -> -0.045328989 | F19: Negativo: pierde dinero sobre sus activos.
B20: ROE | C20: =IFERROR(DATOS!C14/DATOS!C29,"n/d") -> n/d | D20: =IFERROR(DATOS!D14/DATOS!D29,"n/d") -> n/d | E20: =IFERROR(DATOS!E14/DATOS!E29,"n/d") -> -0.093759156 | F20: Negativo (salvo 2023 one-time).
B22: Diagnóstico: los ratios de rentabilidad son negativos y ESO ES NORMAL aquí — UUUU es un minero pre-rentabilidad invirtiendo en transformarse. Analizarlo por ROE/margen es engañoso. Lo relevante es: (1) liquidez extrema (razón corriente ~31x) que le da años de pista; (2) los líquidos cubren la deuda por sí solos; (3) el valor no está en las ganancias (no hay) sino en los ACTIVOS y la opción de tierras raras. Por eso la valoración va por NAV.

Sheet Proyecciones
B2: MODELO DE TRES ESTADOS PROYECTADOS Y ENLAZADOS (5 años) — Energy Fuels
B3: Minero en transición: el margen EBIT (driver) pasa de NEGATIVO a POSITIVO — el modelo muestra CUÁNDO cruza a rentabilidad. Las pérdidas iniciales se financian con los ~$878M en securities. DESCUADRE verifica el cuadre (=0).
B6: Concepto ($M) | C6: Base | D6: Año 1 | E6: Año 2 | F6: Año 3 | G6: Año 4 | H6: Año 5 | I6: Notas / enlace
B7: 1 · ESTADO DE RESULTADOS
B8: Ingresos totales | C8: =DATOS!$K$53 -> 122 | D8: =C8*(1+DATOS!$K$54) -> 158.6 | E8: =D8*(1+DATOS!$K$55) -> 214.11 | F8: =E8*(1+DATOS!$K$56) -> 278.343 | G8: =F8*(1+DATOS!$K$57) -> 334.0116 | H8: =G8*(1+DATOS!$K$58) -> 384.11334 | I8: Rampa uranio + REE.
B9: Crecimiento % | D9: =D8/C8-1 -> 0.3 | E9: =E8/D8-1 -> 0.35 | F9: =F8/E8-1 -> 0.3 | G9: =G8/F8-1 -> 0.2 | H9: =H8/G8-1 -> 0.15
B10: Ingreso operativo (EBIT) | D10: =D8*DATOS!$K$59 -> -47.58 | E10: =E8*DATOS!$K$60 -> -21.411 | F10: =F8*DATOS!$K$61 -> 13.91715 | G10: =G8*DATOS!$K$62 -> 50.10174 | H10: =H8*DATOS!$K$63 -> 84.504935 | I10: Ventas × margen EBIT (driver que sube de neg. a pos.).
B11: Margen EBIT % | D11: =DATOS!$K$59 -> -0.3 | E11: =DATOS!$K$60 -> -0.1 | F11: =DATOS!$K$61 -> 0.05 | G11: =DATOS!$K$62 -> 0.15 | H11: =DATOS!$K$63 -> 0.22 | I11: NEGATIVO años 1-2, POSITIVO desde año 3.
B12: (+) Rendimiento sobre securities | D12: =C19*DATOS!$K$68 -> 35.132 | E12: =D19*DATOS!$K$68 -> 34.5452 | F12: =E19*DATOS!$K$68 -> 33.282253 | G12: =F19*DATOS!$K$68 -> 32.624089 | H12: =G19*DATOS!$K$68 -> 32.624089 | I12: ~4% sobre securities del año anterior.
B13: Utilidad antes de impuestos | D13: =D10+D12 -> -12.448 | E13: =E10+E12 -> 13.1342 | F13: =F10+F12 -> 47.199403 | G13: =G10+G12 -> 82.725829 | H13: =H10+H12 -> 117.12902
B14: (−) Impuestos | D14: =MAX(0,D13)*DATOS!K44 -> 0 | E14: =MAX(0,E13)*DATOS!K44 -> 2.758182 | F14: =MAX(0,F13)*DATOS!K44 -> 9.9118746 | G14: =MAX(0,G13)*DATOS!K44 -> 17.372424 | H14: =MAX(0,H13)*DATOS!K44 -> 24.597095 | I14: Solo paga si hay utilidad (MAX 0).
B15: UTILIDAD (PÉRDIDA) NETA | D15: =D13-D14 -> -12.448 | E15: =E13-E14 -> 10.376018 | F15: =F13-F14 -> 37.287528 | G15: =G13-G14 -> 65.353405 | H15: =H13-H14 -> 92.531929
B17: 2 · BALANCE GENERAL
B18: Caja y equivalentes | C18: =DATOS!I18 -> 58.4 | D18: =D41 -> 30 | E18: =E41 -> 30 | F18: =F41 -> 30 | G18: =G41 -> 33.004573 | H18: =H41 -> 55.227061 | I18: ← Caja final del Flujo.
B19: Valores negociables (securities) | C19: =DATOS!I19 -> 878.3 | D19: =DATOS!I19-(D41-(D40+D39)) -> 863.63 | E19: =D19-(E41-(E40+E39)) -> 832.05632 | F19: =E19-(F41-(F40+F39)) -> 815.60224 | G19: =F19-(G41-(G40+G39)) -> 815.60224 | H19: =G19-(H41-(H40+H39)) -> 815.60224 | I19: Se mantienen (colchón). Editable.
B20: Cuentas por cobrar | C20: =DATOS!I20 -> 15.1 | D20: =D8*(DATOS!I20/DATOS!$K$53) -> 19.63 | E20: =E8*(DATOS!I20/DATOS!$K$53) -> 26.5005 | F20: =F8*(DATOS!I20/DATOS!$K$53) -> 34.45065 | G20: =G8*(DATOS!I20/DATOS!$K$53) -> 41.34078 | H20: =H8*(DATOS!I20/DATOS!$K$53) -> 47.541897 | I20: Ratio CxC/ventas.
B21: Inventarios | C21: =DATOS!I21 -> 75 | D21: =D8*(DATOS!I21/DATOS!$K$53) -> 97.5 | E21: =E8*(DATOS!I21/DATOS!$K$53) -> 131.625 | F21: =F8*(DATOS!I21/DATOS!$K$53) -> 171.1125 | G21: =G8*(DATOS!I21/DATOS!$K$53) -> 205.335 | H21: =H8*(DATOS!I21/DATOS!$K$53) -> 236.13525 | I21: Inventario de uranio.
B22: Propiedades minerales | C22: =DATOS!I24 -> 328.6 | D22: =C22 -> 328.6 | E22: =D22 -> 328.6 | F22: =E22 -> 328.6 | G22: =F22 -> 328.6 | H22: =G22 -> 328.6 | I22: Constante (reservas).
B23: PP&E neto | C23: =DATOS!I23 -> 74.2 | D23: =C23+D8*DATOS!$K$66-D8*DATOS!$K$65 -> 101.162 | E23: =D23+E8*DATOS!$K$66-E8*DATOS!$K$65 -> 137.5607 | F23: =E23+F8*DATOS!$K$66-F8*DATOS!$K$65 -> 184.87901 | G23: =F23+G8*DATOS!$K$66-G8*DATOS!$K$65 -> 241.66098 | H23: =G23+H8*DATOS!$K$66-H8*DATOS!$K$65 -> 306.96025 | I23: + CapEx − depreciación.
B24: Otros activos (resto) | C24: =DATOS!I25-DATOS!I18-DATOS!I19-DATOS!I20-DATOS!I21-DATOS!I24-DATOS!I23 -> 103.6 | D24: =C24 -> 103.6 | E24: =D24 -> 103.6 | F24: =E24 -> 103.6 | G24: =F24 -> 103.6 | H24: =G24 -> 103.6 | I24: Resto constante.
B25: TOTAL ACTIVOS | C25: =C18+C19+C20+C21+C22+C23+C24 -> 1533.2 | D25: =D18+D19+D20+D21+D22+D23+D24 -> 1544.122 | E25: =E18+E19+E20+E21+E22+E23+E24 -> 1589.9425 | F25: =F18+F19+F20+F21+F22+F23+F24 -> 1668.2444 | G25: =G18+G19+G20+G21+G22+G23+G24 -> 1769.1436 | H25: =H18+H19+H20+H21+H22+H23+H24 -> 1893.6667
B26: Pasivos operativos | C26: =DATOS!I28-DATOS!I27 -> 36.4 | D26: =D8*((DATOS!I28-DATOS!I27)/DATOS!$K$53) -> 47.32 | E26: =E8*((DATOS!I28-DATOS!I27)/DATOS!$K$53) -> 63.882 | F26: =F8*((DATOS!I28-DATOS!I27)/DATOS!$K$53) -> 83.0466 | G26: =G8*((DATOS!I28-DATOS!I27)/DATOS!$K$53) -> 99.65592 | H26: =H8*((DATOS!I28-DATOS!I27)/DATOS!$K$53) -> 114.60431 | I26: Ratio pasivos oper./ventas.
B27: Deuda (convertible + plug) | C27: =DATOS!I27 -> 700 | D27: =D25-D26-D29 -> 712.45 | E27: =E25-E26-E29 -> 731.3325 | F27: =F25-F26-F29 -> 753.18225 | G27: =G25-G26-G29 -> 772.1187 | H27: =H25-H26-H29 -> 789.16151 | I27: PLUG: cuadra el balance.
B28: TOTAL PASIVOS | C28: =C26+C27 -> 736.4 | D28: =D26+D27 -> 759.77 | E28: =E26+E27 -> 795.2145 | F28: =F26+F27 -> 836.22885 | G28: =G26+G27 -> 871.77462 | H28: =H26+H27 -> 903.76581
B29: PATRIMONIO | C29: =DATOS!I29 -> 796.8 | D29: =C29+D15 -> 784.352 | E29: =D29+E15 -> 794.72802 | F29: =E29+F15 -> 832.01555 | G29: =F29+G15 -> 897.36895 | H29: =G29+H15 -> 989.90088 | I29: Previo + utilidad (o − pérdida).
B30: TOTAL PASIVO + PATRIMONIO | C30: =C28+C29 -> 1533.2 | D30: =D28+D29 -> 1544.122 | E30: =E28+E29 -> 1589.9425 | F30: =F28+F29 -> 1668.2444 | G30: =G28+G29 -> 1769.1436 | H30: =H28+H29 -> 1893.6667
B31: DESCUADRE (Activo − Pas − Patr) | C31: =C25-C30 -> 0 | D31: =D25-D30 -> 0 | E31: =E25-E30 -> 0 | F31: =F25-F30 -> 0 | G31: =G25-G30 -> 0 | H31: =H25-H30 -> 0 | I31: DEBE SER 0.
B33: 3 · FLUJO DE CAJA
B34: Utilidad (pérdida) neta | D34: =D15 -> -12.448 | E34: =E15 -> 10.376018 | F34: =F15 -> 37.287528 | G34: =G15 -> 65.353405 | H34: =H15 -> 92.531929 | I34: ← Resultados.
B35: (+) Depreciación | D35: =D8*DATOS!$K$65 -> 12.688 | E35: =E8*DATOS!$K$65 -> 17.1288 | F35: =F8*DATOS!$K$65 -> 22.26744 | G35: =G8*DATOS!$K$65 -> 26.720928 | H35: =H8*DATOS!$K$65 -> 30.729067 | I35: No-caja.
B36: (−) Δ Capital de trabajo | D36: =-(D8-C8)*DATOS!$K$67 -> -3.66 | E36: =-(E8-D8)*DATOS!$K$67 -> -5.551 | F36: =-(F8-E8)*DATOS!$K$67 -> -6.4233 | G36: =-(G8-F8)*DATOS!$K$67 -> -5.56686 | H36: =-(H8-G8)*DATOS!$K$67 -> -5.010174 | I36: Sobre crecimiento de ventas.
B37: Flujo de caja operativo | D37: =D34+D35+D36 -> -3.42 | E37: =E34+E35+E36 -> 21.953818 | F37: =F34+F35+F36 -> 53.131668 | G37: =G34+G35+G36 -> 86.507473 | H37: =H34+H35+H36 -> 118.25082
B38: (−) CapEx | D38: =-D8*DATOS!$K$66 -> -39.65 | E38: =-E8*DATOS!$K$66 -> -53.5275 | F38: =-F8*DATOS!$K$66 -> -69.58575 | G38: =-G8*DATOS!$K$66 -> -83.5029 | H38: =-H8*DATOS!$K$66 -> -96.028335 | I38: % de ventas.
B39: Flujo de caja libre (FCF) | D39: =D37+D38 -> -43.07 | E39: =E37+E38 -> -31.573682 | F39: =F37+F38 -> -16.454082 | G39: =G37+G38 -> 3.0045733 | H39: =H37+H38 -> 22.222487 | I39: OCF − CapEx. Alimenta el DCF. Negativo al inicio.
B40: Caja inicial | D40: =DATOS!I18 -> 58.4 | E40: =D41 -> 30 | F40: =E41 -> 30 | G40: =F41 -> 30 | H40: =G41 -> 33.004573
B41: Caja final | D41: =MAX(30,D40+D39) -> 30 | E41: =MAX(30,E40+E39) -> 30 | F41: =MAX(30,F40+F39) -> 30 | G41: =MAX(30,G40+G39) -> 33.004573 | H41: =MAX(30,H40+H39) -> 55.227061 | I41: → Caja del Balance. (Securities cubren si baja mucho.)
B43: Cómo leerlo: el corazón de la tesis de UUUU es CUÁNDO cruza a rentabilidad. El margen EBIT (fila 11) pasa de −30% (año 1) a +5% (año 3) y +22% (año 5) — ahí se ve el punto de inflexión. Mientras pierde, la caja baja pero los ~$878M en securities son el colchón que lo sostiene sin quebrar. El FCF (verde) es negativo al inicio y positivo al madurar; el DCF valora ese futuro. Todo cuadra (Descuadre=0). Cambia los márgenes o el crecimiento en DATOS y ves cómo se mueve el año de breakeven.

Sheet Valoración
B2: VALORACIÓN — NAV / Suma de partes + WACC (CAPM)
B3: UUUU PIERDE dinero: el DCF de flujos da negativo y no sirve. La valoración correcta de un minero pre-rentabilidad es por NAV (valor de activos). Amarillo = editable.
B5: 1 · COSTO DE CAPITAL (WACC vía CAPM)
B6: Tasa libre de riesgo (Rf) | C6: =DATOS!K41 -> 0.043 | E6: De DATOS.
B7: Prima de riesgo (ERP) | C7: =DATOS!K42 -> 0.055 | E7: De DATOS.
B8: Beta desapalancado (βu) | C8: =DATOS!K43 -> 1.2 | E8: Minería: beta alto. De DATOS.
B9: Valor de mercado del equity (E) | C9: =DATOS!K35*DATOS!K16 -> 4158.96 | E9: Precio × acciones (~258M).
B10: Valor de la deuda (D) | C10: =DATOS!I27 -> 700 | E10: Convertible (de DATOS).
B11: Peso deuda D/(D+E) | C11: =C10/(C10+C9) -> 0.14406375
B12: Peso equity E/(D+E) | C12: =C9/(C10+C9) -> 0.85593625
B13: Tasa impositiva (t) | C13: =DATOS!K44 -> 0.21
B14: Beta apalancado (βL, Hamada) | C14: =C8*(1+(1-C13)*C10/C9) -> 1.3595591 | E14: βu×(1+(1−t)×D/E).
B15: Costo del equity (Ke = CAPM) | C15: =C6+C14*C7 -> 0.11777575 | E15: Rf + βL × ERP.
B16: Costo de la deuda (Kd) | C16: =DATOS!K45 -> 0.05
B17: WACC | C17: =C12*C15+C11*C16*(1-C13) -> 0.10649905 | E17: We×Ke + Wd×Kd(1−t).
B19: 2 · DCF — Flujo de Caja Libre proyectado (desde Proyecciones)
B20: UUUU pierde hoy pero el modelo proyecta el cruce a rentabilidad. El DCF captura ese futuro (es especulativo — ver sensibilidad).
B21: Año | C21: FCF ($M) | D21: VP ($M) | E21: FCF de la hoja Proyecciones. Negativo al inicio.
B22: 1 | C22: =Proyecciones!D39 -> -43.07 | D22: =C22/(1+C17)^1 -> -38.92457
B23: 2 | C23: =Proyecciones!E39 -> -31.573682 | D23: =C23/(1+C17)^2 -> -25.788325
B24: 3 | C24: =Proyecciones!F39 -> -16.454082 | D24: =C24/(1+C17)^3 -> -12.145643
B25: 4 | C25: =Proyecciones!G39 -> 3.0045733 | D25: =C25/(1+C17)^4 -> 2.0043733
B26: 5 | C26: =Proyecciones!H39 -> 22.222487 | D26: =C26/(1+C17)^5 -> 13.397922
B27: FCF terminal normalizado ($M) | C27: =Proyecciones!H8*DATOS!K64*(1-DATOS!K44) -> 75.862385 | E27: Ventas año5 × margen EBIT terminal × (1−t). Estado maduro.
B28: Valor terminal (Gordon, g=3%) | C28: =C27*(1.03)/(C17-0.03) -> 1021.4278 | D28: =C28/(1+C17)^5 -> 615.81806 | E28: Crecimiento perpetuo 3%.
B29: Valor empresa (EV) ($M) | C29: =SUM(D22:D26)+D28 -> 554.36182 | E29: Mill + minas.
B30: (+) Securities + caja − deuda ($M) | C30: =DATOS!I19+DATOS!I18-DATOS!I27 -> 236.7 | E30: Puente EV→equity. Incluye el gran colchón de securities.
B31: Valor del patrimonio ($M) | C31: =C29+C30 -> 791.06182 | E31: Cuentas por cobrar.
B32: Valor intrínseco por acción — DCF ($) | C32: =C31/DATOS!K16 -> 3.0661311 | E32: Face $700M.
B33: Precio de mercado ($) | C33: =DATOS!K35 -> 16.12 | E33: Pasivos no financieros.
B34: Margen de seguridad vs DCF | C34: =C32/DATOS!K35-1 -> -0.80979336 | E34: Positivo=infravalorada. OJO: el DCF depende de que la rampa REE funcione.
B35: NAV por acción ($) | C35: =C34/DATOS!K16 -> -0.0031387339 | E35: NAV / ~258M acciones.
B36: Precio de mercado ($) | C36: =DATOS!K35 -> 16.12 | E36: De DATOS.
B37: Precio / NAV | C37: =DATOS!K35/C35 -> -5135.8287 | E37: >1 = cotiza sobre NAV (paga prima por la opción REE). <1 = descuento.
B39: ADVERTENCIA: el NAV depende críticamente de dos cosas muy inciertas: (1) el valor de la "opción tierras raras" ($300M es un marcador editable — podría ser 0 o 5x eso según si el mine-to-magnet funciona), y (2) el precio del uranio y de las equities en securities (volátiles). El grueso del NAV "duro" son los ~$937M de líquidos + inventario, que ponen un piso. Todo lo demás es opcionalidad. Por eso UUUU cotiza como una apuesta al futuro de las tierras raras occidentales respaldada por un balance fuerte.

Sheet Sensibilidad
B2: ANÁLISIS DE SENSIBILIDAD — Valor por acción (DCF)
B3: Cruza WACC (filas) contra el MARGEN EBIT TERMINAL (columnas) — la variable clave de un minero que cruza a rentabilidad. Muestra cuánto vale la empresa según qué tan rentable llegue a ser y a qué tasa se descuente.
B5: WACC \ margen term. | C5: 0.15 | D5: 0.2 | E5: 0.25 | F5: 0.3 | G5: 0.35
B6: 0.085 | C6: =((Proyecciones!D39/(1+$B6)^1+Proyecciones!E39/(1+$B6)^2+Proyecciones!F39/(1+$B6)^3+Proyecciones!G39/(1+$B6)^4+Proyecciones!H39/(1+$B6)^5+(Proyecciones!H8*C$5*(1-DATOS!K44)*1.03/($B6-0.03))/(1+$B6)^5)+(DATOS!I19+DATOS!I18-DATOS!I27))/DATOS!K16 -> 2.8726547 | D6: =((Proyecciones!D39/(1+$B6)^1+Proyecciones!E39/(1+$B6)^2+Proyecciones!F39/(1+$B6)^3+Proyecciones!G39/(1+$B6)^4+Proyecciones!H39/(1+$B6)^5+(Proyecciones!H8*D$5*(1-DATOS!K44)*1.03/($B6-0.03))/(1+$B6)^5)+(DATOS!I19+DATOS!I18-DATOS!I27))/DATOS!K16 -> 3.6050788 | E6: =((Proyecciones!D39/(1+$B6)^1+Proyecciones!E39/(1+$B6)^2+Proyecciones!F39/(1+$B6)^3+Proyecciones!G39/(1+$B6)^4+Proyecciones!H39/(1+$B6)^5+(Proyecciones!H8*E$5*(1-DATOS!K44)*1.03/($B6-0.03))/(1+$B6)^5)+(DATOS!I19+DATOS!I18-DATOS!I27))/DATOS!K16 -> 4.3375029 | F6: =((Proyecciones!D39/(1+$B6)^1+Proyecciones!E39/(1+$B6)^2+Proyecciones!F39/(1+$B6)^3+Proyecciones!G39/(1+$B6)^4+Proyecciones!H39/(1+$B6)^5+(Proyecciones!H8*F$5*(1-DATOS!K44)*1.03/($B6-0.03))/(1+$B6)^5)+(DATOS!I19+DATOS!I18-DATOS!I27))/DATOS!K16 -> 5.069927 | G6: =((Proyecciones!D39/(1+$B6)^1+Proyecciones!E39/(1+$B6)^2+Proyecciones!F39/(1+$B6)^3+Proyecciones!G39/(1+$B6)^4+Proyecciones!H39/(1+$B6)^5+(Proyecciones!H8*G$5*(1-DATOS!K44)*1.03/($B6-0.03))/(1+$B6)^5)+(DATOS!I19+DATOS!I18-DATOS!I27))/DATOS!K16 -> 5.8023511
B7: 0.095 | C7: =((Proyecciones!D39/(1+$B7)^1+Proyecciones!E39/(1+$B7)^2+Proyecciones!F39/(1+$B7)^3+Proyecciones!G39/(1+$B7)^4+Proyecciones!H39/(1+$B7)^5+(Proyecciones!H8*C$5*(1-DATOS!K44)*1.03/($B7-0.03))/(1+$B7)^5)+(DATOS!I19+DATOS!I18-DATOS!I27))/DATOS!K16 -> 2.4530326 | D7: =((Proyecciones!D39/(1+$B7)^1+Proyecciones!E39/(1+$B7)^2+Proyecciones!F39/(1+$B7)^3+Proyecciones!G39/(1+$B7)^4+Proyecciones!H39/(1+$B7)^5+(Proyecciones!H8*D$5*(1-DATOS!K44)*1.03/($B7-0.03))/(1+$B7)^5)+(DATOS!I19+DATOS!I18-DATOS!I27))/DATOS!K16 -> 3.0449894 | E7: =((Proyecciones!D39/(1+$B7)^1+Proyecciones!E39/(1+$B7)^2+Proyecciones!F39/(1+$B7)^3+Proyecciones!G39/(1+$B7)^4+Proyecciones!H39/(1+$B7)^5+(Proyecciones!H8*E$5*(1-DATOS!K44)*1.03/($B7-0.03))/(1+$B7)^5)+(DATOS!I19+DATOS!I18-DATOS!I27))/DATOS!K16 -> 3.6369463 | F7: =((Proyecciones!D39/(1+$B7)^1+Proyecciones!E39/(1+$B7)^2+Proyecciones!F39/(1+$B7)^3+Proyecciones!G39/(1+$B7)^4+Proyecciones!H39/(1+$B7)^5+(Proyecciones!H8*F$5*(1-DATOS!K44)*1.03/($B7-0.03))/(1+$B7)^5)+(DATOS!I19+DATOS!I18-DATOS!I27))/DATOS!K16 -> 4.2289031 | G7: =((Proyecciones!D39/(1+$B7)^1+Proyecciones!E39/(1+$B7)^2+Proyecciones!F39/(1+$B7)^3+Proyecciones!G39/(1+$B7)^4+Proyecciones!H39/(1+$B7)^5+(Proyecciones!H8*G$5*(1-DATOS!K44)*1.03/($B7-0.03))/(1+$B7)^5)+(DATOS!I19+DATOS!I18-DATOS!I27))/DATOS!K16 -> 4.82086
B8: 0.107 | C8: =((Proyecciones!D39/(1+$B8)^1+Proyecciones!E39/(1+$B8)^2+Proyecciones!F39/(1+$B8)^3+Proyecciones!G39/(1+$B8)^4+Proyecciones!H39/(1+$B8)^5+(Proyecciones!H8*C$5*(1-DATOS!K44)*1.03/($B8-0.03))/(1+$B8)^5)+(DATOS!I19+DATOS!I18-DATOS!I27))/DATOS!K16 -> 2.098932 | D8: =((Proyecciones!D39/(1+$B8)^1+Proyecciones!E39/(1+$B8)^2+Proyecciones!F39/(1+$B8)^3+Proyecciones!G39/(1+$B8)^4+Proyecciones!H39/(1+$B8)^5+(Proyecciones!H8*D$5*(1-DATOS!K44)*1.03/($B8-0.03))/(1+$B8)^5)+(DATOS!I19+DATOS!I18-DATOS!I27))/DATOS!K16 -> 2.5721324 | E8: =((Proyecciones!D39/(1+$B8)^1+Proyecciones!E39/(1+$B8)^2+Proyecciones!F39/(1+$B8)^3+Proyecciones!G39/(1+$B8)^4+Proyecciones!H39/(1+$B8)^5+(Proyecciones!H8*E$5*(1-DATOS!K44)*1.03/($B8-0.03))/(1+$B8)^5)+(DATOS!I19+DATOS!I18-DATOS!I27))/DATOS!K16 -> 3.0453329 | F8: =((Proyecciones!D39/(1+$B8)^1+Proyecciones!E39/(1+$B8)^2+Proyecciones!F39/(1+$B8)^3+Proyecciones!G39/(1+$B8)^4+Proyecciones!H39/(1+$B8)^5+(Proyecciones!H8*F$5*(1-DATOS!K44)*1.03/($B8-0.03))/(1+$B8)^5)+(DATOS!I19+DATOS!I18-DATOS!I27))/DATOS!K16 -> 3.5185334 | G8: =((Proyecciones!D39/(1+$B8)^1+Proyecciones!E39/(1+$B8)^2+Proyecciones!F39/(1+$B8)^3+Proyecciones!G39/(1+$B8)^4+Proyecciones!H39/(1+$B8)^5+(Proyecciones!H8*G$5*(1-DATOS!K44)*1.03/($B8-0.03))/(1+$B8)^5)+(DATOS!I19+DATOS!I18-DATOS!I27))/DATOS!K16 -> 3.9917339
B9: 0.12 | C9: =((Proyecciones!D39/(1+$B9)^1+Proyecciones!E39/(1+$B9)^2+Proyecciones!F39/(1+$B9)^3+Proyecciones!G39/(1+$B9)^4+Proyecciones!H39/(1+$B9)^5+(Proyecciones!H8*C$5*(1-DATOS!K44)*1.03/($B9-0.03))/(1+$B9)^5)+(DATOS!I19+DATOS!I18-DATOS!I27))/DATOS!K16 -> 1.8273902 | D9: =((Proyecciones!D39/(1+$B9)^1+Proyecciones!E39/(1+$B9)^2+Proyecciones!F39/(1+$B9)^3+Proyecciones!G39/(1+$B9)^4+Proyecciones!H39/(1+$B9)^5+(Proyecciones!H8*D$5*(1-DATOS!K44)*1.03/($B9-0.03))/(1+$B9)^5)+(DATOS!I19+DATOS!I18-DATOS!I27))/DATOS!K16 -> 2.2092829 | E9: =((Proyecciones!D39/(1+$B9)^1+Proyecciones!E39/(1+$B9)^2+Proyecciones!F39/(1+$B9)^3+Proyecciones!G39/(1+$B9)^4+Proyecciones!H39/(1+$B9)^5+(Proyecciones!H8*E$5*(1-DATOS!K44)*1.03/($B9-0.03))/(1+$B9)^5)+(DATOS!I19+DATOS!I18-DATOS!I27))/DATOS!K16 -> 2.5911756 | F9: =((Proyecciones!D39/(1+$B9)^1+Proyecciones!E39/(1+$B9)^2+Proyecciones!F39/(1+$B9)^3+Proyecciones!G39/(1+$B9)^4+Proyecciones!H39/(1+$B9)^5+(Proyecciones!H8*F$5*(1-DATOS!K44)*1.03/($B9-0.03))/(1+$B9)^5)+(DATOS!I19+DATOS!I18-DATOS!I27))/DATOS!K16 -> 2.9730684 | G9: =((Proyecciones!D39/(1+$B9)^1+Proyecciones!E39/(1+$B9)^2+Proyecciones!F39/(1+$B9)^3+Proyecciones!G39/(1+$B9)^4+Proyecciones!H39/(1+$B9)^5+(Proyecciones!H8*G$5*(1-DATOS!K44)*1.03/($B9-0.03))/(1+$B9)^5)+(DATOS!I19+DATOS!I18-DATOS!I27))/DATOS!K16 -> 3.3549611
B10: 0.135 | C10: =((Proyecciones!D39/(1+$B10)^1+Proyecciones!E39/(1+$B10)^2+Proyecciones!F39/(1+$B10)^3+Proyecciones!G39/(1+$B10)^4+Proyecciones!H39/(1+$B10)^5+(Proyecciones!H8*C$5*(1-DATOS!K44)*1.03/($B10-0.03))/(1+$B10)^5)+(DATOS!I19+DATOS!I18-DATOS!I27))/DATOS!K16 -> 1.6033027 | D10: =((Proyecciones!D39/(1+$B10)^1+Proyecciones!E39/(1+$B10)^2+Proyecciones!F39/(1+$B10)^3+Proyecciones!G39/(1+$B10)^4+Proyecciones!H39/(1+$B10)^5+(Proyecciones!H8*D$5*(1-DATOS!K44)*1.03/($B10-0.03))/(1+$B10)^5)+(DATOS!I19+DATOS!I18-DATOS!I27))/DATOS!K16 -> 1.9095733 | E10: =((Proyecciones!D39/(1+$B10)^1+Proyecciones!E39/(1+$B10)^2+Proyecciones!F39/(1+$B10)^3+Proyecciones!G39/(1+$B10)^4+Proyecciones!H39/(1+$B10)^5+(Proyecciones!H8*E$5*(1-DATOS!K44)*1.03/($B10-0.03))/(1+$B10)^5)+(DATOS!I19+DATOS!I18-DATOS!I27))/DATOS!K16 -> 2.215844 | F10: =((Proyecciones!D39/(1+$B10)^1+Proyecciones!E39/(1+$B10)^2+Proyecciones!F39/(1+$B10)^3+Proyecciones!G39/(1+$B10)^4+Proyecciones!H39/(1+$B10)^5+(Proyecciones!H8*F$5*(1-DATOS!K44)*1.03/($B10-0.03))/(1+$B10)^5)+(DATOS!I19+DATOS!I18-DATOS!I27))/DATOS!K16 -> 2.5221147 | G10: =((Proyecciones!D39/(1+$B10)^1+Proyecciones!E39/(1+$B10)^2+Proyecciones!F39/(1+$B10)^3+Proyecciones!G39/(1+$B10)^4+Proyecciones!H39/(1+$B10)^5+(Proyecciones!H8*G$5*(1-DATOS!K44)*1.03/($B10-0.03))/(1+$B10)^5)+(DATOS!I19+DATOS!I18-DATOS!I27))/DATOS!K16 -> 2.8283853
B12: Precio de mercado: | C12: =DATOS!K35 -> 16.12 | D12: Compara cada celda con el precio de $16. Casi ninguna lo alcanza → el DCF operativo no justifica el precio.
B14: Lectura: incluso en el escenario más optimista (margen terminal 35%, WACC 8.5%), el valor del NEGOCIO OPERATIVO por DCF queda muy por debajo del precio de mercado de $16. Esto es el hallazgo central: el mercado NO paga por las operaciones proyectadas de uranio, paga por (1) el colchón de ~$878M en securities y (2) la opción de tierras raras que este DCF no captura. Por eso UUUU se valora mejor por NAV/suma de partes. La sensibilidad demuestra que la tesis operativa por sí sola no sostiene el precio — hay que creer en la opción REE.

Sheet Comparables
B2: ANÁLISIS DE COMPARABLES (Comps) — mineras de uranio y tierras raras
B3: Ancla UUUU contra mineras similares. Como muchas pierden dinero, el múltiplo relevante es P/VC (precio/valor contable) y EV/ingresos, no P/U. Múltiplos aproximados/editables (azul).
B5: Empresa | C5: Ticker | D5: P/VC | E5: EV/Ventas | F5: P/NAV | G5: Comentario
B6: Cameco | C6: CCJ | D6: 3.8 | E6: 9 | F6: 1.6 | G6: Líder mundial uranio, rentable. Premium.
B7: Denison Mines | C7: DNN | D7: 2.5 | E7: n/d | F7: 1.3 | G7: Uranio junior, pre-producción.
B8: Ur-Energy | C8: URG | D8: 2 | E8: 8 | F8: 1.1 | G8: Productor ISR pequeño de uranio.
B9: MP Materials | C9: MP | D9: 4.5 | E9: 12 | F9: 2 | G9: Tierras raras USA (comparable REE).
B10: Lynas Rare Earths | C10: LYC | D10: 3 | E10: 7 | F10: 1.5 | G10: REE fuera de China (Australia).
B11: NexGen Energy | C11: NXE | D11: 3.5 | E11: n/d | F11: 1.4 | G11: Uranio pre-producción (Canadá).
B12: MEDIANA | D12: =MEDIAN(D6:D11) -> 3.25 | E12: =MEDIAN(E6:E11) -> 8.5 | F12: =MEDIAN(F6:F11) -> 1.45
B14: VALORACIÓN IMPLÍCITA DE UUUU
B15: Método | C15: Base UUUU | D15: × múltiplo | E15: Valor/acción | H15: Nota
B16: Por P/VC (patrimonio) | C16: =DATOS!I29 -> 796.8 | D16: =D12 -> 3.25 | E16: =DATOS!I29*D12/DATOS!K16 -> 10.037209 | F16: Patrimonio × P/VC mediana.
B17: Por EV/Ventas | C17: =DATOS!K53 -> 122 | D17: =E12 -> 8.5 | E17: =(DATOS!K53*E12+DATOS!I19+DATOS!I18-DATOS!I27)/DATOS!K16 -> 4.9368217 | F17: (Ventas×múlt + securities + caja − deuda)/acciones.
B18: Precio de mercado ($) | E18: =DATOS!K35 -> 16.12
B20: Nota: los comps de uranio puro (CCJ, DNN, URG) y de REE (MP, LYC) enmarcan a UUUU, que es híbrido de ambos. El P/VC es el múltiplo más útil aquí porque varias no son rentables. La valoración por comps queda por debajo del precio de mercado, coherente con el DCF y el NAV: UUUU cotiza con prima sobre sus activos y sobre sus pares, reflejando expectativas altas por la transformación a tierras raras. Es la más especulativa de las cuatro empresas.
